Workbook
Name _AtRisk_SimSetting_AutomaticallyGenerateReports: FALSE
Name _AtRisk_SimSetting_AutomaticResultsDisplayMode: 0
Name _AtRisk_SimSetting_ConvergenceConfidenceLevel: 0.95
Name _AtRisk_SimSetting_ConvergencePercentileToTest: 0.9
Name _AtRisk_SimSetting_ConvergencePerformMeanTest: TRUE
Name _AtRisk_SimSetting_ConvergencePerformPercentileTest: FALSE
Name _AtRisk_SimSetting_ConvergencePerformStdDeviationTest: FALSE
Name _AtRisk_SimSetting_ConvergenceTestAllOutputs: TRUE
Name _AtRisk_SimSetting_ConvergenceTestingPeriod: 100
Name _AtRisk_SimSetting_ConvergenceTolerance: 0.03
Name _AtRisk_SimSetting_LiveUpdate: TRUE
Name _AtRisk_SimSetting_LiveUpdatePeriod: -1
Name _AtRisk_SimSetting_MacroRecalculationBehavior: 0
Name _AtRisk_SimSetting_RandomNumberGenerator: 0
Name _AtRisk_SimSetting_ReportOptionCustomItemsCount: 0
Name _AtRisk_SimSetting_ReportOptionDataMode: 1
Name _AtRisk_SimSetting_ReportOptionReportMultiSimType: 1
Name _AtRisk_SimSetting_ReportOptionReportPlacement: 1
Name _AtRisk_SimSetting_ReportOptionReportSelection: 257
Name _AtRisk_SimSetting_ReportOptionReportsFileType: 1
Name _AtRisk_SimSetting_ReportOptionSelectiveQR: FALSE
Name _AtRisk_SimSetting_ReportsList: 257
Name _AtRisk_SimSetting_ShowSimulationProgressWindow: TRUE
Name _AtRisk_SimSetting_SimNameCount: 0
Name _AtRisk_SimSetting_SmartSensitivityAnalysisEnabled: TRUE
Name _AtRisk_SimSetting_StatisticFunctionUpdating: 1
Name _AtRisk_SimSetting_StdRecalcActiveSimulationNumber: 1
Name _AtRisk_SimSetting_StdRecalcBehavior: 1
Name _AtRisk_SimSetting_StdRecalcWithoutRiskStatic: 0
Name _AtRisk_SimSetting_StdRecalcWithoutRiskStaticPercentile: 0.5
Name _Order1: 255
Name _Order2: 255
Name F: {"bal",#N/A,FALSE,"working papers";"income",#N/A,FALSE,"working papers"}
Name fdraf: {"bal",#N/A,FALSE,"working papers";"income",#N/A,FALSE,"working papers"}
Name Fdraft: {"bal",#N/A,FALSE,"working papers";"income",#N/A,FALSE,"working papers"}
Name IQ_CH: 110000
Name IQ_CQ: 5000
Name IQ_CY: 10000
Name IQ_DAILY: 500000
Name IQ_DNTM: 700000
Name IQ_EXPENSE_CODE_: 80019595006
Name IQ_FH: 100000
Name IQ_FQ: 500
Name IQ_FWD_CY: 10001
Name IQ_FWD_CY1: 10002
Name IQ_FWD_CY2: 10003
Name IQ_FWD_FY: 1001
Name IQ_FWD_FY1: 1002
Name IQ_FWD_FY2: 1003
Name IQ_FWD_Q: 501
Name IQ_FWD_Q1: 502
Name IQ_FWD_Q2: 503
Name IQ_FY: 1000
Name IQ_LATESTK: 1000
Name IQ_LATESTQ: 500
Name IQ_LTM: 2000
Name IQ_LTMMONTH: 120000
Name IQ_MONTH: 15000
Name IQ_MTD: 800000
Name IQ_NAMES_REVISION_DATE_: 41366.3748958333

Sheet Cover
A1: =RIGHT(CELL("filename", $A$1), LEN(CELL("filename", $A$1)) - SEARCH("]", CELL("filename", $A$1))) -> Cover
B3: PR24 ODI Risk - Feeder Model (Storm Overflows)
B5: Model code | C5: PR24OC15
B6: Version number: | C6: 1
B7: File name: | C7: =MID(CELL("filename"), FIND("[", CELL("filename"), 1) + 1, FIND("]", CELL("filename"), 1) - FIND("[", CELL("filename"), 1) - 1) -> PR24 FD OC15 ODI risk - Feeder Model (Storm Overflows).xlsx
B8: Date: | C8: 45627
B10: For enquiries please contact: | C10: PR24@ofwat.gov.uk

Sheet Conceptual Model
A1: =RIGHT(CELL("filename", A1), LEN(CELL("filename", A1)) - SEARCH("]", CELL("filename", A1))) -> Conceptual Model
A3: Conceptual model
A28: END

Sheet F_Inputs
C1: ODI Risk SOF_Feeder Inputs | E1: Run on 13 Nov 2024 17:46
A2: Acronym | B2: Reference | C2: Item description | D2: Unit | E2: Model | F2: 2017-18 | G2: 2018-19 | H2: 2019-20 | I2: 2020-21 | J2: 2021-22 | K2: 2022-23 | L2: 2023-24 | M2: 2024-25
F4: Price Review 2024 | G4: Price Review 2024 | H4: Price Review 2024 | I4: Price Review 2024 | J4: Price Review 2024 | K4: Price Review 2024 | L4: Price Review 2024 | M4: Price Review 2024
F5: Run 11 - PR24 FD Data | G5: Run 11 - PR24 FD Data | H5: Run 11 - PR24 FD Data | I5: Run 11 - PR24 FD Data | J5: Run 11 - PR24 FD Data | K5: Run 11 - PR24 FD Data | L5: Run 11 - PR24 FD Data | M5: Run 11 - PR24 FD Data
F6: Latest | G6: Latest | H6: Latest | I6: Latest | J6: Latest | K6: Latest | L6: Latest | M6: Latest
A7: ANH | B7: OUT5_10_PR24 | C7: Underlying calculations for common performance commitments - wastewater - Storm overflows - Average number of spills per overflow - with unmonitored adjustment | D7: Number | E7: Price Review 2024 | G7: 94.114794 | H7: 81.269137 | I7: 65.777984 | J7: 59.163379 | K7: 40.269476 | L7: 25.339864 | M7: 23.14
A8: WSH | B8: OUT5_10_PR24 | C8: Underlying calculations for common performance commitments - wastewater - Storm overflows - Average number of spills per overflow - with unmonitored adjustment | D8: Number | E8: Price Review 2024 | F8: 36.219527 | G8: 41.285496 | H8: 49.773219 | I8: 57.701325 | J8: 48.76808 | K8: 43.317843 | L8: 58.398785 | M8: 49.933594
A9: HDD | B9: OUT5_10_PR24 | C9: Underlying calculations for common performance commitments - wastewater - Storm overflows - Average number of spills per overflow - with unmonitored adjustment | D9: Number | E9: Price Review 2024 | I9: 38.093396 | J9: 50.798519 | K9: 41.806154 | L9: 41.953704 | M9: 39.722222
A10: NES | B10: OUT5_10_PR24 | C10: Underlying calculations for common performance commitments - wastewater - Storm overflows - Average number of spills per overflow - with unmonitored adjustment | D10: Number | E10: Price Review 2024 | F10: 24.058571 | G10: 20.016792 | H10: 26.267794 | I10: 26.339079 | J10: 35.072068 | K10: 29.137852 | L10: 36.127348 | M10: 26
A11: SVE | B11: OUT5_10_PR24 | C11: Underlying calculations for common performance commitments - wastewater - Storm overflows - Average number of spills per overflow - with unmonitored adjustment | D11: Number | E11: Price Review 2024 | F11: 99.441228 | G11: 83.81149 | H11: 74.096128 | I11: 48.149389 | J11: 40.429708 | K11: 33.576197 | L11: 34.88765 | M11: 24.94294
A12: SWB | B12: OUT5_10_PR24 | C12: Underlying calculations for common performance commitments - wastewater - Storm overflows - Average number of spills per overflow - with unmonitored adjustment | D12: Number | E12: Price Review 2024 | F12: 10.015672 | G12: 20.106716 | H12: 25.802985 | I12: 31.382836 | J12: 31.704478 | K12: 28.031343 | L12: 41.020423 | M12: 19.955224
A13: SRN | B13: OUT5_10_PR24 | C13: Underlying calculations for common performance commitments - wastewater - Storm overflows - Average number of spills per overflow - with unmonitored adjustment | D13: Number | E13: Price Review 2024 | F13: 10.540409 | G13: 13.59 | H13: 20.929591 | I13: 29.702638 | J13: 28.450061 | K13: 25.721984 | L13: 38.008811 | M13: 21
A14: TMS | B14: OUT5_10_PR24 | C14: Underlying calculations for common performance commitments - wastewater - Storm overflows - Average number of spills per overflow - with unmonitored adjustment | D14: Number | E14: Price Review 2024 | I14: 58.623993 | J14: 54.008878 | K14: 42.214422 | L14: 37.147496 | M14: 25.823432
A15: NWT | B15: OUT5_10_PR24 | C15: Underlying calculations for common performance commitments - wastewater - Storm overflows - Average number of spills per overflow - with unmonitored adjustment | D15: Number | E15: Price Review 2024 | I15: 63.902423 | J15: 53.029599 | K15: 49.727604 | L15: 50.631714 | M15: 29.3606
A16: WSX | B16: OUT5_10_PR24 | C16: Underlying calculations for common performance commitments - wastewater - Storm overflows - Average number of spills per overflow - with unmonitored adjustment | D16: Number | E16: Price Review 2024 | F16: 10.66 | G16: 21.27 | H16: 26.8 | I16: 30.92 | J16: 22.53 | K16: 18.52 | L16: 32.010039 | M16: 24.008494
A17: YKY | B17: OUT5_10_PR24 | C17: Underlying calculations for common performance commitments - wastewater - Storm overflows - Average number of spills per overflow - with unmonitored adjustment | D17: Number | E17: Price Review 2024 | F17: 100 | G17: 100 | H17: 100 | I17: 39.491946 | J17: 44.194123 | K17: 37.96629 | L17: 42.836424 | M17: 38.962777
A20: END

Sheet Inputs_All
A1: =RIGHT(CELL("filename", A1), LEN(CELL("filename", A1)) - SEARCH("]", CELL("filename", A1))) -> Inputs_All
J2: 2019-20 | K2: 2020-21 | L2: 2021-22 | M2: 2022-23 | N2: 2022-24
E3: Company | F3: Performance Commitment | G3: Measure | H3: Unit
A7: Average number of spills per overflow - with unmonitored adjustment
E9: ANH | F9: SOF | G9: Average spills per overflow | H9: Nr | J9: =F_Inputs!H7 -> 81.269137 | K9: =F_Inputs!I7 -> 65.777984 | L9: =F_Inputs!J7 -> 59.163379 | M9: =F_Inputs!K7 -> 40.269476 | N9: =F_Inputs!L7 -> 25.339864
E10: WSH | F10: SOF | G10: Average spills per overflow | H10: Nr | J10: =F_Inputs!H8 -> 49.773219 | K10: =F_Inputs!I8 -> 57.701325 | L10: =F_Inputs!J8 -> 48.76808 | M10: =F_Inputs!K8 -> 43.317843 | N10: =F_Inputs!L8 -> 58.398785
E11: HDD | F11: SOF | G11: Average spills per overflow | H11: Nr | J11: =F_Inputs!H9 | K11: =F_Inputs!I9 -> 38.093396 | L11: =F_Inputs!J9 -> 50.798519 | M11: =F_Inputs!K9 -> 41.806154 | N11: =F_Inputs!L9 -> 41.953704
E12: NES | F12: SOF | G12: Average spills per overflow | H12: Nr | J12: =F_Inputs!H10 -> 26.267794 | K12: =F_Inputs!I10 -> 26.339079 | L12: =F_Inputs!J10 -> 35.072068 | M12: =F_Inputs!K10 -> 29.137852 | N12: =F_Inputs!L10 -> 36.127348
E13: SVE | F13: SOF | G13: Average spills per overflow | H13: Nr | J13: =F_Inputs!H11 -> 74.096128 | K13: =F_Inputs!I11 -> 48.149389 | L13: =F_Inputs!J11 -> 40.429708 | M13: =F_Inputs!K11 -> 33.576197 | N13: =F_Inputs!L11 -> 34.88765
E14: SWB | F14: SOF | G14: Average spills per overflow | H14: Nr | J14: =F_Inputs!H12 -> 25.802985 | K14: =F_Inputs!I12 -> 31.382836 | L14: =F_Inputs!J12 -> 31.704478 | M14: =F_Inputs!K12 -> 28.031343 | N14: =F_Inputs!L12 -> 41.020423
E15: SRN | F15: SOF | G15: Average spills per overflow | H15: Nr | J15: =F_Inputs!H13 -> 20.929591 | K15: =F_Inputs!I13 -> 29.702638 | L15: =F_Inputs!J13 -> 28.450061 | M15: =F_Inputs!K13 -> 25.721984 | N15: =F_Inputs!L13 -> 38.008811
E16: TMS | F16: SOF | G16: Average spills per overflow | H16: Nr | J16: =F_Inputs!H14 | K16: =F_Inputs!I14 -> 58.623993 | L16: =F_Inputs!J14 -> 54.008878 | M16: =F_Inputs!K14 -> 42.214422 | N16: =F_Inputs!L14 -> 37.147496
E17: UUW | F17: SOF | G17: Average spills per overflow | H17: Nr | J17: =F_Inputs!H15 | K17: =F_Inputs!I15 -> 63.902423 | L17: =F_Inputs!J15 -> 53.029599 | M17: =F_Inputs!K15 -> 49.727604 | N17: =F_Inputs!L15 -> 50.631714
E18: WSX | F18: SOF | G18: Average spills per overflow | H18: Nr | J18: =F_Inputs!H16 -> 26.8 | K18: =F_Inputs!I16 -> 30.92 | L18: =F_Inputs!J16 -> 22.53 | M18: =F_Inputs!K16 -> 18.52 | N18: =F_Inputs!L16 -> 32.010039
E19: YKY | F19: SOF | G19: Average spills per overflow | H19: Nr | J19: =F_Inputs!H17 -> 100 | K19: =F_Inputs!I17 -> 39.491946 | L19: =F_Inputs!J17 -> 44.194123 | M19: =F_Inputs!K17 -> 37.96629 | N19: =F_Inputs!L17 -> 42.836424
A21: END

Sheet Proxy PCL
A1: =RIGHT(CELL("filename", A1), LEN(CELL("filename", A1)) - SEARCH("]", CELL("filename", A1))) -> Proxy PCL
L2: 2019-20 | M2: 2020-21 | N2: 2021-22 | O2: 2022-23 | P2: 2023-24
E3: Company | F3: Performance Commitment | G3: Measure | H3: Unit | I3: Percentile | J3: Help Cells
A7: Average number of spills per overflow - with unmonitored adjustment
E9: ANH | F9: SOF | G9: Avg spills per overflow | H9: Nr | L9: =Inputs_All!J9 -> 81.269137 | M9: =Inputs_All!K9 -> 65.777984 | N9: =Inputs_All!L9 -> 59.163379 | O9: =Inputs_All!M9 -> 40.269476 | P9: =Inputs_All!N9 -> 25.339864
E10: WSH | F10: SOF | G10: Avg spills per overflow | H10: Nr | L10: =Inputs_All!J10 -> 49.773219 | M10: =Inputs_All!K10 -> 57.701325 | N10: =Inputs_All!L10 -> 48.76808 | O10: =Inputs_All!M10 -> 43.317843 | P10: =Inputs_All!N10 -> 58.398785
E11: HDD | F11: SOF | G11: Avg spills per overflow | H11: Nr | L11: =Inputs_All!J11 | M11: =Inputs_All!K11 -> 38.093396 | N11: =Inputs_All!L11 -> 50.798519 | O11: =Inputs_All!M11 -> 41.806154 | P11: =Inputs_All!N11 -> 41.953704
E12: NES | F12: SOF | G12: Avg spills per overflow | H12: Nr | L12: =Inputs_All!J12 -> 26.267794 | M12: =Inputs_All!K12 -> 26.339079 | N12: =Inputs_All!L12 -> 35.072068 | O12: =Inputs_All!M12 -> 29.137852 | P12: =Inputs_All!N12 -> 36.127348
E13: SVE | F13: SOF | G13: Avg spills per overflow | H13: Nr | L13: =Inputs_All!J13 -> 74.096128 | M13: =Inputs_All!K13 -> 48.149389 | N13: =Inputs_All!L13 -> 40.429708 | O13: =Inputs_All!M13 -> 33.576197 | P13: =Inputs_All!N13 -> 34.88765
E14: SWB | F14: SOF | G14: Avg spills per overflow | H14: Nr | L14: =Inputs_All!J14 -> 25.802985 | M14: =Inputs_All!K14 -> 31.382836 | N14: =Inputs_All!L14 -> 31.704478 | O14: =Inputs_All!M14 -> 28.031343 | P14: =Inputs_All!N14 -> 41.020423
E15: SRN | F15: SOF | G15: Avg spills per overflow | H15: Nr | L15: =Inputs_All!J15 -> 20.929591 | M15: =Inputs_All!K15 -> 29.702638 | N15: =Inputs_All!L15 -> 28.450061 | O15: =Inputs_All!M15 -> 25.721984 | P15: =Inputs_All!N15 -> 38.008811
E16: TMS | F16: SOF | G16: Avg spills per overflow | H16: Nr | L16: =Inputs_All!J16 | M16: =Inputs_All!K16 -> 58.623993 | N16: =Inputs_All!L16 -> 54.008878 | O16: =Inputs_All!M16 -> 42.214422 | P16: =Inputs_All!N16 -> 37.147496
E17: UUW | F17: SOF | G17: Avg spills per overflow | H17: Nr | L17: =Inputs_All!J17 | M17: =Inputs_All!K17 -> 63.902423 | N17: =Inputs_All!L17 -> 53.029599 | O17: =Inputs_All!M17 -> 49.727604 | P17: =Inputs_All!N17 -> 50.631714
E18: WSX | F18: SOF | G18: Avg spills per overflow | H18: Nr | L18: =Inputs_All!J18 -> 26.8 | M18: =Inputs_All!K18 -> 30.92 | N18: =Inputs_All!L18 -> 22.53 | O18: =Inputs_All!M18 -> 18.52 | P18: =Inputs_All!N18 -> 32.010039
E19: YKY | F19: SOF | G19: Avg spills per overflow | H19: Nr | L19: =Inputs_All!J19 -> 100 | M19: =Inputs_All!K19 -> 39.491946 | N19: =Inputs_All!L19 -> 44.194123 | O19: =Inputs_All!M19 -> 37.96629 | P19: =Inputs_All!N19 -> 42.836424
A21: Average number of spills per overflow - with unmonitored adjustment - industry-wide percentiles
F23: SOF | G23: Avg spills per overflow | H23: Nr | I23: P10 | J23: 0.1 | L23: =_xlfn.PERCENTILE.INC(L$9:L$19,$J23) -> 24.340967 | M23: =_xlfn.PERCENTILE.INC(M$9:M$19,$J23) -> 29.702638 | N23: =_xlfn.PERCENTILE.INC(N$9:N$19,$J23) -> 28.450061 | O23: =_xlfn.PERCENTILE.INC(O$9:O$19,$J23) -> 25.721984 | P23: =_xlfn.PERCENTILE.INC(P$9:P$19,$J23) -> 32.010039
F24: SOF | G24: Avg spills per overflow | H24: Nr | I24: P15 | J24: 0.15 | L24: =_xlfn.PERCENTILE.INC(L$9:L$19,$J24) -> 25.826226 | M24: =_xlfn.PERCENTILE.INC(M$9:M$19,$J24) -> 30.311319 | N24: =_xlfn.PERCENTILE.INC(N$9:N$19,$J24) -> 30.077269 | O24: =_xlfn.PERCENTILE.INC(O$9:O$19,$J24) -> 26.876663 | P24: =_xlfn.PERCENTILE.INC(P$9:P$19,$J24) -> 33.448844
F25: SOF | G25: Avg spills per overflow | H25: Nr | I25: P20 | J25: 0.2 | L25: =_xlfn.PERCENTILE.INC(L$9:L$19,$J25) -> 25.988908 | M25: =_xlfn.PERCENTILE.INC(M$9:M$19,$J25) -> 30.92 | N25: =_xlfn.PERCENTILE.INC(N$9:N$19,$J25) -> 31.704478 | O25: =_xlfn.PERCENTILE.INC(O$9:O$19,$J25) -> 28.031343 | P25: =_xlfn.PERCENTILE.INC(P$9:P$19,$J25) -> 34.88765
F26: SOF | G26: Avg spills per overflow | H26: Nr | I26: P25 | J26: 0.25 | L26: =_xlfn.PERCENTILE.INC(L$9:L$19,$J26) -> 26.151591 | M26: =_xlfn.PERCENTILE.INC(M$9:M$19,$J26) -> 31.151418 | N26: =_xlfn.PERCENTILE.INC(N$9:N$19,$J26) -> 33.388273 | O26: =_xlfn.PERCENTILE.INC(O$9:O$19,$J26) -> 28.584597 | P26: =_xlfn.PERCENTILE.INC(P$9:P$19,$J26) -> 35.507499
F27: SOF | G27: Avg spills per overflow | H27: Nr | I27: P30 | J27: 0.3 | L27: =_xlfn.PERCENTILE.INC(L$9:L$19,$J27) -> 26.321014 | M27: =_xlfn.PERCENTILE.INC(M$9:M$19,$J27) -> 31.382836 | N27: =_xlfn.PERCENTILE.INC(N$9:N$19,$J27) -> 35.072068 | O27: =_xlfn.PERCENTILE.INC(O$9:O$19,$J27) -> 29.137852 | P27: =_xlfn.PERCENTILE.INC(P$9:P$19,$J27) -> 36.127348
F28: SOF | G28: Avg spills per overflow | H28: Nr | I28: P35 | J28: 0.35 | L28: =_xlfn.PERCENTILE.INC(L$9:L$19,$J28) -> 26.507286 | M28: =_xlfn.PERCENTILE.INC(M$9:M$19,$J28) -> 34.738116 | N28: =_xlfn.PERCENTILE.INC(N$9:N$19,$J28) -> 37.750888 | O28: =_xlfn.PERCENTILE.INC(O$9:O$19,$J28) -> 31.357024 | P28: =_xlfn.PERCENTILE.INC(P$9:P$19,$J28) -> 36.637422
F29: SOF | G29: Avg spills per overflow | H29: Nr | I29: P40 | J29: 0.4 | L29: =_xlfn.PERCENTILE.INC(L$9:L$19,$J29) -> 26.693559 | M29: =_xlfn.PERCENTILE.INC(M$9:M$19,$J29) -> 38.093396 | N29: =_xlfn.PERCENTILE.INC(N$9:N$19,$J29) -> 40.429708 | O29: =_xlfn.PERCENTILE.INC(O$9:O$19,$J29) -> 33.576197 | P29: =_xlfn.PERCENTILE.INC(P$9:P$19,$J29) -> 37.147496
F30: SOF | G30: Avg spills per overflow | H30: Nr | I30: P45 | J30: 0.45 | L30: =_xlfn.PERCENTILE.INC(L$9:L$19,$J30) -> 30.245983 | M30: =_xlfn.PERCENTILE.INC(M$9:M$19,$J30) -> 38.792671 | N30: =_xlfn.PERCENTILE.INC(N$9:N$19,$J30) -> 42.311915 | O30: =_xlfn.PERCENTILE.INC(O$9:O$19,$J30) -> 35.771243 | P30: =_xlfn.PERCENTILE.INC(P$9:P$19,$J30) -> 37.578154
F31: SOF | G31: Avg spills per overflow | H31: Nr | I31: P50 | J31: 0.5 | L31: =_xlfn.PERCENTILE.INC(L$9:L$19,$J31) -> 38.28661 | M31: =_xlfn.PERCENTILE.INC(M$9:M$19,$J31) -> 39.491946 | N31: =_xlfn.PERCENTILE.INC(N$9:N$19,$J31) -> 44.194123 | O31: =_xlfn.PERCENTILE.INC(O$9:O$19,$J31) -> 37.96629 | P31: =_xlfn.PERCENTILE.INC(P$9:P$19,$J31) -> 38.008811
F32: SOF | G32: Avg spills per overflow | H32: Nr | I32: P55 | J32: 0.55 | L32: =_xlfn.PERCENTILE.INC(L$9:L$19,$J32) -> 46.327236 | M32: =_xlfn.PERCENTILE.INC(M$9:M$19,$J32) -> 43.820667 | N32: =_xlfn.PERCENTILE.INC(N$9:N$19,$J32) -> 46.481101 | O32: =_xlfn.PERCENTILE.INC(O$9:O$19,$J32) -> 39.117883 | P32: =_xlfn.PERCENTILE.INC(P$9:P$19,$J32) -> 39.514617
F33: SOF | G33: Avg spills per overflow | H33: Nr | I33: P60 | J33: 0.6 | L33: =_xlfn.PERCENTILE.INC(L$9:L$19,$J33) -> 54.637801 | M33: =_xlfn.PERCENTILE.INC(M$9:M$19,$J33) -> 48.149389 | N33: =_xlfn.PERCENTILE.INC(N$9:N$19,$J33) -> 48.76808 | O33: =_xlfn.PERCENTILE.INC(O$9:O$19,$J33) -> 40.269476 | P33: =_xlfn.PERCENTILE.INC(P$9:P$19,$J33) -> 41.020423
F34: SOF | G34: Avg spills per overflow | H34: Nr | I34: P65 | J34: 0.65 | L34: =_xlfn.PERCENTILE.INC(L$9:L$19,$J34) -> 63.150819 | M34: =_xlfn.PERCENTILE.INC(M$9:M$19,$J34) -> 52.925357 | N34: =_xlfn.PERCENTILE.INC(N$9:N$19,$J34) -> 49.783299 | O34: =_xlfn.PERCENTILE.INC(O$9:O$19,$J34) -> 41.037815 | P34: =_xlfn.PERCENTILE.INC(P$9:P$19,$J34) -> 41.487063
... F39: SOF | G39: Avg spills per overflow | H39: Nr | I39: P90 | J39: 0.9 | L39: =_xlfn.PERCENTILE.INC(L$9:L$19,$J39) -> 86.888396 | M39: =_xlfn.PERCENTILE.INC(M$9:M$19,$J39) -> 63.902423 | N39: =_xlfn.PERCENTILE.INC(N$9:N$19,$J39) -> 54.008878 | O39: =_xlfn.PERCENTILE.INC(O$9:O$19,$J39) -> 43.317843 | P39: =_xlfn.PERCENTILE.INC(P$9:P$19,$J39) -> 50.631714
A41: Average number of spills per overflow - with unmonitored adjustment - P10-P90 midpoint (proxy PCL)
F43: SOF | G43: Avg spills per overflow - proxy PCL | H43: Nr | L43: =AVERAGE(L23,L39) -> 55.614681 | M43: =AVERAGE(M23,M39) -> 46.80253 | N43: =AVERAGE(N23,N39) -> 41.22947 | O43: =AVERAGE(O23,O39) -> 34.519914 | P43: =AVERAGE(P23,P39) -> 41.320876
A45: END

Sheet Difference to PCL
A1: =RIGHT(CELL("filename", A1), LEN(CELL("filename", A1)) - SEARCH("]", CELL("filename", A1))) -> Difference to PCL
J2: 2019-20 | K2: 2020-21 | L2: 2021-22 | M2: 2022-23 | N2: 2023-24
E3: Company | F3: Performance Commitment | G3: Measure | H3: Unit
A7: Average number of spills per overflow - with unmonitored adjustment
E9: ANH | F9: SOF | G9: Avg spills per overflow | H9: Nr | J9: =Inputs_All!J9 -> 81.269137 | K9: =Inputs_All!K9 -> 65.777984 | L9: =Inputs_All!L9 -> 59.163379 | M9: =Inputs_All!M9 -> 40.269476 | N9: =Inputs_All!N9 -> 25.339864
E10: WSH | F10: SOF | G10: Avg spills per overflow | H10: Nr | J10: =Inputs_All!J10 -> 49.773219 | K10: =Inputs_All!K10 -> 57.701325 | L10: =Inputs_All!L10 -> 48.76808 | M10: =Inputs_All!M10 -> 43.317843 | N10: =Inputs_All!N10 -> 58.398785
E11: HDD | F11: SOF | G11: Avg spills per overflow | H11: Nr | J11: =Inputs_All!J11 | K11: =Inputs_All!K11 -> 38.093396 | L11: =Inputs_All!L11 -> 50.798519 | M11: =Inputs_All!M11 -> 41.806154 | N11: =Inputs_All!N11 -> 41.953704
E12: NES | F12: SOF | G12: Avg spills per overflow | H12: Nr | J12: =Inputs_All!J12 -> 26.267794 | K12: =Inputs_All!K12 -> 26.339079 | L12: =Inputs_All!L12 -> 35.072068 | M12: =Inputs_All!M12 -> 29.137852 | N12: =Inputs_All!N12 -> 36.127348
E13: SVE | F13: SOF | G13: Avg spills per overflow | H13: Nr | J13: =Inputs_All!J13 -> 74.096128 | K13: =Inputs_All!K13 -> 48.149389 | L13: =Inputs_All!L13 -> 40.429708 | M13: =Inputs_All!M13 -> 33.576197 | N13: =Inputs_All!N13 -> 34.88765
E14: SWB | F14: SOF | G14: Avg spills per overflow | H14: Nr | J14: =Inputs_All!J14 -> 25.802985 | K14: =Inputs_All!K14 -> 31.382836 | L14: =Inputs_All!L14 -> 31.704478 | M14: =Inputs_All!M14 -> 28.031343 | N14: =Inputs_All!N14 -> 41.020423
E15: SRN | F15: SOF | G15: Avg spills per overflow | H15: Nr | J15: =Inputs_All!J15 -> 20.929591 | K15: =Inputs_All!K15 -> 29.702638 | L15: =Inputs_All!L15 -> 28.450061 | M15: =Inputs_All!M15 -> 25.721984 | N15: =Inputs_All!N15 -> 38.008811
E16: TMS | F16: SOF | G16: Avg spills per overflow | H16: Nr | J16: =Inputs_All!J16 | K16: =Inputs_All!K16 -> 58.623993 | L16: =Inputs_All!L16 -> 54.008878 | M16: =Inputs_All!M16 -> 42.214422 | N16: =Inputs_All!N16 -> 37.147496
E17: UUW | F17: SOF | G17: Avg spills per overflow | H17: Nr | J17: =Inputs_All!J17 | K17: =Inputs_All!K17 -> 63.902423 | L17: =Inputs_All!L17 -> 53.029599 | M17: =Inputs_All!M17 -> 49.727604 | N17: =Inputs_All!N17 -> 50.631714
E18: WSX | F18: SOF | G18: Avg spills per overflow | H18: Nr | J18: =Inputs_All!J18 -> 26.8 | K18: =Inputs_All!K18 -> 30.92 | L18: =Inputs_All!L18 -> 22.53 | M18: =Inputs_All!M18 -> 18.52 | N18: =Inputs_All!N18 -> 32.010039
E19: YKY | F19: SOF | G19: Avg spills per overflow | H19: Nr | J19: =Inputs_All!J19 -> 100 | K19: =Inputs_All!K19 -> 39.491946 | L19: =Inputs_All!L19 -> 44.194123 | M19: =Inputs_All!M19 -> 37.96629 | N19: =Inputs_All!N19 -> 42.836424
A21: Average number of spills per overflow - with unmonitored adjustment - P10-P90 midpoint (proxy PCL)
F23: SOF | G23: Avg spills per overflow (P10-P90 midpoint) | H23: Nr | J23: ='Proxy PCL'!L43 -> 55.614681 | K23: ='Proxy PCL'!M43 -> 46.80253 | L23: ='Proxy PCL'!N43 -> 41.22947 | M23: ='Proxy PCL'!O43 -> 34.519914 | N23: ='Proxy PCL'!P43 -> 41.320876
A25: Average number of spills per overflow - with unmonitored adjustment - difference to PCL
E27: ANH | F27: SOF | G27: Avg spills per overflow | H27: Nr | J27: =IF(J9="","",J$23-J9) -> -25.654456 | K27: =IF(K9="","",K$23-K9) -> -18.975454 | L27: =IF(L9="","",L$23-L9) -> -17.933909 | M27: =IF(M9="","",M$23-M9) -> -5.7495629 | N27: =IF(N9="","",N$23-N9) -> 15.981012
E28: WSH | F28: SOF | G28: Avg spills per overflow | H28: Nr | J28: =IF(J10="","",J$23-J10) -> 5.8414621 | K28: =IF(K10="","",K$23-K10) -> -10.898794 | L28: =IF(L10="","",L$23-L10) -> -7.53861 | M28: =IF(M10="","",M$23-M10) -> -8.7979299 | N28: =IF(N10="","",N$23-N10) -> -17.077909
E29: HDD | F29: SOF | G29: Avg spills per overflow | H29: Nr | J29: =IF(J11="","",J$23-J11) | K29: =IF(K11="","",K$23-K11) -> 8.7091342 | L29: =IF(L11="","",L$23-L11) -> -9.5690489 | M29: =IF(M11="","",M$23-M11) -> -7.2862403 | N29: =IF(N11="","",N$23-N11) -> -0.63282751
E30: NES | F30: SOF | G30: Avg spills per overflow | H30: Nr | J30: =IF(J12="","",J$23-J12) -> 29.346888 | K30: =IF(K12="","",K$23-K12) -> 20.463451 | L30: =IF(L12="","",L$23-L12) -> 6.157402 | M30: =IF(M12="","",M$23-M12) -> 5.3820619 | N30: =IF(N12="","",N$23-N12) -> 5.193528
E31: SVE | F31: SOF | G31: Avg spills per overflow | H31: Nr | J31: =IF(J13="","",J$23-J13) -> -18.481447 | K31: =IF(K13="","",K$23-K13) -> -1.3468589 | L31: =IF(L13="","",L$23-L13) -> 0.79976154 | M31: =IF(M13="","",M$23-M13) -> 0.94371687 | N31: =IF(N13="","",N$23-N13) -> 6.4332265
E32: SWB | F32: SOF | G32: Avg spills per overflow | H32: Nr | J32: =IF(J14="","",J$23-J14) -> 29.811696 | K32: =IF(K14="","",K$23-K14) -> 15.419695 | L32: =IF(L14="","",L$23-L14) -> 9.524992 | M32: =IF(M14="","",M$23-M14) -> 6.4885702 | N32: =IF(N14="","",N$23-N14) -> 0.30045366
E33: SRN | F33: SOF | G33: Avg spills per overflow | H33: Nr | J33: =IF(J15="","",J$23-J15) -> 34.68509 | K33: =IF(K15="","",K$23-K15) -> 17.099892 | L33: =IF(L15="","",L$23-L15) -> 12.779408 | M33: =IF(M15="","",M$23-M15) -> 8.7979299 | N33: =IF(N15="","",N$23-N15) -> 3.3120647
E34: TMS | F34: SOF | G34: Avg spills per overflow | H34: Nr | J34: =IF(J16="","",J$23-J16) | K34: =IF(K16="","",K$23-K16) -> -11.821463 | L34: =IF(L16="","",L$23-L16) -> -12.779408 | M34: =IF(M16="","",M$23-M16) -> -7.6945089 | N34: =IF(N16="","",N$23-N16) -> 4.1733802
E35: UUW | F35: SOF | G35: Avg spills per overflow | H35: Nr | J35: =IF(J17="","",J$23-J17) | K35: =IF(K17="","",K$23-K17) -> -17.099892 | L35: =IF(L17="","",L$23-L17) -> -11.800129 | M35: =IF(M17="","",M$23-M17) -> -15.207691 | N35: =IF(N17="","",N$23-N17) -> -9.3108376
E36: WSX | F36: SOF | G36: Avg spills per overflow | H36: Nr | J36: =IF(J18="","",J$23-J18) -> 28.814681 | K36: =IF(K18="","",K$23-K18) -> 15.88253 | L36: =IF(L18="","",L$23-L18) -> 18.69947 | M36: =IF(M18="","",M$23-M18) -> 15.999914 | N36: =IF(N18="","",N$23-N18) -> 9.3108376
E37: YKY | F37: SOF | G37: Avg spills per overflow | H37: Nr | J37: =IF(J19="","",J$23-J19) -> -44.385319 | K37: =IF(K19="","",K$23-K19) -> 7.3105848 | L37: =IF(L19="","",L$23-L19) -> -2.9646533 | M37: =IF(M19="","",M$23-M19) -> -3.4463764 | N37: =IF(N19="","",N$23-N19) -> -1.5155475
A39: Average number of spills per overflow - with unmonitored adjustment - percentage difference to PCL (clean)
E41: ANH | F41: SOF | G41: Avg spills per overflow - difference to PCL | H41: Nr | J41: =IF(J27="","",J27/J$23) -> -0.46128927 | K41: =IF(K27="","",K27/K$23) -> -0.40543649 | L41: =IF(L27="","",L27/L$23) -> -0.43497792 | M41: =IF(M27="","",M27/M$23) -> -0.16655786 | N41: =IF(N27="","",N27/N$23) -> 0.38675394
E42: WSH | F42: SOF | G42: Avg spills per overflow - difference to PCL | H42: Nr | J42: =IF(J28="","",J28/J$23) -> 0.10503453 | K42: =IF(K28="","",K28/K$23) -> -0.23286763 | L42: =IF(L28="","",L28/L$23) -> -0.18284518 | M42: =IF(M28="","",M28/M$23) -> -0.25486535 | N42: =IF(N28="","",N28/N$23) -> -0.41329977
E43: HDD | F43: SOF | G43: Avg spills per overflow - difference to PCL | H43: Nr | J43: =IF(J29="","",J29/J$23) | K43: =IF(K29="","",K29/K$23) -> 0.18608255 | L43: =IF(L29="","",L29/L$23) -> -0.23209246 | M43: =IF(M29="","",M29/M$23) -> -0.21107354 | N43: =IF(N29="","",N29/N$23) -> -0.015314959
E44: NES | F44: SOF | G44: Avg spills per overflow - difference to PCL | H44: Nr | J44: =IF(J30="","",J30/J$23) -> 0.52768239 | K44: =IF(K30="","",K30/K$23) -> 0.4372296 | L44: =IF(L30="","",L30/L$23) -> 0.14934468 | M44: =IF(M30="","",M30/M$23) -> 0.1559118 | N44: =IF(N30="","",N30/N$23) -> 0.12568775
E45: SVE | F45: SOF | G45: Avg spills per overflow - difference to PCL | H45: Nr | J45: =IF(J31="","",J31/J$23) -> -0.33231237 | K45: =IF(K31="","",K31/K$23) -> -0.028777481 | L45: =IF(L31="","",L31/L$23) -> 0.019397813 | M45: =IF(M31="","",M31/M$23) -> 0.027338332 | N45: =IF(N31="","",N31/N$23) -> 0.1556895
E46: SWB | F46: SOF | G46: Avg spills per overflow - difference to PCL | H46: Nr | J46: =IF(J32="","",J32/J$23) -> 0.53604005 | K46: =IF(K32="","",K32/K$23) -> 0.32946284 | L46: =IF(L32="","",L32/L$23) -> 0.23102388 | M46: =IF(M32="","",M32/M$23) -> 0.187966 | N46: =IF(N32="","",N32/N$23) -> 0.0072712316
E47: SRN | F47: SOF | G47: Avg spills per overflow - difference to PCL | H47: Nr | J47: =IF(J33="","",J33/J$23) -> 0.62366788 | K47: =IF(K33="","",K33/K$23) -> 0.36536256 | L47: =IF(L33="","",L33/L$23) -> 0.3099581 | M47: =IF(M33="","",M33/M$23) -> 0.25486535 | N47: =IF(N33="","",N33/N$23) -> 0.080154755
E48: TMS | F48: SOF | G48: Avg spills per overflow - difference to PCL | H48: Nr | J48: =IF(J34="","",J34/J$23) | K48: =IF(K34="","",K34/K$23) -> -0.25258171 | L48: =IF(L34="","",L34/L$23) -> -0.3099581 | M48: =IF(M34="","",M34/M$23) -> -0.22290059 | N48: =IF(N34="","",N34/N$23) -> 0.10099932
E49: UUW | F49: SOF | G49: Avg spills per overflow - difference to PCL | H49: Nr | J49: =IF(J35="","",J35/J$23) | K49: =IF(K35="","",K35/K$23) -> -0.36536256 | L49: =IF(L35="","",L35/L$23) -> -0.28620618 | M49: =IF(M35="","",M35/M$23) -> -0.44054834 | N49: =IF(N35="","",N35/N$23) -> -0.22533011
E50: WSX | F50: SOF | G50: Avg spills per overflow - difference to PCL | H50: Nr | J50: =IF(J36="","",J36/J$23) -> 0.51811286 | K50: =IF(K36="","",K36/K$23) -> 0.33935196 | L50: =IF(L36="","",L36/L$23) -> 0.45354621 | M50: =IF(M36="","",M36/M$23) -> 0.46349808 | N50: =IF(N36="","",N36/N$23) -> 0.22533011
...

Sheet Percentiles
A1: =RIGHT(CELL("filename", A1), LEN(CELL("filename", A1)) - SEARCH("]", CELL("filename", A1))) -> Percentiles
M2: 2019-20 | N2: 2020-21 | O2: 2021-22 | P2: 2022-23 | Q2: 2023-24
E3: Company | F3: Performance Commitment | G3: Measure | H3: Unit | I3: Percentiles | J3: Help Cells | K3: Value
A7: Average number of spills per overflow - with unmonitored adjustment - percentage difference to PCL (clean)
E9: ANH | F9: SOF | G9: Avg spills per overflow - difference to PCL | H9: Nr | M9: ='Difference to PCL'!J41 -> -0.46128927 | N9: ='Difference to PCL'!K41 -> -0.40543649 | O9: ='Difference to PCL'!L41 -> -0.43497792 | P9: ='Difference to PCL'!M41 -> -0.16655786 | Q9: ='Difference to PCL'!N41 -> 0.38675394
E10: WSH | F10: SOF | G10: Avg spills per overflow - difference to PCL | H10: Nr | M10: ='Difference to PCL'!J42 -> 0.10503453 | N10: ='Difference to PCL'!K42 -> -0.23286763 | O10: ='Difference to PCL'!L42 -> -0.18284518 | P10: ='Difference to PCL'!M42 -> -0.25486535 | Q10: ='Difference to PCL'!N42 -> -0.41329977
E11: HDD | F11: SOF | G11: Avg spills per overflow - difference to PCL | H11: Nr | M11: ='Difference to PCL'!J43 | N11: ='Difference to PCL'!K43 -> 0.18608255 | O11: ='Difference to PCL'!L43 -> -0.23209246 | P11: ='Difference to PCL'!M43 -> -0.21107354 | Q11: ='Difference to PCL'!N43 -> -0.015314959
E12: NES | F12: SOF | G12: Avg spills per overflow - difference to PCL | H12: Nr | M12: ='Difference to PCL'!J44 -> 0.52768239 | N12: ='Difference to PCL'!K44 -> 0.4372296 | O12: ='Difference to PCL'!L44 -> 0.14934468 | P12: ='Difference to PCL'!M44 -> 0.1559118 | Q12: ='Difference to PCL'!N44 -> 0.12568775
E13: SVE | F13: SOF | G13: Avg spills per overflow - difference to PCL | H13: Nr | M13: ='Difference to PCL'!J45 -> -0.33231237 | N13: ='Difference to PCL'!K45 -> -0.028777481 | O13: ='Difference to PCL'!L45 -> 0.019397813 | P13: ='Difference to PCL'!M45 -> 0.027338332 | Q13: ='Difference to PCL'!N45 -> 0.1556895
E14: SWB | F14: SOF | G14: Avg spills per overflow - difference to PCL | H14: Nr | M14: ='Difference to PCL'!J46 -> 0.53604005 | N14: ='Difference to PCL'!K46 -> 0.32946284 | O14: ='Difference to PCL'!L46 -> 0.23102388 | P14: ='Difference to PCL'!M46 -> 0.187966 | Q14: ='Difference to PCL'!N46 -> 0.0072712316
E15: SRN | F15: SOF | G15: Avg spills per overflow - difference to PCL | H15: Nr | M15: ='Difference to PCL'!J47 -> 0.62366788 | N15: ='Difference to PCL'!K47 -> 0.36536256 | O15: ='Difference to PCL'!L47 -> 0.3099581 | P15: ='Difference to PCL'!M47 -> 0.25486535 | Q15: ='Difference to PCL'!N47 -> 0.080154755
E16: TMS | F16: SOF | G16: Avg spills per overflow - difference to PCL | H16: Nr | M16: ='Difference to PCL'!J48 | N16: ='Difference to PCL'!K48 -> -0.25258171 | O16: ='Difference to PCL'!L48 -> -0.3099581 | P16: ='Difference to PCL'!M48 -> -0.22290059 | Q16: ='Difference to PCL'!N48 -> 0.10099932
E17: UUW | F17: SOF | G17: Avg spills per overflow - difference to PCL | H17: Nr | M17: ='Difference to PCL'!J49 | N17: ='Difference to PCL'!K49 -> -0.36536256 | O17: ='Difference to PCL'!L49 -> -0.28620618 | P17: ='Difference to PCL'!M49 -> -0.44054834 | Q17: ='Difference to PCL'!N49 -> -0.22533011
E18: WSX | F18: SOF | G18: Avg spills per overflow - difference to PCL | H18: Nr | M18: ='Difference to PCL'!J50 -> 0.51811286 | N18: ='Difference to PCL'!K50 -> 0.33935196 | O18: ='Difference to PCL'!L50 -> 0.45354621 | P18: ='Difference to PCL'!M50 -> 0.46349808 | Q18: ='Difference to PCL'!N50 -> 0.22533011
E19: YKY | F19: SOF | G19: Avg spills per overflow - difference to PCL | H19: Nr | M19: ='Difference to PCL'!J51 -> -0.79808636 | N19: ='Difference to PCL'!K51 -> 0.15620063 | O19: ='Difference to PCL'!L51 -> -0.07190617 | P19: ='Difference to PCL'!M51 -> -0.099837343 | Q19: ='Difference to PCL'!N51 -> -0.036677526
A21: Average number of spills per overflow - with unmonitored adjustment - industry-wide percentiles of percentage difference to PCL
F23: SOF | G23: Avg spills per overflow - difference to PCL | H23: % | I23: P10 | J23: 0.1 | K23: =_xlfn.PERCENTILE.INC($M$9:$Q$19,J23) -> -0.40142909
F24: SOF | G24: Avg spills per overflow - difference to PCL | H24: % | I24: P15 | J24: 0.15 | K24: =_xlfn.PERCENTILE.INC($M$9:$Q$19,J24) -> -0.3177821
F25: SOF | G25: Avg spills per overflow - difference to PCL | H25: % | I25: P20 | J25: 0.2 | K25: =_xlfn.PERCENTILE.INC($M$9:$Q$19,J25) -> -0.25440862
F26: SOF | G26: Avg spills per overflow - difference to PCL | H26: % | I26: P25 | J26: 0.25 | K26: =_xlfn.PERCENTILE.INC($M$9:$Q$19,J26) -> -0.23228625
F27: SOF | G27: Avg spills per overflow - difference to PCL | H27: % | I27: P30 | J27: 0.3 | K27: =_xlfn.PERCENTILE.INC($M$9:$Q$19,J27) -> -0.21935247
F28: SOF | G28: Avg spills per overflow - difference to PCL | H28: % | I28: P35 | J28: 0.35 | K28: =_xlfn.PERCENTILE.INC($M$9:$Q$19,J28) -> -0.16900096
F29: SOF | G29: Avg spills per overflow - difference to PCL | H29: % | I29: P40 | J29: 0.4 | K29: =_xlfn.PERCENTILE.INC($M$9:$Q$19,J29) -> -0.057814712
F30: SOF | G30: Avg spills per overflow - difference to PCL | H30: % | I30: P45 | J30: 0.45 | K30: =_xlfn.PERCENTILE.INC($M$9:$Q$19,J30) -> -0.015988085
F31: SOF | G31: Avg spills per overflow - difference to PCL | H31: % | I31: P50 | J31: 0.5 | K31: =_xlfn.PERCENTILE.INC($M$9:$Q$19,J31) -> 0.023368073
F32: SOF | G32: Avg spills per overflow - difference to PCL | H32: % | I32: P55 | J32: 0.55 | K32: =_xlfn.PERCENTILE.INC($M$9:$Q$19,J32) -> 0.10120108
F33: SOF | G33: Avg spills per overflow - difference to PCL | H33: % | I33: P60 | J33: 0.6 | K33: =_xlfn.PERCENTILE.INC($M$9:$Q$19,J33) -> 0.13988191
F34: SOF | G34: Avg spills per overflow - difference to PCL | H34: % | I34: P65 | J34: 0.65 | K34: =_xlfn.PERCENTILE.INC($M$9:$Q$19,J34) -> 0.15595512
... F39: SOF | G39: Avg spills per overflow - difference to PCL | H39: % | I39: P90 | J39: 0.9 | K39: =_xlfn.PERCENTILE.INC($M$9:$Q$19,J39) -> 0.45191455
A41: END

Sheet Final Output
A1: =RIGHT(CELL("filename", A1), LEN(CELL("filename", A1)) - SEARCH("]", CELL("filename", A1))) -> Final Output
E3: Company | F3: Performance Commitment | G3: Measure | H3: Unit | I3: Percentile | K3: Value
A7: Percentiles, applicable to all WaSCs
F9: SOF | G9: Difference to PCL (As % of PCL) | H9: % | I9: P10 | K9: =Percentiles!K23 -> -0.40142909
F10: SOF | G10: Difference to PCL (As % of PCL) | H10: % | I10: P15 | K10: =Percentiles!K24 -> -0.3177821
F11: SOF | G11: Difference to PCL (As % of PCL) | H11: % | I11: P20 | K11: =Percentiles!K25 -> -0.25440862
F12: SOF | G12: Difference to PCL (As % of PCL) | H12: % | I12: P25 | K12: =Percentiles!K26 -> -0.23228625
F13: SOF | G13: Difference to PCL (As % of PCL) | H13: % | I13: P30 | K13: =Percentiles!K27 -> -0.21935247
F14: SOF | G14: Difference to PCL (As % of PCL) | H14: % | I14: P35 | K14: =Percentiles!K28 -> -0.16900096
F15: SOF | G15: Difference to PCL (As % of PCL) | H15: % | I15: P40 | K15: =Percentiles!K29 -> -0.057814712
F16: SOF | G16: Difference to PCL (As % of PCL) | H16: % | I16: P45 | K16: =Percentiles!K30 -> -0.015988085
F17: SOF | G17: Difference to PCL (As % of PCL) | H17: % | I17: P50 | K17: =Percentiles!K31 -> 0.023368073
F18: SOF | G18: Difference to PCL (As % of PCL) | H18: % | I18: P55 | K18: =Percentiles!K32 -> 0.10120108
F19: SOF | G19: Difference to PCL (As % of PCL) | H19: % | I19: P60 | K19: =Percentiles!K33 -> 0.13988191
F20: SOF | G20: Difference to PCL (As % of PCL) | H20: % | I20: P65 | K20: =Percentiles!K34 -> 0.15595512
... F25: SOF | G25: Difference to PCL (As % of PCL) | H25: % | I25: P90 | K25: =Percentiles!K39 -> 0.45191455
A27: END

Sheet F_Outputs
C1: _PR24OC02
A2: Acronym | B2: Reference | C2: Item description | D2: Unit | E2: Model | F2: Constant
A4: ANH | B4: PR24QA_PR24OC15_SOFFEED_OUT1 | C4: Date & Time for Model - PR24OC02 | D4: Text | E4: Price Review 2024 | F4: =CONCATENATE("[…]", TEXT(NOW(),"dd/mm/yyy hh:mm:ss")) -> […]12/12/2024 16:43:42
A5: ANH | B5: PR24QA_PR24OC15_SOFFEED_OUT2 | C5: Name of Model - PR24OC02 | D5: Text | E5: Price Review 2024 | F5: =MID(CELL("filename"),SEARCH("[",CELL("filename"))+1,SEARCH("]",CELL("filename"))-SEARCH("[",CELL("filename"))-1) -> PR24 FD OC15 ODI risk - Feeder Model (Storm Overflows).xlsx
A6: ANH | B6: PR24QA_PR24OC15_SOFFEED_OUT3 | C6: F_Inputs time stamp - PR24OC02 | D6: Text | E6: Price Review 2024 | F6: =F_Inputs!$E$1 -> Run on 13 Nov 2024 17:46
A7: ANH | B7: PR24QA_PR24OC15_SOFFEED_OUT4 | C7: Model override switch for - PR24OC02 | D7: nr | E7: Price Review 2024 | F7: N/A
A8: ANH | B8: C_ODIRISK_SOF_FEED_P10 | C8: Historic performance range Percentile (P10) for Storm Overflows Performance Commitment PR24 | D8: % | E8: Price Review 2024 | F8: ='Final Output'!K9 -> -0.40142909
A9: ANH | B9: C_ODIRISK_SOF_FEED_P15 | C9: Historic performance range Percentile (P15) for Storm Overflows Performance Commitment PR24 | D9: % | E9: Price Review 2024 | F9: ='Final Output'!K10 -> -0.3177821
A10: ANH | B10: C_ODIRISK_SOF_FEED_P20 | C10: Historic performance range Percentile (P20) for Storm Overflows Performance Commitment PR24 | D10: % | E10: Price Review 2024 | F10: ='Final Output'!K11 -> -0.25440862
A11: ANH | B11: C_ODIRISK_SOF_FEED_P25 | C11: Historic performance range Percentile (P25) for Storm Overflows Performance Commitment PR24 | D11: % | E11: Price Review 2024 | F11: ='Final Output'!K12 -> -0.23228625
A12: ANH | B12: C_ODIRISK_SOF_FEED_P30 | C12: Historic performance range Percentile (P30) for Storm Overflows Performance Commitment PR24 | D12: % | E12: Price Review 2024 | F12: ='Final Output'!K13 -> -0.21935247
A13: ANH | B13: C_ODIRISK_SOF_FEED_P35 | C13: Historic performance range Percentile (P35) for Storm Overflows Performance Commitment PR24 | D13: % | E13: Price Review 2024 | F13: ='Final Output'!K14 -> -0.16900096
A14: ANH | B14: C_ODIRISK_SOF_FEED_P40 | C14: Historic performance range Percentile (P40) for Storm Overflows Performance Commitment PR24 | D14: % | E14: Price Review 2024 | F14: ='Final Output'!K15 -> -0.057814712
A15: ANH | B15: C_ODIRISK_SOF_FEED_P45 | C15: Historic performance range Percentile (P45) for Storm Overflows Performance Commitment PR24 | D15: % | E15: Price Review 2024 | F15: ='Final Output'!K16 -> -0.015988085
A16: ANH | B16: C_ODIRISK_SOF_FEED_P50 | C16: Historic performance range Percentile (P50) for Storm Overflows Performance Commitment PR24 | D16: % | E16: Price Review 2024 | F16: ='Final Output'!K17 -> 0.023368073
A17: ANH | B17: C_ODIRISK_SOF_FEED_P55 | C17: Historic performance range Percentile (P55) for Storm Overflows Performance Commitment PR24 | D17: % | E17: Price Review 2024 | F17: ='Final Output'!K18 -> 0.10120108
A18: ANH | B18: C_ODIRISK_SOF_FEED_P60 | C18: Historic performance range Percentile (P60) for Storm Overflows Performance Commitment PR24 | D18: % | E18: Price Review 2024 | F18: ='Final Output'!K19 -> 0.13988191
A19: ANH | B19: C_ODIRISK_SOF_FEED_P65 | C19: Historic performance range Percentile (P65) for Storm Overflows Performance Commitment PR24 | D19: % | E19: Price Review 2024 | F19: ='Final Output'!K20 -> 0.15595512
... A24: ANH | B24: C_ODIRISK_SOF_FEED_P90 | C24: Historic performance range Percentile (P90) for Storm Overflows Performance Commitment PR24 | D24: % | E24: Price Review 2024 | F24: ='Final Output'!K25 -> 0.45191455
A25: WSH | B25: PR24QA_PR24OC15_SOFFEED_OUT1 | C25: Date & Time for Model - PR24OC02 | D25: Text | E25: Price Review 2024 | F25: =CONCATENATE("[…]", TEXT(NOW(),"dd/mm/yyy hh:mm:ss")) -> […]12/12/2024 16:43:42
A26: WSH | B26: PR24QA_PR24OC15_SOFFEED_OUT2 | C26: Name of Model - PR24OC02 | D26: Text | E26: Price Review 2024 | F26: =MID(CELL("filename"),SEARCH("[",CELL("filename"))+1,SEARCH("]",CELL("filename"))-SEARCH("[",CELL("filename"))-1) -> PR24 FD OC15 ODI risk - Feeder Model (Storm Overflows).xlsx
A27: WSH | B27: PR24QA_PR24OC15_SOFFEED_OUT3 | C27: F_Inputs time stamp - PR24OC02 | D27: Text | E27: Price Review 2024 | F27: =F_Inputs!$E$1 -> Run on 13 Nov 2024 17:46
A28: WSH | B28: PR24QA_PR24OC15_SOFFEED_OUT4 | C28: Model override switch for - PR24OC02 | D28: nr | E28: Price Review 2024 | F28: N/A
A29: WSH | B29: C_ODIRISK_SOF_FEED_P10 | C29: Historic performance range Percentile (P10) for Storm Overflows Performance Commitment PR24 | D29: % | E29: Price Review 2024 | F29: ='Final Output'!K9 -> -0.40142909
A30: WSH | B30: C_ODIRISK_SOF_FEED_P15 | C30: Historic performance range Percentile (P15) for Storm Overflows Performance Commitment PR24 | D30: % | E30: Price Review 2024 | F30: ='Final Output'!K10 -> -0.3177821
A31: WSH | B31: C_ODIRISK_SOF_FEED_P20 | C31: Historic performance range Percentile (P20) for Storm Overflows Performance Commitment PR24 | D31: % | E31: Price Review 2024 | F31: ='Final Output'!K11 -> -0.25440862
A32: WSH | B32: C_ODIRISK_SOF_FEED_P25 | C32: Historic performance range Percentile (P25) for Storm Overflows Performance Commitment PR24 | D32: % | E32: Price Review 2024 | F32: ='Final Output'!K12 -> -0.23228625
A33: WSH | B33: C_ODIRISK_SOF_FEED_P30 | C33: Historic performance range Percentile (P30) for Storm Overflows Performance Commitment PR24 | D33: % | E33: Price Review 2024 | F33: ='Final Output'!K13 -> -0.21935247
A34: WSH | B34: C_ODIRISK_SOF_FEED_P35 | C34: Historic performance range Percentile (P35) for Storm Overflows Performance Commitment PR24 | D34: % | E34: Price Review 2024 | F34: ='Final Output'!K14 -> -0.16900096
A35: WSH | B35: C_ODIRISK_SOF_FEED_P40 | C35: Historic performance range Percentile (P40) for Storm Overflows Performance Commitment PR24 | D35: % | E35: Price Review 2024 | F35: ='Final Output'!K15 -> -0.057814712
A36: WSH | B36: C_ODIRISK_SOF_FEED_P45 | C36: Historic performance range Percentile (P45) for Storm Overflows Performance Commitment PR24 | D36: % | E36: Price Review 2024 | F36: ='Final Output'!K16 -> -0.015988085
A37: WSH | B37: C_ODIRISK_SOF_FEED_P50 | C37: Historic performance range Percentile (P50) for Storm Overflows Performance Commitment PR24 | D37: % | E37: Price Review 2024 | F37: ='Final Output'!K17 -> 0.023368073
A38: WSH | B38: C_ODIRISK_SOF_FEED_P55 | C38: Historic performance range Percentile (P55) for Storm Overflows Performance Commitment PR24 | D38: % | E38: Price Review 2024 | F38: ='Final Output'!K18 -> 0.10120108
A39: WSH | B39: C_ODIRISK_SOF_FEED_P60 | C39: Historic performance range Percentile (P60) for Storm Overflows Performance Commitment PR24 | D39: % | E39: Price Review 2024 | F39: ='Final Output'!K19 -> 0.13988191
A40: WSH | B40: C_ODIRISK_SOF_FEED_P65 | C40: Historic performance range Percentile (P65) for Storm Overflows Performance Commitment PR24 | D40: % | E40: Price Review 2024 | F40: ='Final Output'!K20 -> 0.15595512
... A45: WSH | B45: C_ODIRISK_SOF_FEED_P90 | C45: Historic performance range Percentile (P90) for Storm Overflows Performance Commitment PR24 | D45: % | E45: Price Review 2024 | F45: ='Final Output'!K25 -> 0.45191455
A46: HDD | B46: PR24QA_PR24OC15_SOFFEED_OUT1 | C46: Date & Time for Model - PR24OC02 | D46: Text | E46: Price Review 2024 | F46: =CONCATENATE("[…]", TEXT(NOW(),"dd/mm/yyy hh:mm:ss")) -> […]12/12/2024 16:43:42
A47: HDD | B47: PR24QA_PR24OC15_SOFFEED_OUT2 | C47: Name of Model - PR24OC02 | D47: Text | E47: Price Review 2024 | F47: =MID(CELL("filename"),SEARCH("[",CELL("filename"))+1,SEARCH("]",CELL("filename"))-SEARCH("[",CELL("filename"))-1) -> PR24 FD OC15 ODI risk - Feeder Model (Storm Overflows).xlsx
A48: HDD | B48: PR24QA_PR24OC15_SOFFEED_OUT3 | C48: F_Inputs time stamp - PR24OC02 | D48: Text | E48: Price Review 2024 | F48: =F_Inputs!$E$1 -> Run on 13 Nov 2024 17:46
A49: HDD | B49: PR24QA_PR24OC15_SOFFEED_OUT4 | C49: Model override switch for - PR24OC02 | D49: nr | E49: Price Review 2024 | F49: N/A
...
