Workbook
Name _AtRisk_SimSetting_AutomaticallyGenerateReports: FALSE
Name _AtRisk_SimSetting_LiveUpdatePeriod: -1
Name _AtRisk_SimSetting_ReportOptionCustomItemsCount: 0
Name _AtRisk_SimSetting_ReportOptionDataMode: 1
Name _AtRisk_SimSetting_ReportOptionReportMultiSimType: 1
Name _AtRisk_SimSetting_ReportOptionReportPlacement: 1
Name _AtRisk_SimSetting_ReportOptionReportSelection: 257
Name _AtRisk_SimSetting_ReportOptionReportsFileType: 1
Name _AtRisk_SimSetting_ReportOptionSelectiveQR: FALSE
Name _AtRisk_SimSetting_ReportsList: 257
Name _AtRisk_SimSetting_StdRecalcWithoutRiskStatic: 0
Name _Order1: 255
Name _Order2: 255
Name F: {"bal",#N/A,FALSE,"working papers";"income",#N/A,FALSE,"working papers"}
Name fdraf: {"bal",#N/A,FALSE,"working papers";"income",#N/A,FALSE,"working papers"}
Name Fdraft: {"bal",#N/A,FALSE,"working papers";"income",#N/A,FALSE,"working papers"}
Name IQ_CH: 110000
Name IQ_CQ: 5000
Name IQ_CY: 10000
Name IQ_DAILY: 500000
Name IQ_DNTM: 700000
Name IQ_EXPENSE_CODE_: 80019595006
Name IQ_FH: 100000
Name IQ_FQ: 500
Name IQ_FWD_CY: 10001
Name IQ_FWD_CY1: 10002
Name IQ_FWD_CY2: 10003
Name IQ_FWD_FY: 1001
Name IQ_FWD_FY1: 1002
Name IQ_FWD_FY2: 1003
Name IQ_FWD_Q: 501
Name IQ_FWD_Q1: 502
Name IQ_FWD_Q2: 503
Name IQ_FY: 1000
Name IQ_LATESTK: 1000
Name IQ_LATESTQ: 500
Name IQ_LTM: 2000
Name IQ_LTMMONTH: 120000
Name IQ_MONTH: 15000
Name IQ_MTD: 800000
Name IQ_NAMES_REVISION_DATE_: 41366.3748958333
Name IQ_NTM: 6000
Name IQ_QTD: 750000
Name IQ_TODAY: 0
Name IQ_WEEK: 50000
Name IQ_YTD: 3000
Name IQ_YTDMONTH: 130000
Name RiskHasSettings: 5
Name RiskMultipleCPUSupportEnabled: TRUE
Name RiskUseMultipleCPUs: TRUE
Name SAPBEXrevision: 1
Name SAPBEXsysID: "BWB"
Name SAPBEXwbID: "49ZLUKBQR0WG29D9LLI3IBIIT"
Name wrn.papersdraft: {"bal",#N/A,FALSE,"working papers";"income",#N/A,FALSE,"working papers"}
Name wrn.wpapers.: {"bal",#N/A,FALSE,"working papers";"income",#N/A,FALSE,"working papers"}

Sheet Cover
A1: =RIGHT(CELL("filename", $A$1), LEN(CELL("filename", $A$1)) - SEARCH("]", CELL("filename", $A$1))) -> Cover
B3: PR24 [Model name]
B5: Model code | C5: PR24OC13
B6: Version number: | C6: 1
B7: File name: | C7: =MID(CELL("filename"), FIND("[", CELL("filename"), 1) + 1, FIND("]", CELL("filename"), 1) - FIND("[", CELL("filename"), 1) - 1) -> PR24 FD OC13 ODI risk - Feeder Model (Per Capita Consumption and Business Demand).xlsx
B8: Date: | C8: 45627
B10: For enquiries please contact: | C10: PR24@ofwat.gov.uk

Sheet Conceptual Model
A1: =RIGHT(CELL("filename", A1), LEN(CELL("filename", A1)) - SEARCH("]", CELL("filename", A1))) -> Conceptual Model
A3: Conceptual model
A28: End of sheet

Sheet F_Inputs
C1: ODI risk PCC NHH feeder inputs Run 11 | E1: Run on 06 Dec 2024 15:13
A2: Acronym | B2: Reference | C2: Item description | D2: Unit | E2: Model | F2: 2011-12 | G2: 2012-13 | H2: 2013-14 | I2: 2014-15 | J2: 2015-16 | K2: 2016-17 | L2: 2017-18 | M2: 2018-19 | N2: 2019-20 | O2: 2020-21 | P2: 2021-22 | Q2: 2022-23 | R2: 2023-24 | S2: 2024-25 | T2: 2025-26 | U2: 2026-27 | V2: 2027-28 | W2: 2028-29 | X2: 2029-30
F4: Price Review 2024 | G4: Price Review 2024 | H4: Price Review 2024 | I4: Price Review 2024 | J4: Price Review 2024 | K4: Price Review 2024 | L4: Price Review 2024 | M4: Price Review 2024 | N4: Price Review 2024 | O4: Price Review 2024 | P4: Price Review 2024 | Q4: Price Review 2024 | R4: Price Review 2024 | S4: Price Review 2024 | T4: Price Review 2024 | U4: Price Review 2024 | V4: Price Review 2024 | W4: Price Review 2024 | X4: Price Review 2024
F5: Run 11 - PR24 FD Data | G5: Run 11 - PR24 FD Data | H5: Run 11 - PR24 FD Data | I5: Run 11 - PR24 FD Data | J5: Run 11 - PR24 FD Data | K5: Run 11 - PR24 FD Data | L5: Run 11 - PR24 FD Data | M5: Run 11 - PR24 FD Data | N5: Run 11 - PR24 FD Data | O5: Run 11 - PR24 FD Data | P5: Run 11 - PR24 FD Data | Q5: Run 11 - PR24 FD Data | R5: Run 11 - PR24 FD Data | S5: Run 11 - PR24 FD Data | T5: Run 11 - PR24 FD Data | U5: Run 11 - PR24 FD Data | V5: Run 11 - PR24 FD Data | W5: Run 11 - PR24 FD Data | X5: Run 11 - PR24 FD Data
F6: Latest | G6: Latest | H6: Latest | I6: Latest | J6: Latest | K6: Latest | L6: Latest | M6: Latest | N6: Latest | O6: Latest | P6: Latest | Q6: Latest | R6: Latest | S6: Latest | T6: Latest | U6: Latest | V6: Latest | W6: Latest | X6: Latest
A7: ANH | B7: OUT4_08_C_PR24 | C7: Underlying calculations for common performance commitments - water and combined - Per capita consumption - Company level - 3- year average per capita consumption | D7: l/p/d | E7: Price Review 2024 | N7: 134.99391 | O7: 139.03659 | P7: 138.72994 | Q7: 138.40089 | R7: 131.94799 | S7: 128.49253 | T7: 125.766 | U7: 124.18519 | V7: 122.78208 | W7: 121.4104 | X7: 120.00612
A8: ANH | B8: OUT4_09_C_PR24 | C8: Underlying calculations for common performance commitments - water and combined - Per capita consumption - Region 1 - 3- year average per capita consumption | D8: l/p/d | E8: Price Review 2024
A9: ANH | B9: OUT4_10_C_PR24 | C9: Underlying calculations for common performance commitments - water and combined - Per capita consumption - Region 2 - 3- year average per capita consumption | D9: Ml/d | E9: Price Review 2024
A10: WSH | B10: OUT4_08_C_PR24 | C10: Underlying calculations for common performance commitments - water and combined - Per capita consumption - Company level - 3- year average per capita consumption | D10: l/p/d | E10: Price Review 2024 | N10: 145.70441 | O10: 151.45371 | P10: 153.85332 | Q10: 154.79902 | R10: 150.68517 | S10: 146.91938 | T10: 144.59678 | U10: 141.62183 | V10: 139.65934 | W10: 137.60481 | X10: 135.60175
A11: WSH | B11: OUT4_09_C_PR24 | C11: Underlying calculations for common performance commitments - water and combined - Per capita consumption - Region 1 - 3- year average per capita consumption | D11: l/p/d | E11: Price Review 2024
A12: WSH | B12: OUT4_10_C_PR24 | C12: Underlying calculations for common performance commitments - water and combined - Per capita consumption - Region 2 - 3- year average per capita consumption | D12: Ml/d | E12: Price Review 2024
A13: HDD | B13: OUT4_08_C_PR24 | C13: Underlying calculations for common performance commitments - water and combined - Per capita consumption - Company level - 3- year average per capita consumption | D13: l/p/d | E13: Price Review 2024 | N13: 128.94099 | O13: 131.37978 | P13: 133.65367 | Q13: 135.07889 | R13: 130.59066 | S13: 123.49266 | T13: 118.02873 | U13: 116.48674 | V13: 115.90576 | W13: 115.30173 | X13: 114.70465
A14: HDD | B14: OUT4_09_C_PR24 | C14: Underlying calculations for common performance commitments - water and combined - Per capita consumption - Region 1 - 3- year average per capita consumption | D14: l/p/d | E14: Price Review 2024
A15: HDD | B15: OUT4_10_C_PR24 | C15: Underlying calculations for common performance commitments - water and combined - Per capita consumption - Region 2 - 3- year average per capita consumption | D15: Ml/d | E15: Price Review 2024
A16: NES | B16: OUT4_08_C_PR24 | C16: Underlying calculations for common performance commitments - water and combined - Per capita consumption - Company level - 3- year average per capita consumption | D16: l/p/d | E16: Price Review 2024 | N16: 150.65617 | O16: 156.29896 | P16: 157.71714 | Q16: 159.10008 | R16: 154.71209 | S16: 151.62717 | T16: 148.61102 | U16: 144.77177 | V16: 141.38115 | W16: 138.46432 | X16: 136.02719
A17: NES | B17: OUT4_09_C_PR24 | C17: Underlying calculations for common performance commitments - water and combined - Per capita consumption - Region 1 - 3- year average per capita consumption | D17: l/p/d | E17: Price Review 2024 | N17: 145.94755 | O17: 152.265 | P17: 155.28117 | Q17: 157.89837 | R17: 154.40186 | S17: 151.32944 | T17: 148.52184 | U17: 144.7769 | V17: 141.34113 | W17: 138.42093 | X17: 136.18592
A18: NES | B18: OUT4_10_C_PR24 | C18: Underlying calculations for common performance commitments - water and combined - Per capita consumption - Region 2 - 3- year average per capita consumption | D18: Ml/d | E18: Price Review 2024 | N18: 156.82409 | O18: 161.57244 | P18: 160.90772 | Q18: 160.69273 | R18: 155.13372 | S18: 152.01813 | T18: 148.73045 | U18: 144.76652 | V18: 141.43265 | W18: 138.52037 | X18: 135.82498
A19: SVE | B19: OUT4_08_C_PR24 | C19: Underlying calculations for common performance commitments - water and combined - Per capita consumption - Company level - 3- year average per capita consumption | D19: l/p/d | E19: Price Review 2024 | N19: 133.7 | O19: 137.13333 | P19: 138.4 | Q19: 137.53196 | R19: 131.25653 | S19: 127.98986 | T19: 127.03628 | U19: 126.52741 | V19: 125.00121 | W19: 123.31585 | X19: 122.25949
A20: SVE | B20: OUT4_09_C_PR24 | C20: Underlying calculations for common performance commitments - water and combined - Per capita consumption - Region 1 - 3- year average per capita consumption | D20: l/p/d | E20: Price Review 2024
A21: SVE | B21: OUT4_10_C_PR24 | C21: Underlying calculations for common performance commitments - water and combined - Per capita consumption - Region 2 - 3- year average per capita consumption | D21: Ml/d | E21: Price Review 2024
A22: SWB | B22: OUT4_08_C_PR24 | C22: Underlying calculations for common performance commitments - water and combined - Per capita consumption - Company level - 3- year average per capita consumption | D22: l/p/d | E22: Price Review 2024 | N22: 146.01339 | O22: 144.91414 | P22: 142.08015 | Q22: 144.93632 | R22: 147.79297 | S22: 148.9641 | T22: 143.54028 | U22: 139.57829 | V22: 134.75471 | W22: 132.92231 | X22: 130.78333
A23: SWB | B23: OUT4_09_C_PR24 | C23: Underlying calculations for common performance commitments - water and combined - Per capita consumption - Region 1 - 3- year average per capita consumption | D23: l/p/d | E23: Price Review 2024
A24: SWB | B24: OUT4_10_C_PR24 | C24: Underlying calculations for common performance commitments - water and combined - Per capita consumption - Region 2 - 3- year average per capita consumption | D24: Ml/d | E24: Price Review 2024
A25: SRN | B25: OUT4_08_C_PR24 | C25: Underlying calculations for common performance commitments - water and combined - Per capita consumption - Company level - 3- year average per capita consumption | D25: l/p/d | E25: Price Review 2024 | N25: 127.96312 | O25: 131.74576 | P25: 132.77548 | Q25: 133.42672 | R25: 130.32224 | S25: 128.02381 | T25: 126.26921 | U25: 124.61679 | V25: 123.27735 | W25: 121.77751 | X25: 120.22837
A26: SRN | B26: OUT4_09_C_PR24 | C26: Underlying calculations for common performance commitments - water and combined - Per capita consumption - Region 1 - 3- year average per capita consumption | D26: l/p/d | E26: Price Review 2024
A27: SRN | B27: OUT4_10_C_PR24 | C27: Underlying calculations for common performance commitments - water and combined - Per capita consumption - Region 2 - 3- year average per capita consumption | D27: Ml/d | E27: Price Review 2024
A28: TMS | B28: OUT4_08_C_PR24 | C28: Underlying calculations for common performance commitments - water and combined - Per capita consumption - Company level - 3- year average per capita consumption | D28: l/p/d | E28: Price Review 2024 | N28: 145.22165 | O28: 147.55806 | P28: 146.71431 | Q28: 145.3399 | R28: 140.65564 | S28: 138.44162 | T28: 137.25947 | U28: 136.54341 | V28: 135.98907 | W28: 135.54767 | X28: 135.09967
A29: TMS | B29: OUT4_09_C_PR24 | C29: Underlying calculations for common performance commitments - water and combined - Per capita consumption - Region 1 - 3- year average per capita consumption | D29: l/p/d | E29: Price Review 2024
A30: TMS | B30: OUT4_10_C_PR24 | C30: Underlying calculations for common performance commitments - water and combined - Per capita consumption - Region 2 - 3- year average per capita consumption | D30: Ml/d | E30: Price Review 2024
A31: NWT | B31: OUT4_08_C_PR24 | C31: Underlying calculations for common performance commitments - water and combined - Per capita consumption - Company level - 3- year average per capita consumption | D31: l/p/d | E31: Price Review 2024 | N31: 144.03057 | O31: 146.54161 | P31: 146.06053 | Q31: 144.73074 | R31: 140.40208 | S31: 137.53127 | T31: 135.7 | U31: 133.8 | V31: 132.6 | W31: 131.4 | X31: 130.2
A32: NWT | B32: OUT4_09_C_PR24 | C32: Underlying calculations for common performance commitments - water and combined - Per capita consumption - Region 1 - 3- year average per capita consumption | D32: l/p/d | E32: Price Review 2024
A33: NWT | B33: OUT4_10_C_PR24 | C33: Underlying calculations for common performance commitments - water and combined - Per capita consumption - Region 2 - 3- year average per capita consumption | D33: Ml/d | E33: Price Review 2024
A34: WSX | B34: OUT4_08_C_PR24 | C34: Underlying calculations for common performance commitments - water and combined - Per capita consumption - Company level - 3- year average per capita consumption | D34: l/p/d | E34: Price Review 2024 | N34: 137.82381 | O34: 143.13763 | P34: 144.99667 | Q34: 145.15481 | R34: 138.83639 | S34: 136.94582 | T34: 136.81405 | U34: 138.04719 | V34: 136.60292 | W34: 134.89161 | X34: 133.24492
A35: WSX | B35: OUT4_09_C_PR24 | C35: Underlying calculations for common performance commitments - water and combined - Per capita consumption - Region 1 - 3- year average per capita consumption | D35: l/p/d | E35: Price Review 2024
A36: WSX | B36: OUT4_10_C_PR24 | C36: Underlying calculations for common performance commitments - water and combined - Per capita consumption - Region 2 - 3- year average per capita consumption | D36: Ml/d | E36: Price Review 2024
A37: YKY | B37: OUT4_08_C_PR24 | C37: Underlying calculations for common performance commitments - water and combined - Per capita consumption - Company level - 3- year average per capita consumption | D37: l/p/d | E37: Price Review 2024 | N37: 128.20209 | O37: 132.49049 | P37: 133.46147 | Q37: 132.18142 | R37: 126.90829 | S37: 124.77072 | T37: 124.85655 | U37: 124.04371 | V37: 122.91038 | W37: 121.68502 | X37: 120.47105
A38: YKY | B38: OUT4_09_C_PR24 | C38: Underlying calculations for common performance commitments - water and combined - Per capita consumption - Region 1 - 3- year average per capita consumption | D38: l/p/d | E38: Price Review 2024
A39: YKY | B39: OUT4_10_C_PR24 | C39: Underlying calculations for common performance commitments - water and combined - Per capita consumption - Region 2 - 3- year average per capita consumption | D39: Ml/d | E39: Price Review 2024
A40: AFW | B40: OUT4_08_C_PR24 | C40: Underlying calculations for common performance commitments - water and combined - Per capita consumption - Company level - 3- year average per capita consumption | D40: l/p/d | E40: Price Review 2024 | N40: 154.01456 | O40: 159.36159 | P40: 159.23321 | Q40: 160.63039 | R40: 156.29511 | S40: 150.39085 | T40: 144.15725 | U40: 138.35682 | V40: 136.75652 | W40: 135.38846 | X40: 134.17394
A41: AFW | B41: OUT4_09_C_PR24 | C41: Underlying calculations for common performance commitments - water and combined - Per capita consumption - Region 1 - 3- year average per capita consumption | D41: l/p/d | E41: Price Review 2024 | N41: 0 | O41: 0 | P41: 0 | Q41: 0 | R41: 0 | S41: 0 | T41: 0 | U41: 0 | V41: 0 | W41: 0 | X41: 0
...

Sheet PCC.Inputs
A1: =RIGHT(CELL("filename", A1), LEN(CELL("filename", A1)) - SEARCH("]", CELL("filename", A1))) -> PCC.Inputs
L2: 2014-15 | M2: 2015-16 | N2: 2016-17 | O2: 2017-18 | P2: 2018-19 | Q2: 2019-20 | R2: 2020-21 | S2: 2021-22 | T2: 2022-23 | U2: 2023-24 | V2: 2024-25
E3: Company | F3: Performance Commitment | G3: Measure | H3: Unit | I3: Helper 1 | J3: Helper 2
A7: PCC Performance as reported in business plan submissions
E9: ANH | F9: PCC | G9: 3-Year average consumption | H9: l/p/d | I9: {=_xlfn.IFS(E9="UUW","NWT",OR(E9="NES (NNE)",E9="NES (ESK)"),"NES",OR(E9="SSC (SST)",E9="SSC (CAM)"),"SSC",TRUE,E9)} -> ANH | J9: OUT4_08_C_PR24 | Q9: =SUMIFS(F_Inputs!N$7:N$132,F_Inputs!$A$7:$A$132,PCC.Inputs!$I9,F_Inputs!$B$7:$B$132,PCC.Inputs!$J9) -> 134.99391 | R9: =SUMIFS(F_Inputs!O$7:O$132,F_Inputs!$A$7:$A$132,PCC.Inputs!$I9,F_Inputs!$B$7:$B$132,PCC.Inputs!$J9) -> 139.03659 | S9: =SUMIFS(F_Inputs!P$7:P$132,F_Inputs!$A$7:$A$132,PCC.Inputs!$I9,F_Inputs!$B$7:$B$132,PCC.Inputs!$J9) -> 138.72994 | T9: =SUMIFS(F_Inputs!Q$7:Q$132,F_Inputs!$A$7:$A$132,PCC.Inputs!$I9,F_Inputs!$B$7:$B$132,PCC.Inputs!$J9) -> 138.40089 | U9: =SUMIFS(F_Inputs!R$7:R$132,F_Inputs!$A$7:$A$132,PCC.Inputs!$I9,F_Inputs!$B$7:$B$132,PCC.Inputs!$J9) -> 131.94799
E10: WSH | F10: PCC | G10: 3-Year average consumption | H10: l/p/d | I10: {=_xlfn.IFS(E10="UUW","NWT",OR(E10="NES (NNE)",E10="NES (ESK)"),"NES",OR(E10="SSC (SST)",E10="SSC (CAM)"),"SSC",TRUE,E10)} -> WSH | J10: OUT4_08_C_PR24 | Q10: =SUMIFS(F_Inputs!N$7:N$132,F_Inputs!$A$7:$A$132,PCC.Inputs!$I10,F_Inputs!$B$7:$B$132,PCC.Inputs!$J10) -> 145.70441 | R10: =SUMIFS(F_Inputs!O$7:O$132,F_Inputs!$A$7:$A$132,PCC.Inputs!$I10,F_Inputs!$B$7:$B$132,PCC.Inputs!$J10) -> 151.45371 | S10: =SUMIFS(F_Inputs!P$7:P$132,F_Inputs!$A$7:$A$132,PCC.Inputs!$I10,F_Inputs!$B$7:$B$132,PCC.Inputs!$J10) -> 153.85332 | T10: =SUMIFS(F_Inputs!Q$7:Q$132,F_Inputs!$A$7:$A$132,PCC.Inputs!$I10,F_Inputs!$B$7:$B$132,PCC.Inputs!$J10) -> 154.79902 | U10: =SUMIFS(F_Inputs!R$7:R$132,F_Inputs!$A$7:$A$132,PCC.Inputs!$I10,F_Inputs!$B$7:$B$132,PCC.Inputs!$J10) -> 150.68517
E11: HDD | F11: PCC | G11: 3-Year average consumption | H11: l/p/d | I11: {=_xlfn.IFS(E11="UUW","NWT",OR(E11="NES (NNE)",E11="NES (ESK)"),"NES",OR(E11="SSC (SST)",E11="SSC (CAM)"),"SSC",TRUE,E11)} -> HDD | J11: OUT4_08_C_PR24 | Q11: =SUMIFS(F_Inputs!N$7:N$132,F_Inputs!$A$7:$A$132,PCC.Inputs!$I11,F_Inputs!$B$7:$B$132,PCC.Inputs!$J11) -> 128.94099 | R11: =SUMIFS(F_Inputs!O$7:O$132,F_Inputs!$A$7:$A$132,PCC.Inputs!$I11,F_Inputs!$B$7:$B$132,PCC.Inputs!$J11) -> 131.37978 | S11: =SUMIFS(F_Inputs!P$7:P$132,F_Inputs!$A$7:$A$132,PCC.Inputs!$I11,F_Inputs!$B$7:$B$132,PCC.Inputs!$J11) -> 133.65367 | T11: =SUMIFS(F_Inputs!Q$7:Q$132,F_Inputs!$A$7:$A$132,PCC.Inputs!$I11,F_Inputs!$B$7:$B$132,PCC.Inputs!$J11) -> 135.07889 | U11: =SUMIFS(F_Inputs!R$7:R$132,F_Inputs!$A$7:$A$132,PCC.Inputs!$I11,F_Inputs!$B$7:$B$132,PCC.Inputs!$J11) -> 130.59066
E12: NES | F12: PCC | G12: 3-Year average consumption | H12: l/p/d | I12: {=_xlfn.IFS(E12="UUW","NWT",OR(E12="NES (NNE)",E12="NES (ESK)"),"NES",OR(E12="SSC (SST)",E12="SSC (CAM)"),"SSC",TRUE,E12)} -> NES | J12: OUT4_08_C_PR24 | Q12: =SUMIFS(F_Inputs!N$7:N$132,F_Inputs!$A$7:$A$132,PCC.Inputs!$I12,F_Inputs!$B$7:$B$132,PCC.Inputs!$J12) -> 150.65617 | R12: =SUMIFS(F_Inputs!O$7:O$132,F_Inputs!$A$7:$A$132,PCC.Inputs!$I12,F_Inputs!$B$7:$B$132,PCC.Inputs!$J12) -> 156.29896 | S12: =SUMIFS(F_Inputs!P$7:P$132,F_Inputs!$A$7:$A$132,PCC.Inputs!$I12,F_Inputs!$B$7:$B$132,PCC.Inputs!$J12) -> 157.71714 | T12: =SUMIFS(F_Inputs!Q$7:Q$132,F_Inputs!$A$7:$A$132,PCC.Inputs!$I12,F_Inputs!$B$7:$B$132,PCC.Inputs!$J12) -> 159.10008 | U12: =SUMIFS(F_Inputs!R$7:R$132,F_Inputs!$A$7:$A$132,PCC.Inputs!$I12,F_Inputs!$B$7:$B$132,PCC.Inputs!$J12) -> 154.71209
E13: NES (NNE) | F13: PCC | G13: 3-Year average consumption (Region 1) | H13: l/p/d | I13: {=_xlfn.IFS(E13="UUW","NWT",OR(E13="NES (NNE)",E13="NES (ESK)"),"NES",OR(E13="SSC (SST)",E13="SSC (CAM)"),"SSC",TRUE,E13)} -> NES | J13: OUT4_09_C_PR24 | Q13: =SUMIFS(F_Inputs!N$7:N$132,F_Inputs!$A$7:$A$132,PCC.Inputs!$I13,F_Inputs!$B$7:$B$132,PCC.Inputs!$J13) -> 145.94755 | R13: =SUMIFS(F_Inputs!O$7:O$132,F_Inputs!$A$7:$A$132,PCC.Inputs!$I13,F_Inputs!$B$7:$B$132,PCC.Inputs!$J13) -> 152.265 | S13: =SUMIFS(F_Inputs!P$7:P$132,F_Inputs!$A$7:$A$132,PCC.Inputs!$I13,F_Inputs!$B$7:$B$132,PCC.Inputs!$J13) -> 155.28117 | T13: =SUMIFS(F_Inputs!Q$7:Q$132,F_Inputs!$A$7:$A$132,PCC.Inputs!$I13,F_Inputs!$B$7:$B$132,PCC.Inputs!$J13) -> 157.89837 | U13: =SUMIFS(F_Inputs!R$7:R$132,F_Inputs!$A$7:$A$132,PCC.Inputs!$I13,F_Inputs!$B$7:$B$132,PCC.Inputs!$J13) -> 154.40186
E14: NES (ESK) | F14: PCC | G14: 3-Year average consumption (Region 2) | H14: l/p/d | I14: {=_xlfn.IFS(E14="UUW","NWT",OR(E14="NES (NNE)",E14="NES (ESK)"),"NES",OR(E14="SSC (SST)",E14="SSC (CAM)"),"SSC",TRUE,E14)} -> NES | J14: OUT4_10_C_PR24 | Q14: =SUMIFS(F_Inputs!N$7:N$132,F_Inputs!$A$7:$A$132,PCC.Inputs!$I14,F_Inputs!$B$7:$B$132,PCC.Inputs!$J14) -> 156.82409 | R14: =SUMIFS(F_Inputs!O$7:O$132,F_Inputs!$A$7:$A$132,PCC.Inputs!$I14,F_Inputs!$B$7:$B$132,PCC.Inputs!$J14) -> 161.57244 | S14: =SUMIFS(F_Inputs!P$7:P$132,F_Inputs!$A$7:$A$132,PCC.Inputs!$I14,F_Inputs!$B$7:$B$132,PCC.Inputs!$J14) -> 160.90772 | T14: =SUMIFS(F_Inputs!Q$7:Q$132,F_Inputs!$A$7:$A$132,PCC.Inputs!$I14,F_Inputs!$B$7:$B$132,PCC.Inputs!$J14) -> 160.69273 | U14: =SUMIFS(F_Inputs!R$7:R$132,F_Inputs!$A$7:$A$132,PCC.Inputs!$I14,F_Inputs!$B$7:$B$132,PCC.Inputs!$J14) -> 155.13372
E15: SVE | F15: PCC | G15: 3-Year average consumption | H15: l/p/d | I15: {=_xlfn.IFS(E15="UUW","NWT",OR(E15="NES (NNE)",E15="NES (ESK)"),"NES",OR(E15="SSC (SST)",E15="SSC (CAM)"),"SSC",TRUE,E15)} -> SVE | J15: OUT4_08_C_PR24 | Q15: =SUMIFS(F_Inputs!N$7:N$132,F_Inputs!$A$7:$A$132,PCC.Inputs!$I15,F_Inputs!$B$7:$B$132,PCC.Inputs!$J15) -> 133.7 | R15: =SUMIFS(F_Inputs!O$7:O$132,F_Inputs!$A$7:$A$132,PCC.Inputs!$I15,F_Inputs!$B$7:$B$132,PCC.Inputs!$J15) -> 137.13333 | S15: =SUMIFS(F_Inputs!P$7:P$132,F_Inputs!$A$7:$A$132,PCC.Inputs!$I15,F_Inputs!$B$7:$B$132,PCC.Inputs!$J15) -> 138.4 | T15: =SUMIFS(F_Inputs!Q$7:Q$132,F_Inputs!$A$7:$A$132,PCC.Inputs!$I15,F_Inputs!$B$7:$B$132,PCC.Inputs!$J15) -> 137.53196 | U15: =SUMIFS(F_Inputs!R$7:R$132,F_Inputs!$A$7:$A$132,PCC.Inputs!$I15,F_Inputs!$B$7:$B$132,PCC.Inputs!$J15) -> 131.25653
E16: SWB | F16: PCC | G16: 3-Year average consumption | H16: l/p/d | I16: {=_xlfn.IFS(E16="UUW","NWT",OR(E16="NES (NNE)",E16="NES (ESK)"),"NES",OR(E16="SSC (SST)",E16="SSC (CAM)"),"SSC",TRUE,E16)} -> SWB | J16: OUT4_08_C_PR24 | Q16: =SUMIFS(F_Inputs!N$7:N$132,F_Inputs!$A$7:$A$132,PCC.Inputs!$I16,F_Inputs!$B$7:$B$132,PCC.Inputs!$J16) -> 146.01339 | R16: =SUMIFS(F_Inputs!O$7:O$132,F_Inputs!$A$7:$A$132,PCC.Inputs!$I16,F_Inputs!$B$7:$B$132,PCC.Inputs!$J16) -> 144.91414 | S16: =SUMIFS(F_Inputs!P$7:P$132,F_Inputs!$A$7:$A$132,PCC.Inputs!$I16,F_Inputs!$B$7:$B$132,PCC.Inputs!$J16) -> 142.08015 | T16: =SUMIFS(F_Inputs!Q$7:Q$132,F_Inputs!$A$7:$A$132,PCC.Inputs!$I16,F_Inputs!$B$7:$B$132,PCC.Inputs!$J16) -> 144.93632 | U16: =SUMIFS(F_Inputs!R$7:R$132,F_Inputs!$A$7:$A$132,PCC.Inputs!$I16,F_Inputs!$B$7:$B$132,PCC.Inputs!$J16) -> 147.79297
E17: SRN | F17: PCC | G17: 3-Year average consumption | H17: l/p/d | I17: {=_xlfn.IFS(E17="UUW","NWT",OR(E17="NES (NNE)",E17="NES (ESK)"),"NES",OR(E17="SSC (SST)",E17="SSC (CAM)"),"SSC",TRUE,E17)} -> SRN | J17: OUT4_08_C_PR24 | Q17: =SUMIFS(F_Inputs!N$7:N$132,F_Inputs!$A$7:$A$132,PCC.Inputs!$I17,F_Inputs!$B$7:$B$132,PCC.Inputs!$J17) -> 127.96312 | R17: =SUMIFS(F_Inputs!O$7:O$132,F_Inputs!$A$7:$A$132,PCC.Inputs!$I17,F_Inputs!$B$7:$B$132,PCC.Inputs!$J17) -> 131.74576 | S17: =SUMIFS(F_Inputs!P$7:P$132,F_Inputs!$A$7:$A$132,PCC.Inputs!$I17,F_Inputs!$B$7:$B$132,PCC.Inputs!$J17) -> 132.77548 | T17: =SUMIFS(F_Inputs!Q$7:Q$132,F_Inputs!$A$7:$A$132,PCC.Inputs!$I17,F_Inputs!$B$7:$B$132,PCC.Inputs!$J17) -> 133.42672 | U17: =SUMIFS(F_Inputs!R$7:R$132,F_Inputs!$A$7:$A$132,PCC.Inputs!$I17,F_Inputs!$B$7:$B$132,PCC.Inputs!$J17) -> 130.32224
E18: TMS | F18: PCC | G18: 3-Year average consumption | H18: l/p/d | I18: {=_xlfn.IFS(E18="UUW","NWT",OR(E18="NES (NNE)",E18="NES (ESK)"),"NES",OR(E18="SSC (SST)",E18="SSC (CAM)"),"SSC",TRUE,E18)} -> TMS | J18: OUT4_08_C_PR24 | Q18: =SUMIFS(F_Inputs!N$7:N$132,F_Inputs!$A$7:$A$132,PCC.Inputs!$I18,F_Inputs!$B$7:$B$132,PCC.Inputs!$J18) -> 145.22165 | R18: =SUMIFS(F_Inputs!O$7:O$132,F_Inputs!$A$7:$A$132,PCC.Inputs!$I18,F_Inputs!$B$7:$B$132,PCC.Inputs!$J18) -> 147.55806 | S18: =SUMIFS(F_Inputs!P$7:P$132,F_Inputs!$A$7:$A$132,PCC.Inputs!$I18,F_Inputs!$B$7:$B$132,PCC.Inputs!$J18) -> 146.71431 | T18: =SUMIFS(F_Inputs!Q$7:Q$132,F_Inputs!$A$7:$A$132,PCC.Inputs!$I18,F_Inputs!$B$7:$B$132,PCC.Inputs!$J18) -> 145.3399 | U18: =SUMIFS(F_Inputs!R$7:R$132,F_Inputs!$A$7:$A$132,PCC.Inputs!$I18,F_Inputs!$B$7:$B$132,PCC.Inputs!$J18) -> 140.65564
E19: UUW | F19: PCC | G19: 3-Year average consumption | H19: l/p/d | I19: {=_xlfn.IFS(E19="UUW","NWT",OR(E19="NES (NNE)",E19="NES (ESK)"),"NES",OR(E19="SSC (SST)",E19="SSC (CAM)"),"SSC",TRUE,E19)} -> NWT | J19: OUT4_08_C_PR24 | Q19: =SUMIFS(F_Inputs!N$7:N$132,F_Inputs!$A$7:$A$132,PCC.Inputs!$I19,F_Inputs!$B$7:$B$132,PCC.Inputs!$J19) -> 144.03057 | R19: =SUMIFS(F_Inputs!O$7:O$132,F_Inputs!$A$7:$A$132,PCC.Inputs!$I19,F_Inputs!$B$7:$B$132,PCC.Inputs!$J19) -> 146.54161 | S19: =SUMIFS(F_Inputs!P$7:P$132,F_Inputs!$A$7:$A$132,PCC.Inputs!$I19,F_Inputs!$B$7:$B$132,PCC.Inputs!$J19) -> 146.06053 | T19: =SUMIFS(F_Inputs!Q$7:Q$132,F_Inputs!$A$7:$A$132,PCC.Inputs!$I19,F_Inputs!$B$7:$B$132,PCC.Inputs!$J19) -> 144.73074 | U19: =SUMIFS(F_Inputs!R$7:R$132,F_Inputs!$A$7:$A$132,PCC.Inputs!$I19,F_Inputs!$B$7:$B$132,PCC.Inputs!$J19) -> 140.40208
E20: WSX | F20: PCC | G20: 3-Year average consumption | H20: l/p/d | I20: {=_xlfn.IFS(E20="UUW","NWT",OR(E20="NES (NNE)",E20="NES (ESK)"),"NES",OR(E20="SSC (SST)",E20="SSC (CAM)"),"SSC",TRUE,E20)} -> WSX | J20: OUT4_08_C_PR24 | Q20: =SUMIFS(F_Inputs!N$7:N$132,F_Inputs!$A$7:$A$132,PCC.Inputs!$I20,F_Inputs!$B$7:$B$132,PCC.Inputs!$J20) -> 137.82381 | R20: =SUMIFS(F_Inputs!O$7:O$132,F_Inputs!$A$7:$A$132,PCC.Inputs!$I20,F_Inputs!$B$7:$B$132,PCC.Inputs!$J20) -> 143.13763 | S20: =SUMIFS(F_Inputs!P$7:P$132,F_Inputs!$A$7:$A$132,PCC.Inputs!$I20,F_Inputs!$B$7:$B$132,PCC.Inputs!$J20) -> 144.99667 | T20: =SUMIFS(F_Inputs!Q$7:Q$132,F_Inputs!$A$7:$A$132,PCC.Inputs!$I20,F_Inputs!$B$7:$B$132,PCC.Inputs!$J20) -> 145.15481 | U20: =SUMIFS(F_Inputs!R$7:R$132,F_Inputs!$A$7:$A$132,PCC.Inputs!$I20,F_Inputs!$B$7:$B$132,PCC.Inputs!$J20) -> 138.83639
... E29: SES | F29: PCC | G29: 3-Year average consumption | H29: l/p/d | I29: {=_xlfn.IFS(E29="UUW","NWT",OR(E29="NES (NNE)",E29="NES (ESK)"),"NES",OR(E29="SSC (SST)",E29="SSC (CAM)"),"SSC",TRUE,E29)} -> SES | J29: OUT4_08_C_PR24 | Q29: =SUMIFS(F_Inputs!N$7:N$132,F_Inputs!$A$7:$A$132,PCC.Inputs!$I29,F_Inputs!$B$7:$B$132,PCC.Inputs!$J29) -> 149.00575 | R29: =SUMIFS(F_Inputs!O$7:O$132,F_Inputs!$A$7:$A$132,PCC.Inputs!$I29,F_Inputs!$B$7:$B$132,PCC.Inputs!$J29) -> 154.59017 | S29: =SUMIFS(F_Inputs!P$7:P$132,F_Inputs!$A$7:$A$132,PCC.Inputs!$I29,F_Inputs!$B$7:$B$132,PCC.Inputs!$J29) -> 152.6352 | T29: =SUMIFS(F_Inputs!Q$7:Q$132,F_Inputs!$A$7:$A$132,PCC.Inputs!$I29,F_Inputs!$B$7:$B$132,PCC.Inputs!$J29) -> 155.13209 | U29: =SUMIFS(F_Inputs!R$7:R$132,F_Inputs!$A$7:$A$132,PCC.Inputs!$I29,F_Inputs!$B$7:$B$132,PCC.Inputs!$J29) -> 149.39938
A31: PCC performance (reported in terms of historical reporting methodologies)
E33: ANH | F33: PCC | G33: 3-Year average consumption | H33: l/p/d | L33: 133.3 | M33: 135.4 | N33: 135.6 | O33: 136.8 | P33: 136.9
E34: WSH | F34: PCC | G34: 3-Year average consumption | H34: l/p/d | L34: - | M34: - | N34: - | O34: - | P34: -
E35: HDD | F35: PCC | G35: 3-Year average consumption | H35: l/p/d | L35: - | M35: - | N35: - | O35: - | P35: 141.4
E36: NES | F36: PCC | G36: 3-Year average consumption | H36: l/p/d | L36: - | M36: - | N36: - | O36: - | P36: -
E37: NES (NNE) | F37: PCC | G37: 3-Year average consumption (Region 1) | H37: l/p/d | L37: - | M37: - | N37: - | O37: - | P37: -
E38: NES (ESK) | F38: PCC | G38: 3-Year average consumption (Region 2) | H38: l/p/d | L38: - | M38: - | N38: - | O38: - | P38: -
E39: SVE | F39: PCC | G39: 3-Year average consumption | H39: l/p/d | L39: - | M39: - | N39: - | O39: - | P39: 132.76
E40: SWB | F40: PCC | G40: 3-Year average consumption | H40: l/p/d | L40: - | M40: - | N40: - | O40: - | P40: -
E41: SRN | F41: PCC | G41: 3-Year average consumption | H41: l/p/d | L41: 134.8 | M41: 129.7 | N41: 131.29 | O41: 128.9 | P41: 129.9
E42: TMS | F42: PCC | G42: 3-Year average consumption | H42: l/p/d | L42: 150.71411 | M42: 150.31192 | N42: 149.90972 | O42: 149.50753 | P42: 149.10533
E43: UUW | F43: PCC | G43: 3-Year average consumption | H43: l/p/d | L43: 130 | M43: 129.6 | N43: 138.9 | O43: 141.9 | P43: 143.7
E44: WSX | F44: PCC | G44: 3-Year average consumption | H44: l/p/d | L44: 138 | M44: 137.6 | N44: 140.7 | O44: 142.8 | P44: 146.2
E45: YKY | F45: PCC | G45: 3-Year average consumption | H45: l/p/d | L45: 133.3 | M45: 133.1 | N45: 134.5 | O45: 133 | P45: 133.5
E46: AFW | F46: PCC | G46: 3-Year average consumption | H46: l/p/d | L46: 148.3 | M46: 151.6 | N46: 153.8 | O46: 151 | P46: 158.8
E47: BRL | F47: PCC | G47: 3-Year average consumption | H47: l/p/d | L47: 143 | M47: 141.1 | N47: 144.1 | O47: 144.5 | P47: 148.3
E48: SSC | F48: PCC | G48: 3-Year average consumption | H48: l/p/d | L48: 129.25 | M48: 129.59 | N48: 129.85 | O48: 133.09 | P48: 136.41
E49: SSC (SST) | F49: PCC | G49: 3-Year average consumption (Region 1) | H49: l/p/d | L49: - | M49: - | N49: - | O49: - | P49: -
E50: SSC (CAM) | F50: PCC | G50: 3-Year average consumption (Region 2) | H50: l/p/d | L50: - | M50: - | N50: - | O50: - | P50: -
E51: PRT | F51: PCC | G51: 3-Year average consumption | H51: l/p/d | L51: 145.55 | M51: 143.29 | N51: 145.1 | O51: 147.54 | P51: 152.39
E52: SEW | F52: PCC | G52: 3-Year average consumption | H52: l/p/d | L52: - | M52: - | N52: - | O52: - | P52: -
E53: SES | F53: PCC | G53: 3-Year average consumption | H53: l/p/d | L53: 161.1 | M53: 160.9 | N53: 159.73 | O53: 158.8 | P53: 162.62
A55: Historical Performance Commitment Level (PCL) for PR14
...

Sheet NHH.Inputs
A1: =RIGHT(CELL("filename", A1), LEN(CELL("filename", A1)) - SEARCH("]", CELL("filename", A1))) -> NHH.Inputs
K2: 2011-12 | L2: 2012-13 | M2: 2013-14 | N2: 2014-15 | O2: 2015-16 | P2: 2016-17 | Q2: 2017-18 | R2: 2018-19 | S2: 2019-20 | T2: 2020-21 | U2: 2021-22 | V2: 2022-23
E3: Company | F3: Performance Commitment | G3: Measure | H3: Unit | I3: Helper 1
A7: NHH Performance - Measured consumption (August 2022 Data Request for Enhancement and Water Balance)
E9: ANH | F9: NHH | G9: Measured non-household consumption (excluding supply pipe leakage) | H9: Ml/d | K9: 256.1867 | L9: 268.71515 | M9: 271.7221 | N9: 269.13362 | O9: 266.5032 | P9: 266.79385 | Q9: 273.94122 | R9: 290.27595 | S9: 283.89642
E10: WSH | F10: NHH | G10: Measured non-household consumption (excluding supply pipe leakage) | H10: Ml/d | K10: 180.5219 | L10: 167.38959 | M10: 170.56505 | N10: 174.88707 | O10: 168.65168 | P10: 173.24099 | Q10: 168.75674 | R10: 177.95661 | S10: 174.23922
E11: HDD | F11: NHH | G11: Measured non-household consumption (excluding supply pipe leakage) | H11: Ml/d | K11: 18.63832 | L11: 17.402594 | M11: 17.267477 | N11: 18.428015 | O11: 17.031067 | P11: 18.454921 | Q11: 18.640562 | R11: 14.757258 | S11: 14.412148
E12: NES | F12: NHH | G12: Measured non-household consumption (excluding supply pipe leakage) | H12: Ml/d | K12: 248.5 | L12: 232.83 | M12: 227.61 | N12: 226 | O12: 216.34 | P12: 226.86 | Q12: 214.54 | R12: 212.08 | S12: 210.35
E13: NES (NNE) | F13: NHH | G13: Measured non-household consumption (excluding supply pipe leakage) | H13: Ml/d | K13: 157.14 | L13: 152.21 | M13: 149.84 | N13: 149.5 | O13: 141.3 | P13: 146.43 | Q13: 139.32 | R13: 138.85 | S13: 137.7
E14: NES (ESK) | F14: NHH | G14: Measured non-household consumption (excluding supply pipe leakage) | H14: Ml/d | K14: 91.36 | L14: 80.62 | M14: 77.78 | N14: 76.5 | O14: 75.03 | P14: 80.42 | Q14: 75.22 | R14: 73.22 | S14: 72.65
E15: SVE | F15: NHH | G15: Measured non-household consumption (excluding supply pipe leakage) | H15: Ml/d | K15: 366.54773 | L15: 346.71925 | M15: 350.78411 | N15: 358.739 | O15: 369.66149 | P15: 356.78522 | Q15: 352.5347 | R15: 367.09314 | S15: 362.51228
E16: SWB | F16: NHH | G16: Measured non-household consumption (excluding supply pipe leakage) | H16: Ml/d | K16: 152.56568 | L16: 146.98318 | M16: 147.18615 | N16: 148.7949 | O16: 146.81682 | P16: 142.16004 | Q16: 142.68138 | R16: 149.34904 | S16: 137.34842
E17: SRN | F17: NHH | G17: Measured non-household consumption (excluding supply pipe leakage) | H17: Ml/d | K17: 89.0822 | L17: 98.629271 | M17: 98.482497 | N17: 100.9972 | O17: 103.04 | P17: 104.7557 | Q17: 112.90667 | R17: 115.31615 | S17: 108.43522
E18: TMS | F18: NHH | G18: Measured non-household consumption (excluding supply pipe leakage) | H18: Ml/d | K18: 480.82 | L18: 470.58 | M18: 485.54 | N18: 492.69 | O18: 484.15 | P18: 461.7 | Q18: 475.68 | R18: 464.63 | S18: 445.91294
E19: UUW | F19: NHH | G19: Measured non-household consumption (excluding supply pipe leakage) | H19: Ml/d | K19: 364.3366 | L19: 359.9819 | M19: 350.12891 | N19: 352.39186 | O19: 360.35446 | P19: 358.14049 | Q19: 351.89174 | R19: 363.44415 | S19: 364.49178
E20: WSX | F20: NHH | G20: Measured non-household consumption (excluding supply pipe leakage) | H20: Ml/d | K20: 83.39 | L20: 78.98 | M20: 81.87 | N20: 81.55 | O20: 81.43 | P20: 80.56 | Q20: 81.38 | R20: 83.52 | S20: 78.93
... E29: SES | F29: NHH | G29: Measured non-household consumption (excluding supply pipe leakage) | H29: Ml/d | K29: 24.512609 | L29: 23.8 | M29: 23.84 | N29: 24.48 | O29: 25.24 | P29: 25.77 | Q29: 23.26 | R29: 22.77 | S29: 23.26
A31: NHH Performance - Unmeasured consumption (August 2022 Data Request for Enhancement and Water Balance)
E33: ANH | F33: NHH | G33: Unmeasured non-household consumption (excluding supply pipe leakage) | H33: Ml/d | K33: 2.0107364 | L33: 1.8926338 | M33: 1.6357996 | N33: 1.4424881 | O33: 1.2227961 | P33: 1.1053871 | Q33: 0.75669702 | R33: 0.86105746 | S33: 0.82332588
E34: WSH | F34: NHH | G34: Unmeasured non-household consumption (excluding supply pipe leakage) | H34: Ml/d | K34: 5.1757947 | L34: 4.2704361 | M34: 4.3296226 | N34: 5.1460452 | O34: 4.7213679 | P34: 5.3633145 | Q34: 5.4128831 | R34: 5.6156115 | S34: 4.0029973
E35: HDD | F35: NHH | G35: Unmeasured non-household consumption (excluding supply pipe leakage) | H35: Ml/d | K35: 0.43687176 | L35: 0.58092877 | M35: 0.51654215 | N35: 0.40652966 | O35: 0.3478012 | P35: 0.67637251 | Q35: 0.71599 | R35: 1.2243589 | S35: 1.2967766
E36: NES | F36: NHH | G36: Unmeasured non-household consumption (excluding supply pipe leakage) | H36: Ml/d | K36: 6.25 | L36: 5.85 | M36: 5.77 | N36: 4.92 | O36: 6.31 | P36: 6.11 | Q36: 6.17 | R36: 5.92 | S36: 4.73
E37: NES (NNE) | F37: NHH | G37: Unmeasured non-household consumption (excluding supply pipe leakage) | H37: Ml/d | K37: 5.1 | L37: 4.76 | M37: 4.71 | N37: 3.91 | O37: 5.33 | P37: 4.99 | Q37: 5.07 | R37: 4.9 | S37: 3.77
E38: NES (ESK) | F38: NHH | G38: Unmeasured non-household consumption (excluding supply pipe leakage) | H38: Ml/d | K38: 1.15 | L38: 1.09 | M38: 1.06 | N38: 1.01 | O38: 0.98 | P38: 1.13 | Q38: 1.1 | R38: 1.01 | S38: 0.96
E39: SVE | F39: NHH | G39: Unmeasured non-household consumption (excluding supply pipe leakage) | H39: Ml/d | K39: 10.367204 | L39: 10.060209 | M39: 10.002952 | N39: 8.9771411 | O39: 8.6983484 | P39: 6.8550098 | Q39: 7.6470658 | R39: 7.1153833 | S39: 7.5796532
E40: SWB | F40: NHH | G40: Unmeasured non-household consumption (excluding supply pipe leakage) | H40: Ml/d | K40: 8.4784789 | L40: 8.6849777 | M40: 9.2751469 | N40: 8.8866816 | O40: 3.4433414 | P40: 4.2592115 | Q40: 3.1029755 | R40: 2.9431951 | S40: 3.0759909
E41: SRN | F41: NHH | G41: Unmeasured non-household consumption (excluding supply pipe leakage) | H41: Ml/d | K41: 4.5517788 | L41: 4.950232 | M41: 4.6053284 | N41: 5.1681622 | O41: 7.25 | P41: 4.4858696 | Q41: 5.3419657 | R41: 4.84 | S41: 4.0243382
E42: TMS | F42: NHH | G42: Unmeasured non-household consumption (excluding supply pipe leakage) | H42: Ml/d | K42: 20.69 | L42: 19.61 | M42: 15.85 | N42: 15.26 | O42: 15.47 | P42: 17.05 | Q42: 15.97 | R42: 14.26 | S42: 14.611728
E43: UUW | F43: NHH | G43: Unmeasured non-household consumption (excluding supply pipe leakage) | H43: Ml/d | K43: 13.486019 | L43: 12.792435 | M43: 11.252864 | N43: 10.084639 | O43: 9.7287472 | P43: 10.504601 | Q43: 13.938321 | R43: 13.372318 | S43: 12.849546
E44: WSX | F44: NHH | G44: Unmeasured non-household consumption (excluding supply pipe leakage) | H44: Ml/d | K44: 18.28 | L44: 17.69 | M44: 17.44 | N44: 17.45 | O44: 17.07 | P44: 17.02 | Q44: 16.83 | R44: 16.87 | S44: 16.28
... E53: SES | F53: NHH | G53: Unmeasured non-household consumption (excluding supply pipe leakage) | H53: Ml/d | K53: 0.58037889 | L53: 0.63 | M53: 0.61 | N53: 0.71 | O53: 0.71 | P53: 1.55 | Q53: 1.42 | R53: 1.84 | S53: 1.59
A55: WRMP14 Forecast
E57: ANH | F57: NHH | G57: WRMP14 Forecast - Total Water delivered NHH | H57: Ml/d | I57: =LEFT(E57,3) -> ANH | O57: 276.03191 | P57: 274.46118 | Q57: 272.89307 | R57: 271.9557 | S57: 271.01734 | T57: 270.10438 | U57: 269.16408 | V57: 268.22239
E58: WSH | F58: NHH | G58: WRMP14 Forecast - Total Water delivered NHH | H58: Ml/d | I58: =LEFT(E58,3) -> WSH | O58: - | P58: - | Q58: - | R58: - | S58: - | T58: - | U58: - | V58: -
E59: HDD | F59: NHH | G59: WRMP14 Forecast - Total Water delivered NHH | H59: Ml/d | I59: =LEFT(E59,3) -> HDD | O59: - | P59: - | Q59: - | R59: - | S59: - | T59: - | U59: - | V59: -
E60: NES (NNE) | F60: NHH | G60: WRMP14 Forecast - Total Water delivered NHH | H60: Ml/d | I60: =LEFT(E60,3) -> NES | O60: 154.89641 | P60: 154.86574 | Q60: 154.49071 | R60: 154.20499 | S60: 153.47829 | T60: 153.55041 | U60: 153.26431 | V60: 152.99355
E61: NES (ESK) | F61: NHH | G61: WRMP14 Forecast - Total Water delivered NHH | H61: Ml/d | I61: =LEFT(E61,3) -> NES | O61: 74.649217 | P61: 74.648291 | Q61: 74.644418 | R61: 74.519454 | S61: 74.203016 | T61: 74.350719 | U61: 74.283847 | V61: 74.282909
E62: SVE | F62: NHH | G62: WRMP14 Forecast - Total Water delivered NHH | H62: Ml/d | I62: =LEFT(E62,3) -> SVE | O62: 345.38169 | P62: 341.01748 | Q62: 336.05183 | R62: 331.38462 | S62: 326.17385 | T62: 324.33075 | U62: 321.85555 | V62: 319.56693
E63: SWB | F63: NHH | G63: WRMP14 Forecast - Total Water delivered NHH | H63: Ml/d | I63: =LEFT(E63,3) -> SWB | O63: 153.23331 | P63: 151.51868 | Q63: 149.87851 | R63: 148.36719 | S63: 146.82345 | T63: 145.52264 | U63: 144.1787 | V63: 142.87381
E64: SRN | F64: NHH | G64: WRMP14 Forecast - Total Water delivered NHH | H64: Ml/d | I64: =LEFT(E64,3) -> SRN | O64: 102.23823 | P64: 101.60046 | Q64: 101.46314 | R64: 101.53092 | S64: 101.05273 | T64: 100.85852 | U64: 100.51493 | V64: 100.0673
...

Sheet NHH.Performance
A1: =RIGHT(CELL("filename", A1), LEN(CELL("filename", A1)) - SEARCH("]", CELL("filename", A1))) -> NHH.Performance
J2: 2011-12 | K2: 2012-13 | L2: 2013-14 | M2: 2014-15 | N2: 2015-16 | O2: 2016-17 | P2: 2017-18 | Q2: 2018-19 | R2: 2019-20
E3: Company | F3: Performance Commitment | G3: Measure | H3: Unit
A7: [INPUT] Measured non-household consumption (excluding supply pipe leakage)
E9: ANH | F9: NHH | G9: Measured non-household consumption (excluding supply pipe leakage) | H9: Ml/d | J9: =NHH.Inputs!K9 -> 256.1867 | K9: =NHH.Inputs!L9 -> 268.71515 | L9: =NHH.Inputs!M9 -> 271.7221 | M9: =NHH.Inputs!N9 -> 269.13362 | N9: =NHH.Inputs!O9 -> 266.5032 | O9: =NHH.Inputs!P9 -> 266.79385 | P9: =NHH.Inputs!Q9 -> 273.94122 | Q9: =NHH.Inputs!R9 -> 290.27595 | R9: =NHH.Inputs!S9 -> 283.89642
E10: WSH | F10: NHH | G10: Measured non-household consumption (excluding supply pipe leakage) | H10: Ml/d | J10: =NHH.Inputs!K10 -> 180.5219 | K10: =NHH.Inputs!L10 -> 167.38959 | L10: =NHH.Inputs!M10 -> 170.56505 | M10: =NHH.Inputs!N10 -> 174.88707 | N10: =NHH.Inputs!O10 -> 168.65168 | O10: =NHH.Inputs!P10 -> 173.24099 | P10: =NHH.Inputs!Q10 -> 168.75674 | Q10: =NHH.Inputs!R10 -> 177.95661 | R10: =NHH.Inputs!S10 -> 174.23922
E11: HDD | F11: NHH | G11: Measured non-household consumption (excluding supply pipe leakage) | H11: Ml/d | J11: =NHH.Inputs!K11 -> 18.63832 | K11: =NHH.Inputs!L11 -> 17.402594 | L11: =NHH.Inputs!M11 -> 17.267477 | M11: =NHH.Inputs!N11 -> 18.428015 | N11: =NHH.Inputs!O11 -> 17.031067 | O11: =NHH.Inputs!P11 -> 18.454921 | P11: =NHH.Inputs!Q11 -> 18.640562 | Q11: =NHH.Inputs!R11 -> 14.757258 | R11: =NHH.Inputs!S11 -> 14.412148
E12: NES | F12: NHH | G12: Measured non-household consumption (excluding supply pipe leakage) | H12: Ml/d | J12: =NHH.Inputs!K12 -> 248.5 | K12: =NHH.Inputs!L12 -> 232.83 | L12: =NHH.Inputs!M12 -> 227.61 | M12: =NHH.Inputs!N12 -> 226 | N12: =NHH.Inputs!O12 -> 216.34 | O12: =NHH.Inputs!P12 -> 226.86 | P12: =NHH.Inputs!Q12 -> 214.54 | Q12: =NHH.Inputs!R12 -> 212.08 | R12: =NHH.Inputs!S12 -> 210.35
E13: NES (NNE) | F13: NHH | G13: Measured non-household consumption (excluding supply pipe leakage) | H13: Ml/d | J13: =NHH.Inputs!K13 -> 157.14 | K13: =NHH.Inputs!L13 -> 152.21 | L13: =NHH.Inputs!M13 -> 149.84 | M13: =NHH.Inputs!N13 -> 149.5 | N13: =NHH.Inputs!O13 -> 141.3 | O13: =NHH.Inputs!P13 -> 146.43 | P13: =NHH.Inputs!Q13 -> 139.32 | Q13: =NHH.Inputs!R13 -> 138.85 | R13: =NHH.Inputs!S13 -> 137.7
E14: NES (ESK) | F14: NHH | G14: Measured non-household consumption (excluding supply pipe leakage) | H14: Ml/d | J14: =NHH.Inputs!K14 -> 91.36 | K14: =NHH.Inputs!L14 -> 80.62 | L14: =NHH.Inputs!M14 -> 77.78 | M14: =NHH.Inputs!N14 -> 76.5 | N14: =NHH.Inputs!O14 -> 75.03 | O14: =NHH.Inputs!P14 -> 80.42 | P14: =NHH.Inputs!Q14 -> 75.22 | Q14: =NHH.Inputs!R14 -> 73.22 | R14: =NHH.Inputs!S14 -> 72.65
E15: SVE | F15: NHH | G15: Measured non-household consumption (excluding supply pipe leakage) | H15: Ml/d | J15: =NHH.Inputs!K15 -> 366.54773 | K15: =NHH.Inputs!L15 -> 346.71925 | L15: =NHH.Inputs!M15 -> 350.78411 | M15: =NHH.Inputs!N15 -> 358.739 | N15: =NHH.Inputs!O15 -> 369.66149 | O15: =NHH.Inputs!P15 -> 356.78522 | P15: =NHH.Inputs!Q15 -> 352.5347 | Q15: =NHH.Inputs!R15 -> 367.09314 | R15: =NHH.Inputs!S15 -> 362.51228
E16: SWB | F16: NHH | G16: Measured non-household consumption (excluding supply pipe leakage) | H16: Ml/d | J16: =NHH.Inputs!K16 -> 152.56568 | K16: =NHH.Inputs!L16 -> 146.98318 | L16: =NHH.Inputs!M16 -> 147.18615 | M16: =NHH.Inputs!N16 -> 148.7949 | N16: =NHH.Inputs!O16 -> 146.81682 | O16: =NHH.Inputs!P16 -> 142.16004 | P16: =NHH.Inputs!Q16 -> 142.68138 | Q16: =NHH.Inputs!R16 -> 149.34904 | R16: =NHH.Inputs!S16 -> 137.34842
E17: SRN | F17: NHH | G17: Measured non-household consumption (excluding supply pipe leakage) | H17: Ml/d | J17: =NHH.Inputs!K17 -> 89.0822 | K17: =NHH.Inputs!L17 -> 98.629271 | L17: =NHH.Inputs!M17 -> 98.482497 | M17: =NHH.Inputs!N17 -> 100.9972 | N17: =NHH.Inputs!O17 -> 103.04 | O17: =NHH.Inputs!P17 -> 104.7557 | P17: =NHH.Inputs!Q17 -> 112.90667 | Q17: =NHH.Inputs!R17 -> 115.31615 | R17: =NHH.Inputs!S17 -> 108.43522
E18: TMS | F18: NHH | G18: Measured non-household consumption (excluding supply pipe leakage) | H18: Ml/d | J18: =NHH.Inputs!K18 -> 480.82 | K18: =NHH.Inputs!L18 -> 470.58 | L18: =NHH.Inputs!M18 -> 485.54 | M18: =NHH.Inputs!N18 -> 492.69 | N18: =NHH.Inputs!O18 -> 484.15 | O18: =NHH.Inputs!P18 -> 461.7 | P18: =NHH.Inputs!Q18 -> 475.68 | Q18: =NHH.Inputs!R18 -> 464.63 | R18: =NHH.Inputs!S18 -> 445.91294
E19: UUW | F19: NHH | G19: Measured non-household consumption (excluding supply pipe leakage) | H19: Ml/d | J19: =NHH.Inputs!K19 -> 364.3366 | K19: =NHH.Inputs!L19 -> 359.9819 | L19: =NHH.Inputs!M19 -> 350.12891 | M19: =NHH.Inputs!N19 -> 352.39186 | N19: =NHH.Inputs!O19 -> 360.35446 | O19: =NHH.Inputs!P19 -> 358.14049 | P19: =NHH.Inputs!Q19 -> 351.89174 | Q19: =NHH.Inputs!R19 -> 363.44415 | R19: =NHH.Inputs!S19 -> 364.49178
E20: WSX | F20: NHH | G20: Measured non-household consumption (excluding supply pipe leakage) | H20: Ml/d | J20: =NHH.Inputs!K20 -> 83.39 | K20: =NHH.Inputs!L20 -> 78.98 | L20: =NHH.Inputs!M20 -> 81.87 | M20: =NHH.Inputs!N20 -> 81.55 | N20: =NHH.Inputs!O20 -> 81.43 | O20: =NHH.Inputs!P20 -> 80.56 | P20: =NHH.Inputs!Q20 -> 81.38 | Q20: =NHH.Inputs!R20 -> 83.52 | R20: =NHH.Inputs!S20 -> 78.93
... E29: SES | F29: NHH | G29: Measured non-household consumption (excluding supply pipe leakage) | H29: Ml/d | J29: =NHH.Inputs!K29 -> 24.512609 | K29: =NHH.Inputs!L29 -> 23.8 | L29: =NHH.Inputs!M29 -> 23.84 | M29: =NHH.Inputs!N29 -> 24.48 | N29: =NHH.Inputs!O29 -> 25.24 | O29: =NHH.Inputs!P29 -> 25.77 | P29: =NHH.Inputs!Q29 -> 23.26 | Q29: =NHH.Inputs!R29 -> 22.77 | R29: =NHH.Inputs!S29 -> 23.26
A31: [INPUT] Unmeasured non-household consumption (excluding supply pipe leakage)
E33: ANH | F33: NHH | G33: Unmeasured non-household consumption (excluding supply pipe leakage) | H33: Ml/d | J33: =NHH.Inputs!K33 -> 2.0107364 | K33: =NHH.Inputs!L33 -> 1.8926338 | L33: =NHH.Inputs!M33 -> 1.6357996 | M33: =NHH.Inputs!N33 -> 1.4424881 | N33: =NHH.Inputs!O33 -> 1.2227961 | O33: =NHH.Inputs!P33 -> 1.1053871 | P33: =NHH.Inputs!Q33 -> 0.75669702 | Q33: =NHH.Inputs!R33 -> 0.86105746 | R33: =NHH.Inputs!S33 -> 0.82332588
E34: WSH | F34: NHH | G34: Unmeasured non-household consumption (excluding supply pipe leakage) | H34: Ml/d | J34: =NHH.Inputs!K34 -> 5.1757947 | K34: =NHH.Inputs!L34 -> 4.2704361 | L34: =NHH.Inputs!M34 -> 4.3296226 | M34: =NHH.Inputs!N34 -> 5.1460452 | N34: =NHH.Inputs!O34 -> 4.7213679 | O34: =NHH.Inputs!P34 -> 5.3633145 | P34: =NHH.Inputs!Q34 -> 5.4128831 | Q34: =NHH.Inputs!R34 -> 5.6156115 | R34: =NHH.Inputs!S34 -> 4.0029973
E35: HDD | F35: NHH | G35: Unmeasured non-household consumption (excluding supply pipe leakage) | H35: Ml/d | J35: =NHH.Inputs!K35 -> 0.43687176 | K35: =NHH.Inputs!L35 -> 0.58092877 | L35: =NHH.Inputs!M35 -> 0.51654215 | M35: =NHH.Inputs!N35 -> 0.40652966 | N35: =NHH.Inputs!O35 -> 0.3478012 | O35: =NHH.Inputs!P35 -> 0.67637251 | P35: =NHH.Inputs!Q35 -> 0.71599 | Q35: =NHH.Inputs!R35 -> 1.2243589 | R35: =NHH.Inputs!S35 -> 1.2967766
E36: NES | F36: NHH | G36: Unmeasured non-household consumption (excluding supply pipe leakage) | H36: Ml/d | J36: =NHH.Inputs!K36 -> 6.25 | K36: =NHH.Inputs!L36 -> 5.85 | L36: =NHH.Inputs!M36 -> 5.77 | M36: =NHH.Inputs!N36 -> 4.92 | N36: =NHH.Inputs!O36 -> 6.31 | O36: =NHH.Inputs!P36 -> 6.11 | P36: =NHH.Inputs!Q36 -> 6.17 | Q36: =NHH.Inputs!R36 -> 5.92 | R36: =NHH.Inputs!S36 -> 4.73
E37: NES (NNE) | F37: NHH | G37: Unmeasured non-household consumption (excluding supply pipe leakage) | H37: Ml/d | J37: =NHH.Inputs!K37 -> 5.1 | K37: =NHH.Inputs!L37 -> 4.76 | L37: =NHH.Inputs!M37 -> 4.71 | M37: =NHH.Inputs!N37 -> 3.91 | N37: =NHH.Inputs!O37 -> 5.33 | O37: =NHH.Inputs!P37 -> 4.99 | P37: =NHH.Inputs!Q37 -> 5.07 | Q37: =NHH.Inputs!R37 -> 4.9 | R37: =NHH.Inputs!S37 -> 3.77
E38: NES (ESK) | F38: NHH | G38: Unmeasured non-household consumption (excluding supply pipe leakage) | H38: Ml/d | J38: =NHH.Inputs!K38 -> 1.15 | K38: =NHH.Inputs!L38 -> 1.09 | L38: =NHH.Inputs!M38 -> 1.06 | M38: =NHH.Inputs!N38 -> 1.01 | N38: =NHH.Inputs!O38 -> 0.98 | O38: =NHH.Inputs!P38 -> 1.13 | P38: =NHH.Inputs!Q38 -> 1.1 | Q38: =NHH.Inputs!R38 -> 1.01 | R38: =NHH.Inputs!S38 -> 0.96
E39: SVE | F39: NHH | G39: Unmeasured non-household consumption (excluding supply pipe leakage) | H39: Ml/d | J39: =NHH.Inputs!K39 -> 10.367204 | K39: =NHH.Inputs!L39 -> 10.060209 | L39: =NHH.Inputs!M39 -> 10.002952 | M39: =NHH.Inputs!N39 -> 8.9771411 | N39: =NHH.Inputs!O39 -> 8.6983484 | O39: =NHH.Inputs!P39 -> 6.8550098 | P39: =NHH.Inputs!Q39 -> 7.6470658 | Q39: =NHH.Inputs!R39 -> 7.1153833 | R39: =NHH.Inputs!S39 -> 7.5796532
E40: SWB | F40: NHH | G40: Unmeasured non-household consumption (excluding supply pipe leakage) | H40: Ml/d | J40: =NHH.Inputs!K40 -> 8.4784789 | K40: =NHH.Inputs!L40 -> 8.6849777 | L40: =NHH.Inputs!M40 -> 9.2751469 | M40: =NHH.Inputs!N40 -> 8.8866816 | N40: =NHH.Inputs!O40 -> 3.4433414 | O40: =NHH.Inputs!P40 -> 4.2592115 | P40: =NHH.Inputs!Q40 -> 3.1029755 | Q40: =NHH.Inputs!R40 -> 2.9431951 | R40: =NHH.Inputs!S40 -> 3.0759909
E41: SRN | F41: NHH | G41: Unmeasured non-household consumption (excluding supply pipe leakage) | H41: Ml/d | J41: =NHH.Inputs!K41 -> 4.5517788 | K41: =NHH.Inputs!L41 -> 4.950232 | L41: =NHH.Inputs!M41 -> 4.6053284 | M41: =NHH.Inputs!N41 -> 5.1681622 | N41: =NHH.Inputs!O41 -> 7.25 | O41: =NHH.Inputs!P41 -> 4.4858696 | P41: =NHH.Inputs!Q41 -> 5.3419657 | Q41: =NHH.Inputs!R41 -> 4.84 | R41: =NHH.Inputs!S41 -> 4.0243382
E42: TMS | F42: NHH | G42: Unmeasured non-household consumption (excluding supply pipe leakage) | H42: Ml/d | J42: =NHH.Inputs!K42 -> 20.69 | K42: =NHH.Inputs!L42 -> 19.61 | L42: =NHH.Inputs!M42 -> 15.85 | M42: =NHH.Inputs!N42 -> 15.26 | N42: =NHH.Inputs!O42 -> 15.47 | O42: =NHH.Inputs!P42 -> 17.05 | P42: =NHH.Inputs!Q42 -> 15.97 | Q42: =NHH.Inputs!R42 -> 14.26 | R42: =NHH.Inputs!S42 -> 14.611728
E43: UUW | F43: NHH | G43: Unmeasured non-household consumption (excluding supply pipe leakage) | H43: Ml/d | J43: =NHH.Inputs!K43 -> 13.486019 | K43: =NHH.Inputs!L43 -> 12.792435 | L43: =NHH.Inputs!M43 -> 11.252864 | M43: =NHH.Inputs!N43 -> 10.084639 | N43: =NHH.Inputs!O43 -> 9.7287472 | O43: =NHH.Inputs!P43 -> 10.504601 | P43: =NHH.Inputs!Q43 -> 13.938321 | Q43: =NHH.Inputs!R43 -> 13.372318 | R43: =NHH.Inputs!S43 -> 12.849546
E44: WSX | F44: NHH | G44: Unmeasured non-household consumption (excluding supply pipe leakage) | H44: Ml/d | J44: =NHH.Inputs!K44 -> 18.28 | K44: =NHH.Inputs!L44 -> 17.69 | L44: =NHH.Inputs!M44 -> 17.44 | M44: =NHH.Inputs!N44 -> 17.45 | N44: =NHH.Inputs!O44 -> 17.07 | O44: =NHH.Inputs!P44 -> 17.02 | P44: =NHH.Inputs!Q44 -> 16.83 | Q44: =NHH.Inputs!R44 -> 16.87 | R44: =NHH.Inputs!S44 -> 16.28
... E53: SES | F53: NHH | G53: Unmeasured non-household consumption (excluding supply pipe leakage) | H53: Ml/d | J53: =NHH.Inputs!K53 -> 0.58037889 | K53: =NHH.Inputs!L53 -> 0.63 | L53: =NHH.Inputs!M53 -> 0.61 | M53: =NHH.Inputs!N53 -> 0.71 | N53: =NHH.Inputs!O53 -> 0.71 | O53: =NHH.Inputs!P53 -> 1.55 | P53: =NHH.Inputs!Q53 -> 1.42 | Q53: =NHH.Inputs!R53 -> 1.84 | R53: =NHH.Inputs!S53 -> 1.59
A55: Total non-household consumption (excluding supply pipe leakage)
E57: ANH | F57: NHH | G57: Total non-household consumption (excluding supply pipe leakage) | H57: Ml/d | J57: =J9+J33 -> 258.19743 | K57: =K9+K33 -> 270.60778 | L57: =L9+L33 -> 273.3579 | M57: =M9+M33 -> 270.57611 | N57: =N9+N33 -> 267.72599 | O57: =O9+O33 -> 267.89924 | P57: =P9+P33 -> 274.69792 | Q57: =Q9+Q33 -> 291.13701 | R57: =R9+R33 -> 284.71975
E58: WSH | F58: NHH | G58: Total non-household consumption (excluding supply pipe leakage) | H58: Ml/d | J58: =J10+J34 -> 185.6977 | K58: =K10+K34 -> 171.66003 | L58: =L10+L34 -> 174.89467 | M58: =M10+M34 -> 180.03311 | N58: =N10+N34 -> 173.37305 | O58: =O10+O34 -> 178.6043 | P58: =P10+P34 -> 174.16962 | Q58: =Q10+Q34 -> 183.57222 | R58: =R10+R34 -> 178.24222
E59: HDD | F59: NHH | G59: Total non-household consumption (excluding supply pipe leakage) | H59: Ml/d | J59: =J11+J35 -> 19.075191 | K59: =K11+K35 -> 17.983523 | L59: =L11+L35 -> 17.784019 | M59: =M11+M35 -> 18.834544 | N59: =N11+N35 -> 17.378868 | O59: =O11+O35 -> 19.131293 | P59: =P11+P35 -> 19.356552 | Q59: =Q11+Q35 -> 15.981617 | R59: =R11+R35 -> 15.708924
E60: NES | F60: NHH | G60: Total non-household consumption (excluding supply pipe leakage) | H60: Ml/d | J60: =J12+J36 -> 254.75 | K60: =K12+K36 -> 238.68 | L60: =L12+L36 -> 233.38 | M60: =M12+M36 -> 230.92 | N60: =N12+N36 -> 222.65 | O60: =O12+O36 -> 232.97 | P60: =P12+P36 -> 220.71 | Q60: =Q12+Q36 -> 218 | R60: =R12+R36 -> 215.08
E61: NES (NNE) | F61: NHH | G61: Total non-household consumption (excluding supply pipe leakage) | H61: Ml/d | J61: =J13+J37 -> 162.24 | K61: =K13+K37 -> 156.97 | L61: =L13+L37 -> 154.55 | M61: =M13+M37 -> 153.41 | N61: =N13+N37 -> 146.63 | O61: =O13+O37 -> 151.42 | P61: =P13+P37 -> 144.39 | Q61: =Q13+Q37 -> 143.75 | R61: =R13+R37 -> 141.47
E62: NES (ESK) | F62: NHH | G62: Total non-household consumption (excluding supply pipe leakage) | H62: Ml/d | J62: =J14+J38 -> 92.51 | K62: =K14+K38 -> 81.71 | L62: =L14+L38 -> 78.84 | M62: =M14+M38 -> 77.51 | N62: =N14+N38 -> 76.01 | O62: =O14+O38 -> 81.55 | P62: =P14+P38 -> 76.32 | Q62: =Q14+Q38 -> 74.23 | R62: =R14+R38 -> 73.61
E63: SVE | F63: NHH | G63: Total non-household consumption (excluding supply pipe leakage) | H63: Ml/d | J63: =J15+J39 -> 376.91494 | K63: =K15+K39 -> 356.77946 | L63: =L15+L39 -> 360.78707 | M63: =M15+M39 -> 367.71615 | N63: =N15+N39 -> 378.35984 | O63: =O15+O39 -> 363.64023 | P63: =P15+P39 -> 360.18177 | Q63: =Q15+Q39 -> 374.20852 | R63: =R15+R39 -> 370.09194
E64: SWB | F64: NHH | G64: Total non-household consumption (excluding supply pipe leakage) | H64: Ml/d | J64: =J16+J40 -> 161.04416 | K64: =K16+K40 -> 155.66816 | L64: =L16+L40 -> 156.4613 | M64: =M16+M40 -> 157.68158 | N64: =N16+N40 -> 150.26016 | O64: =O16+O40 -> 146.41925 | P64: =P16+P40 -> 145.78436 | Q64: =Q16+Q40 -> 152.29224 | R64: =R16+R40 -> 140.42441
...

Sheet NHH.WRMP
A1: =RIGHT(CELL("filename", A1), LEN(CELL("filename", A1)) - SEARCH("]", CELL("filename", A1))) -> NHH.WRMP
J2: 2015-16 | K2: 2016-17 | L2: 2017-18 | M2: 2018-19 | N2: 2019-20 | O2: 2020-21 | P2: 2021-22 | Q2: 2022-23
E3: Company | F3: Performance Commitment | G3: Measure | H3: Unit
A7: [INPUT] WRMP14 Forecast - Total Non-household Water Delivered
E9: ANH | F9: NHH | G9: WRMP14 Forecast - Total Water delivered NHH | H9: Ml/d | J9: =INDEX(NHH.Inputs!$O$57:$W$78,MATCH($E9,NHH.Inputs!$E$57:$E$78,0),MATCH(J$2,NHH.Inputs!$O$2:$W$2,0)) -> 276.03191 | K9: =INDEX(NHH.Inputs!$O$57:$W$78,MATCH($E9,NHH.Inputs!$E$57:$E$78,0),MATCH(K$2,NHH.Inputs!$O$2:$W$2,0)) -> 274.46118 | L9: =INDEX(NHH.Inputs!$O$57:$W$78,MATCH($E9,NHH.Inputs!$E$57:$E$78,0),MATCH(L$2,NHH.Inputs!$O$2:$W$2,0)) -> 272.89307 | M9: =INDEX(NHH.Inputs!$O$57:$W$78,MATCH($E9,NHH.Inputs!$E$57:$E$78,0),MATCH(M$2,NHH.Inputs!$O$2:$W$2,0)) -> 271.9557 | N9: =INDEX(NHH.Inputs!$O$57:$W$78,MATCH($E9,NHH.Inputs!$E$57:$E$78,0),MATCH(N$2,NHH.Inputs!$O$2:$W$2,0)) -> 271.01734 | O9: =INDEX(NHH.Inputs!$O$57:$W$78,MATCH($E9,NHH.Inputs!$E$57:$E$78,0),MATCH(O$2,NHH.Inputs!$O$2:$W$2,0)) -> 270.10438 | P9: =INDEX(NHH.Inputs!$O$57:$W$78,MATCH($E9,NHH.Inputs!$E$57:$E$78,0),MATCH(P$2,NHH.Inputs!$O$2:$W$2,0)) -> 269.16408 | Q9: =INDEX(NHH.Inputs!$O$57:$W$78,MATCH($E9,NHH.Inputs!$E$57:$E$78,0),MATCH(Q$2,NHH.Inputs!$O$2:$W$2,0)) -> 268.22239
E10: WSH | F10: NHH | G10: WRMP14 Forecast - Total Water delivered NHH | H10: Ml/d | J10: =INDEX(NHH.Inputs!$O$57:$W$78,MATCH($E10,NHH.Inputs!$E$57:$E$78,0),MATCH(J$2,NHH.Inputs!$O$2:$W$2,0)) -> - | K10: =INDEX(NHH.Inputs!$O$57:$W$78,MATCH($E10,NHH.Inputs!$E$57:$E$78,0),MATCH(K$2,NHH.Inputs!$O$2:$W$2,0)) -> - | L10: =INDEX(NHH.Inputs!$O$57:$W$78,MATCH($E10,NHH.Inputs!$E$57:$E$78,0),MATCH(L$2,NHH.Inputs!$O$2:$W$2,0)) -> - | M10: =INDEX(NHH.Inputs!$O$57:$W$78,MATCH($E10,NHH.Inputs!$E$57:$E$78,0),MATCH(M$2,NHH.Inputs!$O$2:$W$2,0)) -> - | N10: =INDEX(NHH.Inputs!$O$57:$W$78,MATCH($E10,NHH.Inputs!$E$57:$E$78,0),MATCH(N$2,NHH.Inputs!$O$2:$W$2,0)) -> - | O10: =INDEX(NHH.Inputs!$O$57:$W$78,MATCH($E10,NHH.Inputs!$E$57:$E$78,0),MATCH(O$2,NHH.Inputs!$O$2:$W$2,0)) -> - | P10: =INDEX(NHH.Inputs!$O$57:$W$78,MATCH($E10,NHH.Inputs!$E$57:$E$78,0),MATCH(P$2,NHH.Inputs!$O$2:$W$2,0)) -> - | Q10: =INDEX(NHH.Inputs!$O$57:$W$78,MATCH($E10,NHH.Inputs!$E$57:$E$78,0),MATCH(Q$2,NHH.Inputs!$O$2:$W$2,0)) -> -
E11: HDD | F11: NHH | G11: WRMP14 Forecast - Total Water delivered NHH | H11: Ml/d | J11: =INDEX(NHH.Inputs!$O$57:$W$78,MATCH($E11,NHH.Inputs!$E$57:$E$78,0),MATCH(J$2,NHH.Inputs!$O$2:$W$2,0)) -> - | K11: =INDEX(NHH.Inputs!$O$57:$W$78,MATCH($E11,NHH.Inputs!$E$57:$E$78,0),MATCH(K$2,NHH.Inputs!$O$2:$W$2,0)) -> - | L11: =INDEX(NHH.Inputs!$O$57:$W$78,MATCH($E11,NHH.Inputs!$E$57:$E$78,0),MATCH(L$2,NHH.Inputs!$O$2:$W$2,0)) -> - | M11: =INDEX(NHH.Inputs!$O$57:$W$78,MATCH($E11,NHH.Inputs!$E$57:$E$78,0),MATCH(M$2,NHH.Inputs!$O$2:$W$2,0)) -> - | N11: =INDEX(NHH.Inputs!$O$57:$W$78,MATCH($E11,NHH.Inputs!$E$57:$E$78,0),MATCH(N$2,NHH.Inputs!$O$2:$W$2,0)) -> - | O11: =INDEX(NHH.Inputs!$O$57:$W$78,MATCH($E11,NHH.Inputs!$E$57:$E$78,0),MATCH(O$2,NHH.Inputs!$O$2:$W$2,0)) -> - | P11: =INDEX(NHH.Inputs!$O$57:$W$78,MATCH($E11,NHH.Inputs!$E$57:$E$78,0),MATCH(P$2,NHH.Inputs!$O$2:$W$2,0)) -> - | Q11: =INDEX(NHH.Inputs!$O$57:$W$78,MATCH($E11,NHH.Inputs!$E$57:$E$78,0),MATCH(Q$2,NHH.Inputs!$O$2:$W$2,0)) -> -
E12: NES | F12: NHH | G12: WRMP14 Forecast - Total Water delivered NHH | H12: Ml/d | J12: =INDEX(NHH.Inputs!$O$57:$W$78,MATCH($E12,NHH.Inputs!$E$57:$E$78,0),MATCH(J$2,NHH.Inputs!$O$2:$W$2,0)) -> 229.54563 | K12: =INDEX(NHH.Inputs!$O$57:$W$78,MATCH($E12,NHH.Inputs!$E$57:$E$78,0),MATCH(K$2,NHH.Inputs!$O$2:$W$2,0)) -> 229.51404 | L12: =INDEX(NHH.Inputs!$O$57:$W$78,MATCH($E12,NHH.Inputs!$E$57:$E$78,0),MATCH(L$2,NHH.Inputs!$O$2:$W$2,0)) -> 229.13513 | M12: =INDEX(NHH.Inputs!$O$57:$W$78,MATCH($E12,NHH.Inputs!$E$57:$E$78,0),MATCH(M$2,NHH.Inputs!$O$2:$W$2,0)) -> 228.72445 | N12: =INDEX(NHH.Inputs!$O$57:$W$78,MATCH($E12,NHH.Inputs!$E$57:$E$78,0),MATCH(N$2,NHH.Inputs!$O$2:$W$2,0)) -> 227.68131 | O12: =INDEX(NHH.Inputs!$O$57:$W$78,MATCH($E12,NHH.Inputs!$E$57:$E$78,0),MATCH(O$2,NHH.Inputs!$O$2:$W$2,0)) -> 227.90112 | P12: =INDEX(NHH.Inputs!$O$57:$W$78,MATCH($E12,NHH.Inputs!$E$57:$E$78,0),MATCH(P$2,NHH.Inputs!$O$2:$W$2,0)) -> 227.54816 | Q12: =INDEX(NHH.Inputs!$O$57:$W$78,MATCH($E12,NHH.Inputs!$E$57:$E$78,0),MATCH(Q$2,NHH.Inputs!$O$2:$W$2,0)) -> 227.27645
E13: NES (NNE) | F13: NHH | G13: WRMP14 Forecast - Total Water delivered NHH | H13: Ml/d | J13: =INDEX(NHH.Inputs!$O$57:$W$78,MATCH($E13,NHH.Inputs!$E$57:$E$78,0),MATCH(J$2,NHH.Inputs!$O$2:$W$2,0)) -> 154.89641 | K13: =INDEX(NHH.Inputs!$O$57:$W$78,MATCH($E13,NHH.Inputs!$E$57:$E$78,0),MATCH(K$2,NHH.Inputs!$O$2:$W$2,0)) -> 154.86574 | L13: =INDEX(NHH.Inputs!$O$57:$W$78,MATCH($E13,NHH.Inputs!$E$57:$E$78,0),MATCH(L$2,NHH.Inputs!$O$2:$W$2,0)) -> 154.49071 | M13: =INDEX(NHH.Inputs!$O$57:$W$78,MATCH($E13,NHH.Inputs!$E$57:$E$78,0),MATCH(M$2,NHH.Inputs!$O$2:$W$2,0)) -> 154.20499 | N13: =INDEX(NHH.Inputs!$O$57:$W$78,MATCH($E13,NHH.Inputs!$E$57:$E$78,0),MATCH(N$2,NHH.Inputs!$O$2:$W$2,0)) -> 153.47829 | O13: =INDEX(NHH.Inputs!$O$57:$W$78,MATCH($E13,NHH.Inputs!$E$57:$E$78,0),MATCH(O$2,NHH.Inputs!$O$2:$W$2,0)) -> 153.55041 | P13: =INDEX(NHH.Inputs!$O$57:$W$78,MATCH($E13,NHH.Inputs!$E$57:$E$78,0),MATCH(P$2,NHH.Inputs!$O$2:$W$2,0)) -> 153.26431 | Q13: =INDEX(NHH.Inputs!$O$57:$W$78,MATCH($E13,NHH.Inputs!$E$57:$E$78,0),MATCH(Q$2,NHH.Inputs!$O$2:$W$2,0)) -> 152.99355
E14: NES (ESK) | F14: NHH | G14: WRMP14 Forecast - Total Water delivered NHH | H14: Ml/d | J14: =INDEX(NHH.Inputs!$O$57:$W$78,MATCH($E14,NHH.Inputs!$E$57:$E$78,0),MATCH(J$2,NHH.Inputs!$O$2:$W$2,0)) -> 74.649217 | K14: =INDEX(NHH.Inputs!$O$57:$W$78,MATCH($E14,NHH.Inputs!$E$57:$E$78,0),MATCH(K$2,NHH.Inputs!$O$2:$W$2,0)) -> 74.648291 | L14: =INDEX(NHH.Inputs!$O$57:$W$78,MATCH($E14,NHH.Inputs!$E$57:$E$78,0),MATCH(L$2,NHH.Inputs!$O$2:$W$2,0)) -> 74.644418 | M14: =INDEX(NHH.Inputs!$O$57:$W$78,MATCH($E14,NHH.Inputs!$E$57:$E$78,0),MATCH(M$2,NHH.Inputs!$O$2:$W$2,0)) -> 74.519454 | N14: =INDEX(NHH.Inputs!$O$57:$W$78,MATCH($E14,NHH.Inputs!$E$57:$E$78,0),MATCH(N$2,NHH.Inputs!$O$2:$W$2,0)) -> 74.203016 | O14: =INDEX(NHH.Inputs!$O$57:$W$78,MATCH($E14,NHH.Inputs!$E$57:$E$78,0),MATCH(O$2,NHH.Inputs!$O$2:$W$2,0)) -> 74.350719 | P14: =INDEX(NHH.Inputs!$O$57:$W$78,MATCH($E14,NHH.Inputs!$E$57:$E$78,0),MATCH(P$2,NHH.Inputs!$O$2:$W$2,0)) -> 74.283847 | Q14: =INDEX(NHH.Inputs!$O$57:$W$78,MATCH($E14,NHH.Inputs!$E$57:$E$78,0),MATCH(Q$2,NHH.Inputs!$O$2:$W$2,0)) -> 74.282909
E15: SVE | F15: NHH | G15: WRMP14 Forecast - Total Water delivered NHH | H15: Ml/d | J15: =INDEX(NHH.Inputs!$O$57:$W$78,MATCH($E15,NHH.Inputs!$E$57:$E$78,0),MATCH(J$2,NHH.Inputs!$O$2:$W$2,0)) -> 345.38169 | K15: =INDEX(NHH.Inputs!$O$57:$W$78,MATCH($E15,NHH.Inputs!$E$57:$E$78,0),MATCH(K$2,NHH.Inputs!$O$2:$W$2,0)) -> 341.01748 | L15: =INDEX(NHH.Inputs!$O$57:$W$78,MATCH($E15,NHH.Inputs!$E$57:$E$78,0),MATCH(L$2,NHH.Inputs!$O$2:$W$2,0)) -> 336.05183 | M15: =INDEX(NHH.Inputs!$O$57:$W$78,MATCH($E15,NHH.Inputs!$E$57:$E$78,0),MATCH(M$2,NHH.Inputs!$O$2:$W$2,0)) -> 331.38462 | N15: =INDEX(NHH.Inputs!$O$57:$W$78,MATCH($E15,NHH.Inputs!$E$57:$E$78,0),MATCH(N$2,NHH.Inputs!$O$2:$W$2,0)) -> 326.17385 | O15: =INDEX(NHH.Inputs!$O$57:$W$78,MATCH($E15,NHH.Inputs!$E$57:$E$78,0),MATCH(O$2,NHH.Inputs!$O$2:$W$2,0)) -> 324.33075 | P15: =INDEX(NHH.Inputs!$O$57:$W$78,MATCH($E15,NHH.Inputs!$E$57:$E$78,0),MATCH(P$2,NHH.Inputs!$O$2:$W$2,0)) -> 321.85555 | Q15: =INDEX(NHH.Inputs!$O$57:$W$78,MATCH($E15,NHH.Inputs!$E$57:$E$78,0),MATCH(Q$2,NHH.Inputs!$O$2:$W$2,0)) -> 319.56693
