Workbook
Name _AtRisk_SimSetting_AutomaticallyGenerateReports: FALSE
Name _AtRisk_SimSetting_AutomaticResultsDisplayMode: 0
Name _AtRisk_SimSetting_ConvergenceConfidenceLevel: 0.95
Name _AtRisk_SimSetting_ConvergencePercentileToTest: 0.9
Name _AtRisk_SimSetting_ConvergencePerformMeanTest: TRUE
Name _AtRisk_SimSetting_ConvergencePerformPercentileTest: FALSE
Name _AtRisk_SimSetting_ConvergencePerformStdDeviationTest: FALSE
Name _AtRisk_SimSetting_ConvergenceTestAllOutputs: TRUE
Name _AtRisk_SimSetting_ConvergenceTestingPeriod: 100
Name _AtRisk_SimSetting_ConvergenceTolerance: 0.03
Name _AtRisk_SimSetting_LiveUpdate: TRUE
Name _AtRisk_SimSetting_LiveUpdatePeriod: -1
Name _AtRisk_SimSetting_MacroRecalculationBehavior: 0
Name _AtRisk_SimSetting_RandomNumberGenerator: 0
Name _AtRisk_SimSetting_ReportOptionCustomItemsCount: 0
Name _AtRisk_SimSetting_ReportOptionDataMode: 1
Name _AtRisk_SimSetting_ReportOptionReportMultiSimType: 1
Name _AtRisk_SimSetting_ReportOptionReportPlacement: 1
Name _AtRisk_SimSetting_ReportOptionReportSelection: 257
Name _AtRisk_SimSetting_ReportOptionReportsFileType: 1
Name _AtRisk_SimSetting_ReportOptionSelectiveQR: FALSE
Name _AtRisk_SimSetting_ReportsList: 257
Name _AtRisk_SimSetting_ShowSimulationProgressWindow: TRUE
Name _AtRisk_SimSetting_SimNameCount: 0
Name _AtRisk_SimSetting_SmartSensitivityAnalysisEnabled: TRUE
Name _AtRisk_SimSetting_StatisticFunctionUpdating: 1
Name _AtRisk_SimSetting_StdRecalcActiveSimulationNumber: 1
Name _AtRisk_SimSetting_StdRecalcBehavior: 1
Name _AtRisk_SimSetting_StdRecalcWithoutRiskStatic: 0
Name _AtRisk_SimSetting_StdRecalcWithoutRiskStaticPercentile: 0.5
Name _Order1: 255
Name _Order2: 255
Name F: {"bal",#N/A,FALSE,"working papers";"income",#N/A,FALSE,"working papers"}
Name fdraf: {"bal",#N/A,FALSE,"working papers";"income",#N/A,FALSE,"working papers"}
Name Fdraft: {"bal",#N/A,FALSE,"working papers";"income",#N/A,FALSE,"working papers"}
Name IQ_CH: 110000
Name IQ_CQ: 5000
Name IQ_CY: 10000
Name IQ_DAILY: 500000
Name IQ_DNTM: 700000
Name IQ_EXPENSE_CODE_: 80019595006
Name IQ_FH: 100000
Name IQ_FQ: 500
Name IQ_FWD_CY: 10001
Name IQ_FWD_CY1: 10002
Name IQ_FWD_CY2: 10003
Name IQ_FWD_FY: 1001
Name IQ_FWD_FY1: 1002
Name IQ_FWD_FY2: 1003
Name IQ_FWD_Q: 501
Name IQ_FWD_Q1: 502
Name IQ_FWD_Q2: 503
Name IQ_FY: 1000
Name IQ_LATESTK: 1000
Name IQ_LATESTQ: 500
Name IQ_LTM: 2000
Name IQ_LTMMONTH: 120000
Name IQ_MONTH: 15000
Name IQ_MTD: 800000
Name IQ_NAMES_REVISION_DATE_: 41366.3748958333

Sheet Cover
A1: =RIGHT(CELL("filename", $A$1), LEN(CELL("filename", $A$1)) - SEARCH("]", CELL("filename", $A$1))) -> Cover
B3: PR24 ODI Risk - Feeder Model (Discharge Permit Compliance)
B5: Model code | C5: PR24OC11
B6: Version number: | C6: 1
B7: File name: | C7: =MID(CELL("filename"), FIND("[", CELL("filename"), 1) + 1, FIND("]", CELL("filename"), 1) - FIND("[", CELL("filename"), 1) - 1) -> PR24 FD OC11 ODI risk - Feeder Model (Discharge Permit Compliance).xlsx
B8: Date: | C8: 45627
B10: For enquiries please contact: | C10: PR24@ofwat.gov.uk

Sheet Conceptual Model
A1: =RIGHT(CELL("filename", A1), LEN(CELL("filename", A1)) - SEARCH("]", CELL("filename", A1))) -> Conceptual Model
A3: Conceptual model
A28: END

Sheet F_Inputs
C1: ODI Risk DIS Feeder Input Run 11 | E1: Run on 12 Nov 2024 17:31
A2: Acronym | B2: Reference | C2: Item description | D2: Unit | E2: Model | F2: 2012-13 | G2: 2013-14 | H2: 2014-15 | I2: 2015-16 | J2: 2016-17 | K2: 2017-18 | L2: 2018-19 | M2: 2019-20 | N2: 2020-21 | O2: 2021-22 | P2: 2022-23 | Q2: 2023-24
F4: Price Review 2024 | G4: Price Review 2024 | H4: Price Review 2024 | I4: Price Review 2024 | J4: Price Review 2024 | K4: Price Review 2024 | L4: Price Review 2024 | M4: Price Review 2024 | N4: Price Review 2024 | O4: Price Review 2024 | P4: Price Review 2024 | Q4: Price Review 2024
F5: Run 11 - PR24 FD Data | G5: Run 11 - PR24 FD Data | H5: Run 11 - PR24 FD Data | I5: Run 11 - PR24 FD Data | J5: Run 11 - PR24 FD Data | K5: Run 11 - PR24 FD Data | L5: Run 11 - PR24 FD Data | M5: Run 11 - PR24 FD Data | N5: Run 11 - PR24 FD Data | O5: Run 11 - PR24 FD Data | P5: Run 11 - PR24 FD Data | Q5: Run 11 - PR24 FD Data
F6: Latest | G6: Latest | H6: Latest | I6: Latest | J6: Latest | K6: Latest | L6: Latest | M6: Latest | N6: Latest | O6: Latest | P6: Latest | Q6: Latest
A7: ANH | B7: OUT4_19_PR24 | C7: Underlying calculations for common performance commitments - water and combined - Discharge permit compliance - Percentage compliance | D7: % | E7: Price Review 2024 | F7: 0.97073791 | G7: 0.97197452 | H7: 0.98348158 | I7: 0.9826087 | J7: 0.99119497 | K7: 0.98612863 | L7: 0.98212157 | M7: 0.9858156 | N7: 0.99292453 | O7: 0.98220641 | P7: 0.98566308 | Q7: 0.98444976
A8: WSH | B8: OUT4_19_PR24 | C8: Underlying calculations for common performance commitments - water and combined - Discharge permit compliance - Percentage compliance | D8: % | E8: Price Review 2024 | F8: 0.97063369 | G8: 0.96360759 | H8: 0.97752809 | I8: 0.97087379 | J8: 0.99029126 | K8: 0.9669967 | L8: 0.98019802 | M8: 0.98181818 | N8: 0.99664992 | O8: 0.98322148 | P8: 0.98504983 | Q8: 0.9800995
A9: HDD | B9: OUT4_19_PR24 | C9: Underlying calculations for common performance commitments - water and combined - Discharge permit compliance - Percentage compliance | D9: % | E9: Price Review 2024 | F9: 1 | G9: 1 | H9: 0.75 | I9: 1 | J9: 1 | K9: 1 | L9: 1 | M9: 1 | N9: 1 | O9: 0.9787234 | P9: 0.97826087 | Q9: 1
A10: NES | B10: OUT4_19_PR24 | C10: Underlying calculations for common performance commitments - water and combined - Discharge permit compliance - Percentage compliance | D10: % | E10: Price Review 2024 | K10: 0.96 | L10: 0.995 | M10: 0.96568627 | N10: 0.99512195 | O10: 0.98039216 | P10: 0.98529412 | Q10: 0.98543689
A11: SVE | B11: OUT4_19_PR24 | C11: Underlying calculations for common performance commitments - water and combined - Discharge permit compliance - Percentage compliance | D11: % | E11: Price Review 2024 | K11: 0.9963145 | L11: 0.98423127 | M11: 0.99605782 | N11: 0.99602649 | O11: 0.99332443 | P11: 0.99327957 | Q11: 0.99462366
A12: SWB | B12: OUT4_19_PR24 | C12: Underlying calculations for common performance commitments - water and combined - Discharge permit compliance - Percentage compliance | D12: % | E12: Price Review 2024 | F12: 0.96485623 | G12: 0.93269231 | H12: 0.96141479 | I12: 0.95527157 | J12: 0.98076923 | K12: 0.97096774 | L12: 0.98722045 | M12: 0.98713826 | N12: 0.9903537 | O12: 0.97460317 | P12: 0.99365079 | Q12: 0.96190476
A13: SRN | B13: OUT4_19_PR24 | C13: Underlying calculations for common performance commitments - water and combined - Discharge permit compliance - Percentage compliance | D13: % | E13: Price Review 2024 | F13: 0.96283784 | G13: 0.95297806 | H13: 0.98101266 | I13: 0.98392283 | J13: 0.98722045 | K13: 0.98170732 | L13: 0.99099099 | M13: 0.98809524 | N13: 0.97058824 | O13: 0.97941176 | P13: 0.98214286 | Q13: 0.99404762
A14: TMS | B14: OUT4_19_PR24 | C14: Underlying calculations for common performance commitments - water and combined - Discharge permit compliance - Percentage compliance | D14: % | E14: Price Review 2024 | F14: 0.99208443 | G14: 0.95572917 | H14: 0.98691099 | I14: 0.99210526 | J14: 0.97911227 | K14: 0.99477807 | L14: 0.98958333 | M14: 0.9974026 | N14: 0.9974026 | O14: 0.98958333 | P14: 0.99479167 | Q14: 0.9921875
A15: NWT | B15: OUT4_19_PR24 | C15: Underlying calculations for common performance commitments - water and combined - Discharge permit compliance - Percentage compliance | D15: % | E15: Price Review 2024 | F15: 0.99164345 | G15: 0.98607242 | H15: 0.98333333 | I15: 0.97206704 | J15: 0.97374702 | K15: 0.98762376 | L15: 0.98737374 | M15: 0.98469388 | N15: 0.99748111 | O15: 0.98976982 | P15: 0.98453608 | Q15: 0.98969072
A16: WSX | B16: OUT4_19_PR24 | C16: Underlying calculations for common performance commitments - water and combined - Discharge permit compliance - Percentage compliance | D16: % | E16: Price Review 2024 | F16: 0.99671053 | G16: 0.99016393 | H16: 0.99667774 | I16: 0.99666667 | J16: 0.99371069 | K16: 0.99019608 | L16: 1 | M16: 0.98461538 | N16: 0.99076923 | O16: 1 | P16: 0.99350649 | Q16: 0.99025974
A17: YKY | B17: OUT4_19_PR24 | C17: Underlying calculations for common performance commitments - water and combined - Discharge permit compliance - Percentage compliance | D17: % | E17: Price Review 2024 | F17: 0.97278912 | G17: 0.97979798 | H17: 0.99331104 | I17: 0.99322034 | J17: 0.97169811 | K17: 0.97770701 | L17: 0.97452229 | M17: 0.97468354 | N17: 0.99038462 | O17: 0.99032258 | P17: 0.99680511 | Q17: 0.99041534
A18: AFW | B18: OUT4_19_PR24 | C18: Underlying calculations for common performance commitments - water and combined - Discharge permit compliance - Percentage compliance | D18: % | E18: Price Review 2024 | F18: 1 | G18: 1 | H18: 1 | I18: 1 | J18: 1 | K18: 1 | L18: 1 | M18: 1 | N18: 0.97619048 | O18: 0.96774194 | P18: 0.96774194 | Q18: 1
A19: BRL | B19: OUT4_19_PR24 | C19: Underlying calculations for common performance commitments - water and combined - Discharge permit compliance - Percentage compliance | D19: % | E19: Price Review 2024 | M19: 1 | N19: 1 | O19: 1 | P19: 1 | Q19: 1
A20: SSC | B20: OUT4_19_PR24 | C20: Underlying calculations for common performance commitments - water and combined - Discharge permit compliance - Percentage compliance | D20: % | E20: Price Review 2024 | M20: 0.93103448 | N20: 1 | O20: 0.86206897 | P20: 0.86206897 | Q20: 0.96551724
A21: PRT | B21: OUT4_19_PR24 | C21: Underlying calculations for common performance commitments - water and combined - Discharge permit compliance - Percentage compliance | D21: % | E21: Price Review 2024 | F21: 1 | G21: 1 | H21: 1 | I21: 1 | J21: 1 | K21: 0.83333333 | L21: 1 | M21: 1 | N21: 1 | O21: 1 | P21: 1 | Q21: 0.83333333
A22: SEW | B22: OUT4_19_PR24 | C22: Underlying calculations for common performance commitments - water and combined - Discharge permit compliance - Percentage compliance | D22: % | E22: Price Review 2024 | G22: 0.97368421 | H22: 0.92105263 | I22: 0.98684211 | J22: 0.93421053 | K22: 0.94736842 | L22: 0.96052632 | M22: 0.96052632 | N22: 0.98684211 | O22: 0.97368421 | P22: 0.92105263 | Q22: 0.92105263
A23: SES | B23: OUT4_19_PR24 | C23: Underlying calculations for common performance commitments - water and combined - Discharge permit compliance - Percentage compliance | D23: % | E23: Price Review 2024 | F23: 1 | G23: 1 | H23: 1 | I23: 1 | J23: 1 | K23: 1 | L23: 1 | M23: 1 | N23: 1 | O23: 1 | P23: 1 | Q23: 1
A25: END

Sheet Inputs_All
A1: =RIGHT(CELL("filename", A1), LEN(CELL("filename", A1)) - SEARCH("]", CELL("filename", A1))) -> Inputs_All
K2: 2012-13 | L2: 2013-14 | M2: 2014-15 | N2: 2015-16 | O2: 2016-17 | P2: 2017-18 | Q2: 2018-19 | R2: 2019-20 | S2: 2020-21 | T2: 2021-22 | U2: 2022-23 | V2: 2023-24
E3: Company | G3: Performance Commitment | H3: Measure | I3: Unit
A7: Percentage Compliance
E9: ANH | F9: WaSC | G9: DPC | H9: Percentage compliance | I9: % | K9: =F_Inputs!F7 -> 0.97073791 | L9: =F_Inputs!G7 -> 0.97197452 | M9: =F_Inputs!H7 -> 0.98348158 | N9: =F_Inputs!I7 -> 0.9826087 | O9: =F_Inputs!J7 -> 0.99119497 | P9: =F_Inputs!K7 -> 0.98612863 | Q9: =F_Inputs!L7 -> 0.98212157 | R9: =F_Inputs!M7 -> 0.9858156 | ... V9: =F_Inputs!Q7 -> 0.98444976
E10: WSH | F10: WaSC | G10: DPC | H10: Percentage compliance | I10: % | K10: =F_Inputs!F8 -> 0.97063369 | L10: =F_Inputs!G8 -> 0.96360759 | M10: =F_Inputs!H8 -> 0.97752809 | N10: =F_Inputs!I8 -> 0.97087379 | O10: =F_Inputs!J8 -> 0.99029126 | P10: =F_Inputs!K8 -> 0.9669967 | Q10: =F_Inputs!L8 -> 0.98019802 | R10: =F_Inputs!M8 -> 0.98181818 | ... V10: =F_Inputs!Q8 -> 0.9800995
E11: HDD | F11: WaSC | G11: DPC | H11: Percentage compliance | I11: % | K11: =F_Inputs!F9 -> 1 | L11: =F_Inputs!G9 -> 1 | M11: =F_Inputs!H9 -> 0.75 | N11: =F_Inputs!I9 -> 1 | O11: =F_Inputs!J9 -> 1 | P11: =F_Inputs!K9 -> 1 | Q11: =F_Inputs!L9 -> 1 | R11: =F_Inputs!M9 -> 1 | ... V11: =F_Inputs!Q9 -> 1
E12: NES | F12: WaSC | G12: DPC | H12: Percentage compliance | I12: % | K12: =F_Inputs!F10 | L12: =F_Inputs!G10 | M12: =F_Inputs!H10 | N12: =F_Inputs!I10 | O12: =F_Inputs!J10 | P12: =F_Inputs!K10 -> 0.96 | Q12: =F_Inputs!L10 -> 0.995 | R12: =F_Inputs!M10 -> 0.96568627 | ... V12: =F_Inputs!Q10 -> 0.98543689
E13: SVE | F13: WaSC | G13: DPC | H13: Percentage compliance | I13: % | K13: =F_Inputs!F11 | L13: =F_Inputs!G11 | M13: =F_Inputs!H11 | N13: =F_Inputs!I11 | O13: =F_Inputs!J11 | P13: =F_Inputs!K11 -> 0.9963145 | Q13: =F_Inputs!L11 -> 0.98423127 | R13: =F_Inputs!M11 -> 0.99605782 | ... V13: =F_Inputs!Q11 -> 0.99462366
E14: SWB | F14: WaSC | G14: DPC | H14: Percentage compliance | I14: % | K14: =F_Inputs!F12 -> 0.96485623 | L14: =F_Inputs!G12 -> 0.93269231 | M14: =F_Inputs!H12 -> 0.96141479 | N14: =F_Inputs!I12 -> 0.95527157 | O14: =F_Inputs!J12 -> 0.98076923 | P14: =F_Inputs!K12 -> 0.97096774 | Q14: =F_Inputs!L12 -> 0.98722045 | R14: =F_Inputs!M12 -> 0.98713826 | ... V14: =F_Inputs!Q12 -> 0.96190476
E15: SRN | F15: WaSC | G15: DPC | H15: Percentage compliance | I15: % | K15: =F_Inputs!F13 -> 0.96283784 | L15: =F_Inputs!G13 -> 0.95297806 | M15: =F_Inputs!H13 -> 0.98101266 | N15: =F_Inputs!I13 -> 0.98392283 | O15: =F_Inputs!J13 -> 0.98722045 | P15: =F_Inputs!K13 -> 0.98170732 | Q15: =F_Inputs!L13 -> 0.99099099 | R15: =F_Inputs!M13 -> 0.98809524 | ... V15: =F_Inputs!Q13 -> 0.99404762
E16: TMS | F16: WaSC | G16: DPC | H16: Percentage compliance | I16: % | K16: =F_Inputs!F14 -> 0.99208443 | L16: =F_Inputs!G14 -> 0.95572917 | M16: =F_Inputs!H14 -> 0.98691099 | N16: =F_Inputs!I14 -> 0.99210526 | O16: =F_Inputs!J14 -> 0.97911227 | P16: =F_Inputs!K14 -> 0.99477807 | Q16: =F_Inputs!L14 -> 0.98958333 | R16: =F_Inputs!M14 -> 0.9974026 | ... V16: =F_Inputs!Q14 -> 0.9921875
E17: UUW | F17: WaSC | G17: DPC | H17: Percentage compliance | I17: % | K17: =F_Inputs!F15 -> 0.99164345 | L17: =F_Inputs!G15 -> 0.98607242 | M17: =F_Inputs!H15 -> 0.98333333 | N17: =F_Inputs!I15 -> 0.97206704 | O17: =F_Inputs!J15 -> 0.97374702 | P17: =F_Inputs!K15 -> 0.98762376 | Q17: =F_Inputs!L15 -> 0.98737374 | R17: =F_Inputs!M15 -> 0.98469388 | ... V17: =F_Inputs!Q15 -> 0.98969072
E18: WSX | F18: WaSC | G18: DPC | H18: Percentage compliance | I18: % | K18: =F_Inputs!F16 -> 0.99671053 | L18: =F_Inputs!G16 -> 0.99016393 | M18: =F_Inputs!H16 -> 0.99667774 | N18: =F_Inputs!I16 -> 0.99666667 | O18: =F_Inputs!J16 -> 0.99371069 | P18: =F_Inputs!K16 -> 0.99019608 | Q18: =F_Inputs!L16 -> 1 | R18: =F_Inputs!M16 -> 0.98461538 | ... V18: =F_Inputs!Q16 -> 0.99025974
E19: YKY | F19: WaSC | G19: DPC | H19: Percentage compliance | I19: % | K19: =F_Inputs!F17 -> 0.97278912 | L19: =F_Inputs!G17 -> 0.97979798 | M19: =F_Inputs!H17 -> 0.99331104 | N19: =F_Inputs!I17 -> 0.99322034 | O19: =F_Inputs!J17 -> 0.97169811 | P19: =F_Inputs!K17 -> 0.97770701 | Q19: =F_Inputs!L17 -> 0.97452229 | R19: =F_Inputs!M17 -> 0.97468354 | ... V19: =F_Inputs!Q17 -> 0.99041534
E20: AFW | F20: WoC | G20: DPC | H20: Percentage compliance | I20: % | K20: =F_Inputs!F18 -> 1 | L20: =F_Inputs!G18 -> 1 | M20: =F_Inputs!H18 -> 1 | N20: =F_Inputs!I18 -> 1 | O20: =F_Inputs!J18 -> 1 | P20: =F_Inputs!K18 -> 1 | Q20: =F_Inputs!L18 -> 1 | R20: =F_Inputs!M18 -> 1 | ... V20: =F_Inputs!Q18 -> 1
... E25: SES | F25: WoC | G25: DPC | H25: Percentage compliance | I25: % | K25: =F_Inputs!F23 -> 1 | L25: =F_Inputs!G23 -> 1 | M25: =F_Inputs!H23 -> 1 | N25: =F_Inputs!I23 -> 1 | O25: =F_Inputs!J23 -> 1 | P25: =F_Inputs!K23 -> 1 | Q25: =F_Inputs!L23 -> 1 | R25: =F_Inputs!M23 -> 1 | ... V25: =F_Inputs!Q23 -> 1
A27: Industry-wide Historic PCL
G29: DPC | H29: Percentage compliance | I29: % | K29: 1 | L29: 1 | M29: 1 | N29: 1 | O29: 1 | P29: 1 | Q29: 1 | R29: 1 | S29: 1 | T29: 1 | U29: 1 | V29: 1
A31: END

Sheet Difference to PCL
A1: =RIGHT(CELL("filename", A1), LEN(CELL("filename", A1)) - SEARCH("]", CELL("filename", A1))) -> Difference to PCL
J2: 2012-13 | K2: 2013-14 | L2: 2014-15 | M2: 2015-16 | N2: 2016-17 | O2: 2017-18 | P2: 2018-19 | Q2: 2019-20 | R2: 2020-21 | S2: 2021-22 | T2: 2022-23 | U2: 2023-24
E3: Company | F3: Performance Commitment | G3: Measure | H3: Unit
A7: Discharge permit compliance - percentage compliance
E9: ANH | F9: DPC | G9: Percentage compliance | H9: % | J9: =Inputs_All!K9 -> 0.97073791 | K9: =Inputs_All!L9 -> 0.97197452 | L9: =Inputs_All!M9 -> 0.98348158 | M9: =Inputs_All!N9 -> 0.9826087 | N9: =Inputs_All!O9 -> 0.99119497 | O9: =Inputs_All!P9 -> 0.98612863 | P9: =Inputs_All!Q9 -> 0.98212157 | Q9: =Inputs_All!R9 -> 0.9858156 | ... U9: =Inputs_All!V9 -> 0.98444976
E10: WSH | F10: DPC | G10: Percentage compliance | H10: % | J10: =Inputs_All!K10 -> 0.97063369 | K10: =Inputs_All!L10 -> 0.96360759 | L10: =Inputs_All!M10 -> 0.97752809 | M10: =Inputs_All!N10 -> 0.97087379 | N10: =Inputs_All!O10 -> 0.99029126 | O10: =Inputs_All!P10 -> 0.9669967 | P10: =Inputs_All!Q10 -> 0.98019802 | Q10: =Inputs_All!R10 -> 0.98181818 | ... U10: =Inputs_All!V10 -> 0.9800995
E11: HDD | F11: DPC | G11: Percentage compliance | H11: % | J11: =Inputs_All!K11 -> 1 | K11: =Inputs_All!L11 -> 1 | L11: =Inputs_All!M11 -> 0.75 | M11: =Inputs_All!N11 -> 1 | N11: =Inputs_All!O11 -> 1 | O11: =Inputs_All!P11 -> 1 | P11: =Inputs_All!Q11 -> 1 | Q11: =Inputs_All!R11 -> 1 | ... U11: =Inputs_All!V11 -> 1
E12: NES | F12: DPC | G12: Percentage compliance | H12: % | J12: =Inputs_All!K12 | K12: =Inputs_All!L12 | L12: =Inputs_All!M12 | M12: =Inputs_All!N12 | N12: =Inputs_All!O12 | O12: =Inputs_All!P12 -> 0.96 | P12: =Inputs_All!Q12 -> 0.995 | Q12: =Inputs_All!R12 -> 0.96568627 | ... U12: =Inputs_All!V12 -> 0.98543689
E13: SVE | F13: DPC | G13: Percentage compliance | H13: % | J13: =Inputs_All!K13 | K13: =Inputs_All!L13 | L13: =Inputs_All!M13 | M13: =Inputs_All!N13 | N13: =Inputs_All!O13 | O13: =Inputs_All!P13 -> 0.9963145 | P13: =Inputs_All!Q13 -> 0.98423127 | Q13: =Inputs_All!R13 -> 0.99605782 | ... U13: =Inputs_All!V13 -> 0.99462366
E14: SWB | F14: DPC | G14: Percentage compliance | H14: % | J14: =Inputs_All!K14 -> 0.96485623 | K14: =Inputs_All!L14 -> 0.93269231 | L14: =Inputs_All!M14 -> 0.96141479 | M14: =Inputs_All!N14 -> 0.95527157 | N14: =Inputs_All!O14 -> 0.98076923 | O14: =Inputs_All!P14 -> 0.97096774 | P14: =Inputs_All!Q14 -> 0.98722045 | Q14: =Inputs_All!R14 -> 0.98713826 | ... U14: =Inputs_All!V14 -> 0.96190476
E15: SRN | F15: DPC | G15: Percentage compliance | H15: % | J15: =Inputs_All!K15 -> 0.96283784 | K15: =Inputs_All!L15 -> 0.95297806 | L15: =Inputs_All!M15 -> 0.98101266 | M15: =Inputs_All!N15 -> 0.98392283 | N15: =Inputs_All!O15 -> 0.98722045 | O15: =Inputs_All!P15 -> 0.98170732 | P15: =Inputs_All!Q15 -> 0.99099099 | Q15: =Inputs_All!R15 -> 0.98809524 | ... U15: =Inputs_All!V15 -> 0.99404762
E16: TMS | F16: DPC | G16: Percentage compliance | H16: % | J16: =Inputs_All!K16 -> 0.99208443 | K16: =Inputs_All!L16 -> 0.95572917 | L16: =Inputs_All!M16 -> 0.98691099 | M16: =Inputs_All!N16 -> 0.99210526 | N16: =Inputs_All!O16 -> 0.97911227 | O16: =Inputs_All!P16 -> 0.99477807 | P16: =Inputs_All!Q16 -> 0.98958333 | Q16: =Inputs_All!R16 -> 0.9974026 | ... U16: =Inputs_All!V16 -> 0.9921875
E17: UUW | F17: DPC | G17: Percentage compliance | H17: % | J17: =Inputs_All!K17 -> 0.99164345 | K17: =Inputs_All!L17 -> 0.98607242 | L17: =Inputs_All!M17 -> 0.98333333 | M17: =Inputs_All!N17 -> 0.97206704 | N17: =Inputs_All!O17 -> 0.97374702 | O17: =Inputs_All!P17 -> 0.98762376 | P17: =Inputs_All!Q17 -> 0.98737374 | Q17: =Inputs_All!R17 -> 0.98469388 | ... U17: =Inputs_All!V17 -> 0.98969072
E18: WSX | F18: DPC | G18: Percentage compliance | H18: % | J18: =Inputs_All!K18 -> 0.99671053 | K18: =Inputs_All!L18 -> 0.99016393 | L18: =Inputs_All!M18 -> 0.99667774 | M18: =Inputs_All!N18 -> 0.99666667 | N18: =Inputs_All!O18 -> 0.99371069 | O18: =Inputs_All!P18 -> 0.99019608 | P18: =Inputs_All!Q18 -> 1 | Q18: =Inputs_All!R18 -> 0.98461538 | ... U18: =Inputs_All!V18 -> 0.99025974
E19: YKY | F19: DPC | G19: Percentage compliance | H19: % | J19: =Inputs_All!K19 -> 0.97278912 | K19: =Inputs_All!L19 -> 0.97979798 | L19: =Inputs_All!M19 -> 0.99331104 | M19: =Inputs_All!N19 -> 0.99322034 | N19: =Inputs_All!O19 -> 0.97169811 | O19: =Inputs_All!P19 -> 0.97770701 | P19: =Inputs_All!Q19 -> 0.97452229 | Q19: =Inputs_All!R19 -> 0.97468354 | ... U19: =Inputs_All!V19 -> 0.99041534
E20: AFW | F20: DPC | G20: Percentage compliance | H20: % | J20: =Inputs_All!K20 -> 1 | K20: =Inputs_All!L20 -> 1 | L20: =Inputs_All!M20 -> 1 | M20: =Inputs_All!N20 -> 1 | N20: =Inputs_All!O20 -> 1 | O20: =Inputs_All!P20 -> 1 | P20: =Inputs_All!Q20 -> 1 | Q20: =Inputs_All!R20 -> 1 | ... U20: =Inputs_All!V20 -> 1
... E25: SES | F25: DPC | G25: Percentage compliance | H25: % | J25: =Inputs_All!K25 -> 1 | K25: =Inputs_All!L25 -> 1 | L25: =Inputs_All!M25 -> 1 | M25: =Inputs_All!N25 -> 1 | N25: =Inputs_All!O25 -> 1 | O25: =Inputs_All!P25 -> 1 | P25: =Inputs_All!Q25 -> 1 | Q25: =Inputs_All!R25 -> 1 | ... U25: =Inputs_All!V25 -> 1
A27: PCL
F29: DPC | G29: Percentage compliance | H29: % | J29: =Inputs_All!K29 -> 1 | K29: =Inputs_All!L29 -> 1 | L29: =Inputs_All!M29 -> 1 | M29: =Inputs_All!N29 -> 1 | N29: =Inputs_All!O29 -> 1 | O29: =Inputs_All!P29 -> 1 | P29: =Inputs_All!Q29 -> 1 | Q29: =Inputs_All!R29 -> 1 | ... U29: =Inputs_All!V29 -> 1
A31: Difference to PCL (Numeric)
E33: ANH | F33: DPC | G33: Difference to PCL (Numeric) | H33: % | J33: =IF(J9="","",J9-$J$29) -> -0.029262087 | K33: =IF(K9="","",K9-$J$29) -> -0.028025478 | L33: =IF(L9="","",L9-$J$29) -> -0.016518424 | M33: =IF(M9="","",M9-$J$29) -> -0.017391304 | N33: =IF(N9="","",N9-$J$29) -> -0.0088050314 | O33: =IF(O9="","",O9-$J$29) -> -0.013871375 | P33: =IF(P9="","",P9-$J$29) -> -0.017878427 | Q33: =IF(Q9="","",Q9-$J$29) -> -0.014184397 | ... U33: =IF(U9="","",U9-$J$29) -> -0.015550239
E34: WSH | F34: DPC | G34: Difference to PCL (Numeric) | H34: % | J34: =IF(J10="","",J10-$J$29) -> -0.029366306 | K34: =IF(K10="","",K10-$J$29) -> -0.036392405 | L34: =IF(L10="","",L10-$J$29) -> -0.02247191 | M34: =IF(M10="","",M10-$J$29) -> -0.029126214 | N34: =IF(N10="","",N10-$J$29) -> -0.0097087379 | O34: =IF(O10="","",O10-$J$29) -> -0.0330033 | P34: =IF(P10="","",P10-$J$29) -> -0.01980198 | Q34: =IF(Q10="","",Q10-$J$29) -> -0.018181818 | ... U34: =IF(U10="","",U10-$J$29) -> -0.019900498
E35: HDD | F35: DPC | G35: Difference to PCL (Numeric) | H35: % | J35: =IF(J11="","",J11-$J$29) -> 0 | K35: =IF(K11="","",K11-$J$29) -> 0 | L35: =IF(L11="","",L11-$J$29) -> -0.25 | M35: =IF(M11="","",M11-$J$29) -> 0 | N35: =IF(N11="","",N11-$J$29) -> 0 | O35: =IF(O11="","",O11-$J$29) -> 0 | P35: =IF(P11="","",P11-$J$29) -> 0 | Q35: =IF(Q11="","",Q11-$J$29) -> 0 | ... U35: =IF(U11="","",U11-$J$29) -> 0
E36: NES | F36: DPC | G36: Difference to PCL (Numeric) | H36: % | J36: =IF(J12="","",J12-$J$29) | K36: =IF(K12="","",K12-$J$29) | L36: =IF(L12="","",L12-$J$29) | M36: =IF(M12="","",M12-$J$29) | N36: =IF(N12="","",N12-$J$29) | O36: =IF(O12="","",O12-$J$29) -> -0.04 | P36: =IF(P12="","",P12-$J$29) -> -0.005 | Q36: =IF(Q12="","",Q12-$J$29) -> -0.034313725 | ... U36: =IF(U12="","",U12-$J$29) -> -0.014563107
E37: SVE | F37: DPC | G37: Difference to PCL (Numeric) | H37: % | J37: =IF(J13="","",J13-$J$29) | K37: =IF(K13="","",K13-$J$29) | L37: =IF(L13="","",L13-$J$29) | M37: =IF(M13="","",M13-$J$29) | N37: =IF(N13="","",N13-$J$29) | O37: =IF(O13="","",O13-$J$29) -> -0.0036855037 | P37: =IF(P13="","",P13-$J$29) -> -0.015768725 | Q37: =IF(Q13="","",Q13-$J$29) -> -0.0039421813 | ... U37: =IF(U13="","",U13-$J$29) -> -0.0053763441
E38: SWB | F38: DPC | G38: Difference to PCL (Numeric) | H38: % | J38: =IF(J14="","",J14-$J$29) -> -0.03514377 | K38: =IF(K14="","",K14-$J$29) -> -0.067307692 | L38: =IF(L14="","",L14-$J$29) -> -0.038585209 | M38: =IF(M14="","",M14-$J$29) -> -0.044728435 | N38: =IF(N14="","",N14-$J$29) -> -0.019230769 | O38: =IF(O14="","",O14-$J$29) -> -0.029032258 | P38: =IF(P14="","",P14-$J$29) -> -0.012779553 | Q38: =IF(Q14="","",Q14-$J$29) -> -0.012861736 | ... U38: =IF(U14="","",U14-$J$29) -> -0.038095238
E39: SRN | F39: DPC | G39: Difference to PCL (Numeric) | H39: % | J39: =IF(J15="","",J15-$J$29) -> -0.037162162 | K39: =IF(K15="","",K15-$J$29) -> -0.047021944 | L39: =IF(L15="","",L15-$J$29) -> -0.018987342 | M39: =IF(M15="","",M15-$J$29) -> -0.01607717 | N39: =IF(N15="","",N15-$J$29) -> -0.012779553 | O39: =IF(O15="","",O15-$J$29) -> -0.018292683 | P39: =IF(P15="","",P15-$J$29) -> -0.009009009 | Q39: =IF(Q15="","",Q15-$J$29) -> -0.011904762 | ... U39: =IF(U15="","",U15-$J$29) -> -0.005952381
E40: TMS | F40: DPC | G40: Difference to PCL (Numeric) | H40: % | J40: =IF(J16="","",J16-$J$29) -> -0.0079155673 | K40: =IF(K16="","",K16-$J$29) -> -0.044270833 | L40: =IF(L16="","",L16-$J$29) -> -0.013089005 | M40: =IF(M16="","",M16-$J$29) -> -0.0078947368 | N40: =IF(N16="","",N16-$J$29) -> -0.020887728 | O40: =IF(O16="","",O16-$J$29) -> -0.0052219321 | P40: =IF(P16="","",P16-$J$29) -> -0.010416667 | Q40: =IF(Q16="","",Q16-$J$29) -> -0.0025974026 | ... U40: =IF(U16="","",U16-$J$29) -> -0.0078125
E41: UUW | F41: DPC | G41: Difference to PCL (Numeric) | H41: % | J41: =IF(J17="","",J17-$J$29) -> -0.008356546 | K41: =IF(K17="","",K17-$J$29) -> -0.013927577 | L41: =IF(L17="","",L17-$J$29) -> -0.016666667 | M41: =IF(M17="","",M17-$J$29) -> -0.027932961 | N41: =IF(N17="","",N17-$J$29) -> -0.026252983 | O41: =IF(O17="","",O17-$J$29) -> -0.012376238 | P41: =IF(P17="","",P17-$J$29) -> -0.012626263 | Q41: =IF(Q17="","",Q17-$J$29) -> -0.015306122 | ... U41: =IF(U17="","",U17-$J$29) -> -0.010309278
E42: WSX | F42: DPC | G42: Difference to PCL (Numeric) | H42: % | J42: =IF(J18="","",J18-$J$29) -> -0.0032894737 | K42: =IF(K18="","",K18-$J$29) -> -0.0098360656 | L42: =IF(L18="","",L18-$J$29) -> -0.0033222591 | M42: =IF(M18="","",M18-$J$29) -> -0.0033333333 | N42: =IF(N18="","",N18-$J$29) -> -0.0062893082 | O42: =IF(O18="","",O18-$J$29) -> -0.0098039216 | P42: =IF(P18="","",P18-$J$29) -> 0 | Q42: =IF(Q18="","",Q18-$J$29) -> -0.015384615 | ... U42: =IF(U18="","",U18-$J$29) -> -0.0097402597
E43: YKY | F43: DPC | G43: Difference to PCL (Numeric) | H43: % | J43: =IF(J19="","",J19-$J$29) -> -0.027210884 | K43: =IF(K19="","",K19-$J$29) -> -0.02020202 | L43: =IF(L19="","",L19-$J$29) -> -0.0066889632 | M43: =IF(M19="","",M19-$J$29) -> -0.006779661 | N43: =IF(N19="","",N19-$J$29) -> -0.028301887 | O43: =IF(O19="","",O19-$J$29) -> -0.022292994 | P43: =IF(P19="","",P19-$J$29) -> -0.025477707 | Q43: =IF(Q19="","",Q19-$J$29) -> -0.025316456 | ... U43: =IF(U19="","",U19-$J$29) -> -0.0095846645
E44: AFW | F44: DPC | G44: Difference to PCL (Numeric) | H44: % | J44: =IF(J20="","",J20-$J$29) -> 0 | K44: =IF(K20="","",K20-$J$29) -> 0 | L44: =IF(L20="","",L20-$J$29) -> 0 | M44: =IF(M20="","",M20-$J$29) -> 0 | N44: =IF(N20="","",N20-$J$29) -> 0 | O44: =IF(O20="","",O20-$J$29) -> 0 | P44: =IF(P20="","",P20-$J$29) -> 0 | Q44: =IF(Q20="","",Q20-$J$29) -> 0 | ... U44: =IF(U20="","",U20-$J$29) -> 0
... E49: SES | F49: DPC | G49: Difference to PCL (Numeric) | H49: % | J49: =IF(J25="","",J25-$J$29) -> 0 | K49: =IF(K25="","",K25-$J$29) -> 0 | L49: =IF(L25="","",L25-$J$29) -> 0 | M49: =IF(M25="","",M25-$J$29) -> 0 | N49: =IF(N25="","",N25-$J$29) -> 0 | O49: =IF(O25="","",O25-$J$29) -> 0 | P49: =IF(P25="","",P25-$J$29) -> 0 | Q49: =IF(Q25="","",Q25-$J$29) -> 0 | ... U49: =IF(U25="","",U25-$J$29) -> 0
A51: Difference to PCL (As % of PCL)
E53: ANH | F53: DPC | G53: Difference to PCL (As % of PCL) | H53: % | J53: =IF(J33="","",J33/J$29) -> -0.029262087 | K53: =IF(K33="","",K33/K$29) -> -0.028025478 | L53: =IF(L33="","",L33/L$29) -> -0.016518424 | M53: =IF(M33="","",M33/M$29) -> -0.017391304 | N53: =IF(N33="","",N33/N$29) -> -0.0088050314 | O53: =IF(O33="","",O33/O$29) -> -0.013871375 | P53: =IF(P33="","",P33/P$29) -> -0.017878427 | Q53: =IF(Q33="","",Q33/Q$29) -> -0.014184397 | ... U53: =IF(U33="","",U33/U$29) -> -0.015550239
E54: WSH | F54: DPC | G54: Difference to PCL (As % of PCL) | H54: % | J54: =IF(J34="","",J34/J$29) -> -0.029366306 | K54: =IF(K34="","",K34/K$29) -> -0.036392405 | L54: =IF(L34="","",L34/L$29) -> -0.02247191 | M54: =IF(M34="","",M34/M$29) -> -0.029126214 | N54: =IF(N34="","",N34/N$29) -> -0.0097087379 | O54: =IF(O34="","",O34/O$29) -> -0.0330033 | P54: =IF(P34="","",P34/P$29) -> -0.01980198 | Q54: =IF(Q34="","",Q34/Q$29) -> -0.018181818 | ... U54: =IF(U34="","",U34/U$29) -> -0.019900498
E55: HDD | F55: DPC | G55: Difference to PCL (As % of PCL) | H55: % | J55: =IF(J35="","",J35/J$29) -> 0 | K55: =IF(K35="","",K35/K$29) -> 0 | L55: =IF(L35="","",L35/L$29) -> -0.25 | M55: =IF(M35="","",M35/M$29) -> 0 | N55: =IF(N35="","",N35/N$29) -> 0 | O55: =IF(O35="","",O35/O$29) -> 0 | P55: =IF(P35="","",P35/P$29) -> 0 | Q55: =IF(Q35="","",Q35/Q$29) -> 0 | ... U55: =IF(U35="","",U35/U$29) -> 0
E56: NES | F56: DPC | G56: Difference to PCL (As % of PCL) | H56: % | J56: =IF(J36="","",J36/J$29) | K56: =IF(K36="","",K36/K$29) | L56: =IF(L36="","",L36/L$29) | M56: =IF(M36="","",M36/M$29) | N56: =IF(N36="","",N36/N$29) | O56: =IF(O36="","",O36/O$29) -> -0.04 | P56: =IF(P36="","",P36/P$29) -> -0.005 | Q56: =IF(Q36="","",Q36/Q$29) -> -0.034313725 | ... U56: =IF(U36="","",U36/U$29) -> -0.014563107
E57: SVE | F57: DPC | G57: Difference to PCL (As % of PCL) | H57: % | J57: =IF(J37="","",J37/J$29) | K57: =IF(K37="","",K37/K$29) | L57: =IF(L37="","",L37/L$29) | M57: =IF(M37="","",M37/M$29) | N57: =IF(N37="","",N37/N$29) | O57: =IF(O37="","",O37/O$29) -> -0.0036855037 | P57: =IF(P37="","",P37/P$29) -> -0.015768725 | Q57: =IF(Q37="","",Q37/Q$29) -> -0.0039421813 | ... U57: =IF(U37="","",U37/U$29) -> -0.0053763441
E58: SWB | F58: DPC | G58: Difference to PCL (As % of PCL) | H58: % | J58: =IF(J38="","",J38/J$29) -> -0.03514377 | K58: =IF(K38="","",K38/K$29) -> -0.067307692 | L58: =IF(L38="","",L38/L$29) -> -0.038585209 | M58: =IF(M38="","",M38/M$29) -> -0.044728435 | N58: =IF(N38="","",N38/N$29) -> -0.019230769 | O58: =IF(O38="","",O38/O$29) -> -0.029032258 | P58: =IF(P38="","",P38/P$29) -> -0.012779553 | Q58: =IF(Q38="","",Q38/Q$29) -> -0.012861736 | ... U58: =IF(U38="","",U38/U$29) -> -0.038095238
...

Sheet Percentiles
A1: =RIGHT(CELL("filename", A1), LEN(CELL("filename", A1)) - SEARCH("]", CELL("filename", A1))) -> Percentiles
K2: 2012-13 | L2: 2013-14 | M2: 2014-15 | N2: 2015-16 | O2: 2016-17 | P2: 2017-18 | Q2: 2018-19 | R2: 2019-20 | S2: 2020-21 | T2: 2021-22 | U2: 2022-23 | V2: 2023-24
E3: Company | F3: Performance Commitment | G3: Percentile | H3: Value | I3: Helper
A7: Difference to PCL
E9: ANH | F9: DPC | K9: ='Difference to PCL'!J53 -> -0.029262087 | L9: ='Difference to PCL'!K53 -> -0.028025478 | M9: ='Difference to PCL'!L53 -> -0.016518424 | N9: ='Difference to PCL'!M53 -> -0.017391304 | O9: ='Difference to PCL'!N53 -> -0.0088050314 | P9: ='Difference to PCL'!O53 -> -0.013871375 | Q9: ='Difference to PCL'!P53 -> -0.017878427 | R9: ='Difference to PCL'!Q53 -> -0.014184397 | ... V9: ='Difference to PCL'!U53 -> -0.015550239
E10: WSH | F10: DPC | K10: ='Difference to PCL'!J54 -> -0.029366306 | L10: ='Difference to PCL'!K54 -> -0.036392405 | M10: ='Difference to PCL'!L54 -> -0.02247191 | N10: ='Difference to PCL'!M54 -> -0.029126214 | O10: ='Difference to PCL'!N54 -> -0.0097087379 | P10: ='Difference to PCL'!O54 -> -0.0330033 | Q10: ='Difference to PCL'!P54 -> -0.01980198 | R10: ='Difference to PCL'!Q54 -> -0.018181818 | ... V10: ='Difference to PCL'!U54 -> -0.019900498
E11: HDD | F11: DPC | K11: ='Difference to PCL'!J55 -> 0 | L11: ='Difference to PCL'!K55 -> 0 | M11: ='Difference to PCL'!L55 -> -0.25 | N11: ='Difference to PCL'!M55 -> 0 | O11: ='Difference to PCL'!N55 -> 0 | P11: ='Difference to PCL'!O55 -> 0 | Q11: ='Difference to PCL'!P55 -> 0 | R11: ='Difference to PCL'!Q55 -> 0 | ... V11: ='Difference to PCL'!U55 -> 0
E12: NES | F12: DPC | K12: ='Difference to PCL'!J56 | L12: ='Difference to PCL'!K56 | M12: ='Difference to PCL'!L56 | N12: ='Difference to PCL'!M56 | O12: ='Difference to PCL'!N56 | P12: ='Difference to PCL'!O56 -> -0.04 | Q12: ='Difference to PCL'!P56 -> -0.005 | R12: ='Difference to PCL'!Q56 -> -0.034313725 | ... V12: ='Difference to PCL'!U56 -> -0.014563107
E13: SVE | F13: DPC | K13: ='Difference to PCL'!J57 | L13: ='Difference to PCL'!K57 | M13: ='Difference to PCL'!L57 | N13: ='Difference to PCL'!M57 | O13: ='Difference to PCL'!N57 | P13: ='Difference to PCL'!O57 -> -0.0036855037 | Q13: ='Difference to PCL'!P57 -> -0.015768725 | R13: ='Difference to PCL'!Q57 -> -0.0039421813 | ... V13: ='Difference to PCL'!U57 -> -0.0053763441
E14: SWB | F14: DPC | K14: ='Difference to PCL'!J58 -> -0.03514377 | L14: ='Difference to PCL'!K58 -> -0.067307692 | M14: ='Difference to PCL'!L58 -> -0.038585209 | N14: ='Difference to PCL'!M58 -> -0.044728435 | O14: ='Difference to PCL'!N58 -> -0.019230769 | P14: ='Difference to PCL'!O58 -> -0.029032258 | Q14: ='Difference to PCL'!P58 -> -0.012779553 | R14: ='Difference to PCL'!Q58 -> -0.012861736 | ... V14: ='Difference to PCL'!U58 -> -0.038095238
E15: SRN | F15: DPC | K15: ='Difference to PCL'!J59 -> -0.037162162 | L15: ='Difference to PCL'!K59 -> -0.047021944 | M15: ='Difference to PCL'!L59 -> -0.018987342 | N15: ='Difference to PCL'!M59 -> -0.01607717 | O15: ='Difference to PCL'!N59 -> -0.012779553 | P15: ='Difference to PCL'!O59 -> -0.018292683 | Q15: ='Difference to PCL'!P59 -> -0.009009009 | R15: ='Difference to PCL'!Q59 -> -0.011904762 | ... V15: ='Difference to PCL'!U59 -> -0.005952381
E16: TMS | F16: DPC | K16: ='Difference to PCL'!J60 -> -0.0079155673 | L16: ='Difference to PCL'!K60 -> -0.044270833 | M16: ='Difference to PCL'!L60 -> -0.013089005 | N16: ='Difference to PCL'!M60 -> -0.0078947368 | O16: ='Difference to PCL'!N60 -> -0.020887728 | P16: ='Difference to PCL'!O60 -> -0.0052219321 | Q16: ='Difference to PCL'!P60 -> -0.010416667 | R16: ='Difference to PCL'!Q60 -> -0.0025974026 | ... V16: ='Difference to PCL'!U60 -> -0.0078125
E17: UUW | F17: DPC | K17: ='Difference to PCL'!J61 -> -0.008356546 | L17: ='Difference to PCL'!K61 -> -0.013927577 | M17: ='Difference to PCL'!L61 -> -0.016666667 | N17: ='Difference to PCL'!M61 -> -0.027932961 | O17: ='Difference to PCL'!N61 -> -0.026252983 | P17: ='Difference to PCL'!O61 -> -0.012376238 | Q17: ='Difference to PCL'!P61 -> -0.012626263 | R17: ='Difference to PCL'!Q61 -> -0.015306122 | ... V17: ='Difference to PCL'!U61 -> -0.010309278
E18: WSX | F18: DPC | K18: ='Difference to PCL'!J62 -> -0.0032894737 | L18: ='Difference to PCL'!K62 -> -0.0098360656 | M18: ='Difference to PCL'!L62 -> -0.0033222591 | N18: ='Difference to PCL'!M62 -> -0.0033333333 | O18: ='Difference to PCL'!N62 -> -0.0062893082 | P18: ='Difference to PCL'!O62 -> -0.0098039216 | Q18: ='Difference to PCL'!P62 -> 0 | R18: ='Difference to PCL'!Q62 -> -0.015384615 | ... V18: ='Difference to PCL'!U62 -> -0.0097402597
E19: YKY | F19: DPC | K19: ='Difference to PCL'!J63 -> -0.027210884 | L19: ='Difference to PCL'!K63 -> -0.02020202 | M19: ='Difference to PCL'!L63 -> -0.0066889632 | N19: ='Difference to PCL'!M63 -> -0.006779661 | O19: ='Difference to PCL'!N63 -> -0.028301887 | P19: ='Difference to PCL'!O63 -> -0.022292994 | Q19: ='Difference to PCL'!P63 -> -0.025477707 | R19: ='Difference to PCL'!Q63 -> -0.025316456 | ... V19: ='Difference to PCL'!U63 -> -0.0095846645
E20: AFW | F20: DPC | K20: ='Difference to PCL'!J64 -> 0 | L20: ='Difference to PCL'!K64 -> 0 | M20: ='Difference to PCL'!L64 -> 0 | N20: ='Difference to PCL'!M64 -> 0 | O20: ='Difference to PCL'!N64 -> 0 | P20: ='Difference to PCL'!O64 -> 0 | Q20: ='Difference to PCL'!P64 -> 0 | R20: ='Difference to PCL'!Q64 -> 0 | ... V20: ='Difference to PCL'!U64 -> 0
... E25: SES | F25: DPC | K25: ='Difference to PCL'!J69 -> 0 | L25: ='Difference to PCL'!K69 -> 0 | M25: ='Difference to PCL'!L69 -> 0 | N25: ='Difference to PCL'!M69 -> 0 | O25: ='Difference to PCL'!N69 -> 0 | P25: ='Difference to PCL'!O69 -> 0 | Q25: ='Difference to PCL'!P69 -> 0 | R25: ='Difference to PCL'!Q69 -> 0 | ... V25: ='Difference to PCL'!U69 -> 0
A28: Industry-wide percentiles of difference to PCL
B30: WaSC-Wide Percentiles
E32: ANH | F32: DPC | G32: P10 | H32: =_xlfn.PERCENTILE.INC($K$9:$XFD$19,I32) -> -0.032644147 | I32: 0.1
E33: WSH | F33: DPC | G33: P15 | H33: =_xlfn.PERCENTILE.INC($K$9:$XFD$19,I33) -> -0.028260425 | I33: 0.15
E34: HDD | F34: DPC | G34: P20 | H34: =_xlfn.PERCENTILE.INC($K$9:$XFD$19,I34) -> -0.025380751 | I34: 0.2
E35: NES | F35: DPC | G35: P25 | H35: =_xlfn.PERCENTILE.INC($K$9:$XFD$19,I35) -> -0.020812855 | I35: 0.25
E36: SVE | F36: DPC | G36: P30 | H36: =_xlfn.PERCENTILE.INC($K$9:$XFD$19,I36) -> -0.019157741 | I36: 0.3
E37: SWB | F37: DPC | G37: P35 | H37: =_xlfn.PERCENTILE.INC($K$9:$XFD$19,I37) -> -0.017652793 | I37: 0.35
E38: SRN | F38: DPC | G38: P40 | H38: =_xlfn.PERCENTILE.INC($K$9:$XFD$19,I38) -> -0.015681331 | I38: 0.4
E39: TMS | F39: DPC | G39: P45 | H39: =_xlfn.PERCENTILE.INC($K$9:$XFD$19,I39) -> -0.014641633 | I39: 0.45
E40: UUW | F40: DPC | G40: P50 | H40: =_xlfn.PERCENTILE.INC($K$9:$XFD$19,I40) -> -0.012975371 | I40: 0.5
E41: WSX | F41: DPC | G41: P55 | H41: =_xlfn.PERCENTILE.INC($K$9:$XFD$19,I41) -> -0.01108631 | I41: 0.55
E42: YKY | F42: DPC | G42: P60 | H42: =_xlfn.PERCENTILE.INC($K$9:$XFD$19,I42) -> -0.0097657245 | I42: 0.6
E43: AFW | F43: DPC | G43: P65 | H43: =_xlfn.PERCENTILE.INC($K$9:$XFD$19,I43) -> -0.0093546326 | I43: 0.65
... E48: SES | F48: DPC | G48: P90 | H48: =_xlfn.PERCENTILE.INC($K$9:$XFD$19,I48) -> -0.0025974026 | I48: 0.9
B50: WoC-Wide Percentiles
E52: ANH | F52: DPC | G52: P10 | H52: =_xlfn.PERCENTILE.INC($K$20:$V$25,I52) -> -0.078947368 | I52: 0.1
E53: WSH | F53: DPC | G53: P15 | H53: =_xlfn.PERCENTILE.INC($K$20:$V$25,I53) -> -0.060526316 | I53: 0.15
E54: HDD | F54: DPC | G54: P20 | H54: =_xlfn.PERCENTILE.INC($K$20:$V$25,I54) -> -0.038475499 | I54: 0.2
E55: NES | F55: DPC | G55: P25 | H55: =_xlfn.PERCENTILE.INC($K$20:$V$25,I55) -> -0.032258065 | I55: 0.25
E56: SVE | F56: DPC | G56: P30 | H56: =_xlfn.PERCENTILE.INC($K$20:$V$25,I56) -> -0.024310777 | I56: 0.3
E57: SWB | F57: DPC | G57: P35 | H57: =_xlfn.PERCENTILE.INC($K$20:$V$25,I57) -> -0.0052631579 | I57: 0.35
E58: SRN | F58: DPC | G58: P40 | H58: =_xlfn.PERCENTILE.INC($K$20:$V$25,I58) -> 0 | I58: 0.4
...

Sheet Final Output
A1: =RIGHT(CELL("filename", A1), LEN(CELL("filename", A1)) - SEARCH("]", CELL("filename", A1))) -> Final Output
E3: Company | F3: Performance Commitment | G3: Measure | H3: Unit | I3: Percentile | K3: Value
A7: Percentiles ( WaSCs )
F9: DPC | G9: Difference to PCL (As % of PCL) | H9: % | I9: P10 | K9: =Percentiles!H32 -> -0.032644147
F10: DPC | G10: Difference to PCL (As % of PCL) | H10: % | I10: P15 | K10: =Percentiles!H33 -> -0.028260425
F11: DPC | G11: Difference to PCL (As % of PCL) | H11: % | I11: P20 | K11: =Percentiles!H34 -> -0.025380751
F12: DPC | G12: Difference to PCL (As % of PCL) | H12: % | I12: P25 | K12: =Percentiles!H35 -> -0.020812855
F13: DPC | G13: Difference to PCL (As % of PCL) | H13: % | I13: P30 | K13: =Percentiles!H36 -> -0.019157741
F14: DPC | G14: Difference to PCL (As % of PCL) | H14: % | I14: P35 | K14: =Percentiles!H37 -> -0.017652793
F15: DPC | G15: Difference to PCL (As % of PCL) | H15: % | I15: P40 | K15: =Percentiles!H38 -> -0.015681331
F16: DPC | G16: Difference to PCL (As % of PCL) | H16: % | I16: P45 | K16: =Percentiles!H39 -> -0.014641633
F17: DPC | G17: Difference to PCL (As % of PCL) | H17: % | I17: P50 | K17: =Percentiles!H40 -> -0.012975371
F18: DPC | G18: Difference to PCL (As % of PCL) | H18: % | I18: P55 | K18: =Percentiles!H41 -> -0.01108631
F19: DPC | G19: Difference to PCL (As % of PCL) | H19: % | I19: P60 | K19: =Percentiles!H42 -> -0.0097657245
F20: DPC | G20: Difference to PCL (As % of PCL) | H20: % | I20: P65 | K20: =Percentiles!H43 -> -0.0093546326
... F25: DPC | G25: Difference to PCL (As % of PCL) | H25: % | I25: P90 | K25: =Percentiles!H48 -> -0.0025974026
A28: Percentiles ( WoCs )
F30: DPC | G30: Difference to PCL (As % of PCL) | H30: % | I30: P10 | K30: =Percentiles!H52 -> -0.078947368
F31: DPC | G31: Difference to PCL (As % of PCL) | H31: % | I31: P15 | K31: =Percentiles!H53 -> -0.060526316
F32: DPC | G32: Difference to PCL (As % of PCL) | H32: % | I32: P20 | K32: =Percentiles!H54 -> -0.038475499
F33: DPC | G33: Difference to PCL (As % of PCL) | H33: % | I33: P25 | K33: =Percentiles!H55 -> -0.032258065
F34: DPC | G34: Difference to PCL (As % of PCL) | H34: % | I34: P30 | K34: =Percentiles!H56 -> -0.024310777
F35: DPC | G35: Difference to PCL (As % of PCL) | H35: % | I35: P35 | K35: =Percentiles!H57 -> -0.0052631579
F36: DPC | G36: Difference to PCL (As % of PCL) | H36: % | I36: P40 | K36: =Percentiles!H58 -> 0
F37: DPC | G37: Difference to PCL (As % of PCL) | H37: % | I37: P45 | K37: =Percentiles!H59 -> 0
F38: DPC | G38: Difference to PCL (As % of PCL) | H38: % | I38: P50 | K38: =Percentiles!H60 -> 0
F39: DPC | G39: Difference to PCL (As % of PCL) | H39: % | I39: P55 | K39: =Percentiles!H61 -> 0
F40: DPC | G40: Difference to PCL (As % of PCL) | H40: % | I40: P60 | K40: =Percentiles!H62 -> 0
F41: DPC | G41: Difference to PCL (As % of PCL) | H41: % | I41: P65 | K41: =Percentiles!H63 -> 0
... F46: DPC | G46: Difference to PCL (As % of PCL) | H46: % | I46: P90 | K46: =Percentiles!H68 -> 0
A48: END

Sheet F_Outputs
C1: _PR24OC02
A2: Acronym | B2: Reference | C2: Item description | D2: Unit | E2: Model | F2: Constant
A4: ANH | B4: PR24QA_PR24OC02_OUT1 | C4: Date & Time for Model - PR24OC02 | D4: Text | E4: Price Review 2024 | F4: =CONCATENATE("[…]", TEXT(NOW(),"dd/mm/yyy hh:mm:ss")) -> […]12/12/2024 16:35:52
A5: ANH | B5: PR24QA_PR24OC02_OUT2 | C5: Name of Model - PR24OC02 | D5: Text | E5: Price Review 2024 | F5: =MID(CELL("filename"),SEARCH("[",CELL("filename"))+1,SEARCH("]",CELL("filename"))-SEARCH("[",CELL("filename"))-1) -> PR24 FD OC11 ODI risk - Feeder Model (Discharge Permit Compliance).xlsx
A6: ANH | B6: PR24QA_PR24OC02_OUT3 | C6: F_Inputs time stamp - PR24OC02 | D6: Text | E6: Price Review 2024 | F6: =F_Inputs!$E$1 -> Run on 12 Nov 2024 17:31
A7: ANH | B7: PR24QA_PR24OC02_OUT4 | C7: Model override switch for - PR24OC02 | D7: nr | E7: Price Review 2024 | F7: N/A
A8: ANH | B8: C_ODIRISK_DIS_FEED_P10 | C8: Historic performance range Percentile (P10) for Discharge Permit Compliance Performance Commitment PR24 | D8: % | E8: Price Review 2024 | F8: ='Final Output'!K9 -> -0.032644147
A9: ANH | B9: C_ODIRISK_DIS_FEED_P15 | C9: Historic performance range Percentile (P15) for Discharge Permit Compliance Performance Commitment PR24 | D9: % | E9: Price Review 2024 | F9: ='Final Output'!K10 -> -0.028260425
A10: ANH | B10: C_ODIRISK_DIS_FEED_P20 | C10: Historic performance range Percentile (P20) for Discharge Permit Compliance Performance Commitment PR24 | D10: % | E10: Price Review 2024 | F10: ='Final Output'!K11 -> -0.025380751
A11: ANH | B11: C_ODIRISK_DIS_FEED_P25 | C11: Historic performance range Percentile (P25) for Discharge Permit Compliance Performance Commitment PR24 | D11: % | E11: Price Review 2024 | F11: ='Final Output'!K12 -> -0.020812855
A12: ANH | B12: C_ODIRISK_DIS_FEED_P30 | C12: Historic performance range Percentile (P30) for Discharge Permit Compliance Performance Commitment PR24 | D12: % | E12: Price Review 2024 | F12: ='Final Output'!K13 -> -0.019157741
A13: ANH | B13: C_ODIRISK_DIS_FEED_P35 | C13: Historic performance range Percentile (P35) for Discharge Permit Compliance Performance Commitment PR24 | D13: % | E13: Price Review 2024 | F13: ='Final Output'!K14 -> -0.017652793
A14: ANH | B14: C_ODIRISK_DIS_FEED_P40 | C14: Historic performance range Percentile (P40) for Discharge Permit Compliance Performance Commitment PR24 | D14: % | E14: Price Review 2024 | F14: ='Final Output'!K15 -> -0.015681331
A15: ANH | B15: C_ODIRISK_DIS_FEED_P45 | C15: Historic performance range Percentile (P45) for Discharge Permit Compliance Performance Commitment PR24 | D15: % | E15: Price Review 2024 | F15: ='Final Output'!K16 -> -0.014641633
A16: ANH | B16: C_ODIRISK_DIS_FEED_P50 | C16: Historic performance range Percentile (P50) for Discharge Permit Compliance Performance Commitment PR24 | D16: % | E16: Price Review 2024 | F16: ='Final Output'!K17 -> -0.012975371
A17: ANH | B17: C_ODIRISK_DIS_FEED_P55 | C17: Historic performance range Percentile (P55) for Discharge Permit Compliance Performance Commitment PR24 | D17: % | E17: Price Review 2024 | F17: ='Final Output'!K18 -> -0.01108631
A18: ANH | B18: C_ODIRISK_DIS_FEED_P60 | C18: Historic performance range Percentile (P60) for Discharge Permit Compliance Performance Commitment PR24 | D18: % | E18: Price Review 2024 | F18: ='Final Output'!K19 -> -0.0097657245
A19: ANH | B19: C_ODIRISK_DIS_FEED_P65 | C19: Historic performance range Percentile (P65) for Discharge Permit Compliance Performance Commitment PR24 | D19: % | E19: Price Review 2024 | F19: ='Final Output'!K20 -> -0.0093546326
... A24: ANH | B24: C_ODIRISK_DIS_FEED_P90 | C24: Historic performance range Percentile (P90) for Discharge Permit Compliance Performance Commitment PR24 | D24: % | E24: Price Review 2024 | F24: ='Final Output'!K25 -> -0.0025974026
A25: WSH | B25: PR24QA_PR24OC02_OUT1 | C25: Date & Time for Model - PR24OC02 | D25: Text | E25: Price Review 2024 | F25: =CONCATENATE("[…]", TEXT(NOW(),"dd/mm/yyy hh:mm:ss")) -> […]12/12/2024 16:35:52
A26: WSH | B26: PR24QA_PR24OC02_OUT2 | C26: Name of Model - PR24OC02 | D26: Text | E26: Price Review 2024 | F26: =MID(CELL("filename"),SEARCH("[",CELL("filename"))+1,SEARCH("]",CELL("filename"))-SEARCH("[",CELL("filename"))-1) -> PR24 FD OC11 ODI risk - Feeder Model (Discharge Permit Compliance).xlsx
A27: WSH | B27: PR24QA_PR24OC02_OUT3 | C27: F_Inputs time stamp - PR24OC02 | D27: Text | E27: Price Review 2024 | F27: =F_Inputs!$E$1 -> Run on 12 Nov 2024 17:31
A28: WSH | B28: PR24QA_PR24OC02_OUT4 | C28: Model override switch for - PR24OC02 | D28: nr | E28: Price Review 2024 | F28: N/A
A29: WSH | B29: C_ODIRISK_DIS_FEED_P10 | C29: Historic performance range Percentile (P10) for Discharge Permit Compliance Performance Commitment PR24 | D29: % | E29: Price Review 2024 | F29: ='Final Output'!K9 -> -0.032644147
A30: WSH | B30: C_ODIRISK_DIS_FEED_P15 | C30: Historic performance range Percentile (P15) for Discharge Permit Compliance Performance Commitment PR24 | D30: % | E30: Price Review 2024 | F30: ='Final Output'!K10 -> -0.028260425
A31: WSH | B31: C_ODIRISK_DIS_FEED_P20 | C31: Historic performance range Percentile (P20) for Discharge Permit Compliance Performance Commitment PR24 | D31: % | E31: Price Review 2024 | F31: ='Final Output'!K11 -> -0.025380751
A32: WSH | B32: C_ODIRISK_DIS_FEED_P25 | C32: Historic performance range Percentile (P25) for Discharge Permit Compliance Performance Commitment PR24 | D32: % | E32: Price Review 2024 | F32: ='Final Output'!K12 -> -0.020812855
A33: WSH | B33: C_ODIRISK_DIS_FEED_P30 | C33: Historic performance range Percentile (P30) for Discharge Permit Compliance Performance Commitment PR24 | D33: % | E33: Price Review 2024 | F33: ='Final Output'!K13 -> -0.019157741
A34: WSH | B34: C_ODIRISK_DIS_FEED_P35 | C34: Historic performance range Percentile (P35) for Discharge Permit Compliance Performance Commitment PR24 | D34: % | E34: Price Review 2024 | F34: ='Final Output'!K14 -> -0.017652793
A35: WSH | B35: C_ODIRISK_DIS_FEED_P40 | C35: Historic performance range Percentile (P40) for Discharge Permit Compliance Performance Commitment PR24 | D35: % | E35: Price Review 2024 | F35: ='Final Output'!K15 -> -0.015681331
A36: WSH | B36: C_ODIRISK_DIS_FEED_P45 | C36: Historic performance range Percentile (P45) for Discharge Permit Compliance Performance Commitment PR24 | D36: % | E36: Price Review 2024 | F36: ='Final Output'!K16 -> -0.014641633
A37: WSH | B37: C_ODIRISK_DIS_FEED_P50 | C37: Historic performance range Percentile (P50) for Discharge Permit Compliance Performance Commitment PR24 | D37: % | E37: Price Review 2024 | F37: ='Final Output'!K17 -> -0.012975371
A38: WSH | B38: C_ODIRISK_DIS_FEED_P55 | C38: Historic performance range Percentile (P55) for Discharge Permit Compliance Performance Commitment PR24 | D38: % | E38: Price Review 2024 | F38: ='Final Output'!K18 -> -0.01108631
A39: WSH | B39: C_ODIRISK_DIS_FEED_P60 | C39: Historic performance range Percentile (P60) for Discharge Permit Compliance Performance Commitment PR24 | D39: % | E39: Price Review 2024 | F39: ='Final Output'!K19 -> -0.0097657245
A40: WSH | B40: C_ODIRISK_DIS_FEED_P65 | C40: Historic performance range Percentile (P65) for Discharge Permit Compliance Performance Commitment PR24 | D40: % | E40: Price Review 2024 | F40: ='Final Output'!K20 -> -0.0093546326
... A45: WSH | B45: C_ODIRISK_DIS_FEED_P90 | C45: Historic performance range Percentile (P90) for Discharge Permit Compliance Performance Commitment PR24 | D45: % | E45: Price Review 2024 | F45: ='Final Output'!K25 -> -0.0025974026
A46: HDD | B46: PR24QA_PR24OC02_OUT1 | C46: Date & Time for Model - PR24OC02 | D46: Text | E46: Price Review 2024 | F46: =CONCATENATE("[…]", TEXT(NOW(),"dd/mm/yyy hh:mm:ss")) -> […]12/12/2024 16:35:52
A47: HDD | B47: PR24QA_PR24OC02_OUT2 | C47: Name of Model - PR24OC02 | D47: Text | E47: Price Review 2024 | F47: =MID(CELL("filename"),SEARCH("[",CELL("filename"))+1,SEARCH("]",CELL("filename"))-SEARCH("[",CELL("filename"))-1) -> PR24 FD OC11 ODI risk - Feeder Model (Discharge Permit Compliance).xlsx
A48: HDD | B48: PR24QA_PR24OC02_OUT3 | C48: F_Inputs time stamp - PR24OC02 | D48: Text | E48: Price Review 2024 | F48: =F_Inputs!$E$1 -> Run on 12 Nov 2024 17:31
A49: HDD | B49: PR24QA_PR24OC02_OUT4 | C49: Model override switch for - PR24OC02 | D49: nr | E49: Price Review 2024 | F49: N/A
...
